Workbook
Name IQ_CH: 110000
Name IQ_CQ: 5000
Name IQ_CY: 10000
Name IQ_DAILY: 500000
Name IQ_FH: 100000
Name IQ_FQ: 500
Name IQ_FY: 1000
Name IQ_LTM: 2000
Name IQ_MONTH: 15000
Name IQ_NTM: 6000
Name IQ_WEEK: 50000
Name IQ_YTD: 3000

Sheet __snloffice
A1: 允䅁䙁䅕䅁佁䅁䅁杗桂䝁䄰杙灂䝁䅅䅁祁䅁䅁䅙䅁䙁䅁睑啂䙁䄸睔塂䕁䄴兒䕂䙁䄸兓佂䙁䅍䅖佂䙁䄸兒䕂䙁䅕睑䉂䙁䅑兓偂䕁䄴兑䵂䍁䄸睑噂䕁䅷䅖噂䙁䅉兑䵂䙁䄸兒佂䕁䅑睔塂䕁䄰兒佂䙁䅑睕䅁䅁䅣䅁允䅁䅁䅎ぁ䑁䅅兎ㅁ䑁䅑兏䅁䉁䅍䅁杁䅁䅁睕兂䙁䄸睑偂䙁䅕杔啂䙁䅉兗時䕁䄴兑乂䕁䅕䅁䩁䅁䅁䅉䅁䙁䅍䅕時䕁䅍睔乂䙁䅁兑佂䙁䅫睘啂䙁䅫䅕䙂䅁䅁䅁䅁䉁䄴䅁兂䡁䅕杙獂䝁䅫睙杁䕁䅍睢瑂䡁䅁兙畂䡁䅫䅁䉁䅁䅁䅅䅁䑁䅑兎㍁䑁䅕䅎穁䑁䅙䅁⽁䅁䅁杣䅁䙁䅁睑啂䙁䄸睔塂䕁䄴兒䕂䙁䄸睕啂䙁䅉兑啂䕁䅕睒䩂䕁䅍睘䥂䕁䅕䅒䡂䕁䅕睘䝂䙁䅕杔䕂䙁䄸兔䡂䙁䅉睕時䕁䄰睔卂䕁䅕睘䙂䙁䅅兖䉂䕁䅷兎兂䕁䅍䅖時䙁䅍䅖䉂䕁䅳兒䅁䅁䅑䅁䅃䅁䅁䅕䑂䙁䅑睘偂䙁䅣杔䙂䕁䅑睘呂䙁䅑杕䉂䙁䅑兒䡂䕁䅫睑時䙁䅍睔坂䕁䅕杕䙂䕁䅫睒佂䙁䄸睖䙂䕁䅅䅔啂䕁䅧睘䝂䙁䅕杔䕂䙁䅍睘乂䕁䄸杕䙂䙁䄸兒剂䙁䅕兑䵂䑁䅕䅕䑂䙁䅑睘呂䙁䅑兑䱂䕁䅕䅁潁䅁䅁杚䅁䙁䅁睑啂䙁䄸睔塂䕁䄴兒䕂䙁䄸睕啂䙁䅉兑啂䕁䅕睒䩂䕁䅍睘䑂䕁䄸兔兂䕁䅅杔婂䙁䄸睑偂䕁䄴䅖卂䕁䄸䅔䵂䕁䅕䅒時䕁䅙睔噂䕁䄴䅒䉂䙁䅑兓偂䕁䄴睕䅁䉁䅯䅁杁䅁䅁䅕祂䝁䅫杤桂䡁䅑党杁䕁䅍睢瑂䡁䅁兙畂䡁䅫䅁䍁䅁䅁杌䅁䕁䅣睢㉂䝁䅕杣畂䝁䄰党畂䡁䅑䅉䩂䝁䄴督あ䝁䅫䅤ㅂ䡁䅑兡療䝁䄴䅁䑁䅁䅁杋䅁䙁䅕杢灂䡁䅑党歂䍁䅁兑祂䝁䅅杙杁䕁䅕兢灂䡁䅉兙あ䝁䅕督䅁䑁䅷䅁䝁䅁䅁杔䉂䅁䅁兂䅁䍁䅷䅁呂䝁䅧兙獂䝁䅫杢桂䍁䅁睒祂䝁䄸兤睂䍁䅁䅔灂䝁䄰兡あ䝁䅕䅚䅁䉁䄰䅁㙁䅁䅁䅕䑂䙁䅑睘偂䙁䅣杔䙂䕁䅑睘䩂䕁䄴睕啂䕁䄴睘噂䕁䄴睑䵂䕁䅅睕呂䕁䅫杒䩂䕁䅕䅒䅁䅁䅙䅁楁䅁䅁䅕桂䡁䅁兤桂䍁䅁杔求䡁䅣䅉䡂䡁䅕兡畂䝁䅕兙䅁䕁䄰䅁佁䅁䅁睑桂䝁䄴兙歂䝁䅅䅁㑁䅁䅁杕䅁䙁䅁睑啂䙁䄸睔塂䕁䄴兒䕂䙁䄸睕啂䙁䅉兑啂䕁䅕睒䩂䕁䅍睘䑂䕁䄸杕兂䕁䄸杕䉂䙁䅑兓偂䕁䄴睕時䙁䅁杕䩂䙁䅙兑啂䕁䅕䅁佁䅁䅁䅅䅁䑁䅑䅎㉁䑁䅙兎ㅁ䑁䅁䅁穁䅁䅁条䅁䙁䅁睑啂䙁䄸睔塂䕁䄴兒䕂䙁䄸睕啂䙁䅉兑啂䕁䅕睒䩂䕁䅍睘坂䕁䅍睌兂䕁䅕睘䝂䕁䅫杕乂䙁䅍睘乂䕁䄸杕䙂䙁䄸兒剂䙁䅕兑䵂䑁䅕䅕䑂䙁䅑睘呂䙁䅑兑䱂䕁䅕䅁晁䅁䅁䅔䅁䙁䅁睑啂䙁䄸睔塂䕁䄴兒䕂䙁䄸兓佂䙁䅍䅖佂䙁䄸睑偂䙁䅉䅕時䙁䅁兒佂䙁䅍兓偂䕁䄴睘呂䙁䅁睔佂䙁䅍睔卂䙁䅍䅁䥁䅁䅁杔䅁䙁䅁睑啂䙁䄸睔塂䕁䄴兒䕂䙁䄸兓佂䙁䅍䅖佂䙁䄸兖佂䕁䅫睔佂䙁䄸䅕䙂䕁䄴睕䩂䕁䄸杔時䙁䅍䅕偂䕁䄴睕偂䙁䅉睕䅁䍁䅕䅁獁䅁䅁睕兂䙁䄸兖䵂䙁䅑睘兂䕁䅅杕䙂䕁䄴䅖時䕁䅍睔噂䕁䄴䅖卂䙁䅫䅁允䅁䅁䅄䅁䕁䅍䅡灂䝁䄴兙䅁䅁䅯䅁坂䅁䅁䅕䑂䙁䅑睘偂䙁䅣杔䙂䕁䅑睘䩂䕁䄴睕啂䕁䄴睘坂䕁䅍睌兂䕁䅕睘䝂䕁䅫杕乂䙁䅍睘䵂䕁䅕睕呂䑁䅕䅕䑂䙁䅑睘呂䙁䅑兑䱂䕁䅕䅁䱁䅁䅁䅏䅁䙁䅁睑啂䙁䄸睔塂䕁䄴兒䕂䙁䄸兓佂䙁䅍䅖佂䙁䄸兓佂䙁䅙兒呂䙁䅑睘乂䕁䅣杕呂䅁䅁䅄䅁䍁䅑䅁呂䙁䅁睘兂䕁䅅杕䙂䕁䄴䅖時䕁䅍睔噂䕁䄴䅖卂䙁䅫䅁乁䅁䅁杘䅁䙁䅁睑啂䙁䄸睔塂䕁䄴兒䕂䙁䄸兓佂䙁䅍䅖佂䙁䄸䅓䙂䕁䅑睒䙂䙁䄸杒噂䕁䄴䅒時䕁䄰睒卂䙁䅍睘䵂䕁䅕睕呂䑁䅕䅕䑂䙁䅑睘呂䙁䅑兑䱂䕁䅕䅁湁䅁䅁䅢䅁䙁䅁睑啂䙁䄸睔塂䕁䄴兒䕂䙁䄸兓佂䙁䅍䅖佂䙁䄸睕偂䙁䅙兒卂䕁䅕兓䡂䕁䄴睘塂䕁䅕兑䵂䙁䅑䅓時䕁䅙兖佂䕁䅑睕時䕁䅷兒呂䙁䅍兎兂䕁䅍䅖時䙁䅍䅖䉂䕁䅳兒䅁䅁䄸䅁䍁䅁䅁䅁剁䅁䅁李䅁䙁䅍䅕時䙁䅕䅔啂䙁䄸䅕䉂䙁䅉兒佂䙁䅑睘䑂䕁䄸兔兂䕁䅅杔婂䙁䄸杔䉂䕁䄰兒䅁䉁䅣䅁煁䅁䅁睕兂䙁䄸䅕䉂䙁䅉兒佂䙁䅑睘䑂䕁䄸兔兂䕁䅅杔婂䙁䄸兓䕂䅁䅁杅䅁䑁䅉䅁呂䙁䅁睘噂䕁䅷䅖時䙁䅁兑卂䕁䅕杔啂䙁䄸睑偂䕁䄰䅕䉂䕁䄴兗時䕁䅫䅒䅁䉁䅑䅁奁䅁䅁睕療䡁䅕䅤潂䍁䅁睓療䡁䅉党桂䅁䅁兆䅁䅁䄴䅁䍂䡁䅉兙㙂䝁䅫䅢䅁䑁䅯䅁祁䅁䅁䅕䑂䙁䅑睘偂䙁䅣杔䙂䕁䅑睘呂䙁䅑杕䉂䙁䅑兒䡂䕁䅫睑時䕁䅕睕偂䙁䅁䅁坁䅁䅁䅚䅁䙁䅧兡畂䝁䅯兡桂䝁䄴睚杁䕁䄴睢畂䕁䅙党祂䡁䅉睢ㅂ䡁䅍䅉乂䝁䅕䅤桂䝁䅷䅉䩂䝁䄴䅚ㅂ䡁䅍䅤祂䡁䅫䅉潁䕁䅣杣療䡁䅕䅣灁䍁䅁睑療䍁䄴䅔あ䝁䅑䅁奁䅁䅁杓䅁䙁䅍䅕時䙁䅁睑啂䙁䄸睕䥂䕁䅅杕䙂䙁䅍睘偂䙁䅣杔䙂䕁䅑睘䉂䕁䅷䅔時䕁䅫杔呂䙁䅑兓啂䙁䅕䅖䩂䕁䄸杔呂䅁䅁䅈䅁䙁䅁䅁兂䕁䅍䅖時䕁䄸睖佂䕁䅕䅒時䙁䅍䅖卂䕁䅅䅖䙂䕁䅣兓䑂䙁䄸睑偂䙁䅉䅕偂䙁䅉兑啂䕁䅫睔佂䙁䅍睘兂䙁䅕村䵂䕁䅫睑䅁䉁䅫䅁佂䅁䅁䅕䑂䙁䅑睘偂䙁䅣杔䙂䕁䅑睘䩂䕁䄴睕啂䕁䄴睘䑂䕁䅧兑卂䕁䅫䅖䉂䕁䅉䅔䙂䙁䄸杒偂䙁䅕杔䕂䕁䅅䅖䩂䕁䄸杔呂䅁䅁睇䅁䉁䄴䅁噂䝁䄴兡あ䝁䅕䅚杁䕁䅳兡畂䝁䅣䅚療䝁䄰䅁㝁䅁䅁杒䅁䙁䅁睑啂䙁䄸睔塂䕁䄴兒䕂䙁䄸兓佂䙁䅍䅖佂䙁䄸村䉂䕁䄴睓呂䍁䄸兓佂䙁䅙兒呂䙁䅑睘䍂䕁䅅杔䱂䙁䅍䅁敁䅁䅁杆䅁䕁䅷兤㑂䝁䅕兢楂䝁䄸兤祂䝁䅣䅁煁䅁䅁䅔䅁䙁䅁睑啂䙁䄸睔塂䕁䄴兒䕂䙁䄸兓佂䙁䅍䅖佂䙁䄸睒偂䙁䅙䅖時䙁䅁兒佂䙁䅍兓偂䕁䄴睘呂䙁䅁睔佂䙁䅍睔卂䙁䅍䅁杁䅁䅁䅉䅁䕁䅑党瑂䍁䄴䅉卂䝁䅕䅣畁䍁䅁睑療䝁䄴睚療䅁䅁光䅁䕁䅷䅁兂䕁䅍䅖時䕁䄸睖佂䕁䅕䅒時䕁䅫杔呂䙁䅑杔時䕁䅙兑乂䕁䅫䅔婂䙁䄸睔䝂䕁䅙兓䑂䕁䅕睕癁䙁䅑杕噂䙁䅍䅖呂䅁䅁杉䅁䝁䅧䅁䩂䝁䄴䅚ㅂ䡁䅍䅤祂䝁䅫兙獂䍁䅁䅒求䡁䅙党獂䝁䄸䅣瑂䝁䅕杢あ䍁䅁睑療䡁䅉䅣療䡁䅉兙あ䝁䅫睢畂䍁䅁䅋慂䝁䅅兢楂䝁䅫兙灁䍁䅁䅔灂䝁䄰兡あ䝁䅕䅚䅁䑁䅑䅁煁䅁䅁䅕䑂䙁䅑睘偂䙁䅣杔䙂䕁䅑睘䩂䕁䄴睕啂䕁䄴睘卂䕁䅕兓啂䅁䅁睉䅁䍁䅙䅁兂䕁䅍䅖時䕁䄸睖佂䕁䅕䅒時䕁䅫杔呂䕁䅫䅒䙂䙁䅉睕䅁䍁䅑䅁䥂䅁䅁䅕䑂䙁䅑睘偂䙁䅣杔䙂䕁䅑睘䩂䕁䄴睕啂䕁䄴睘䩂䕁䄴睕噂䙁䅉兑佂䕁䅍兒時䕁䅍睔乂䙁䅁兑佂䕁䅫兒呂䅁䅁杊䅁䅁䅷䅁䭂䝁䅅䅣桂䝁䄴䅁灁䅁䅁䅑䅁䙁䅁睑啂䙁䄸睔塂䕁䄴兒䕂䙁䄸睕啂䙁䅉兑啂䕁䅕睒䩂䕁䅍睘呂䙁䅑兑啂䕁䅕睘偂䙁䅣杔䙂䙁䅉䅁牁䅁䅁杄䅁䕁䅙杣桂䝁䄴睙求䅁䅁䅌䅁䉁䅧䅁呂䡁䅣兡あ䡁䅯党祂䝁䅷兙畂䝁䅑䅁硁䅁䅁䅅䅁䑁䅑兎硁䑁䅧兎㍁䑁䅫䅁瑁䅁䅁䅃䅁䕁䅉杖䩂䅁䅁杌䅁䉁䅁䅁ぁ䑁䅑免㉁䑁䅍兏硁䅁䅁睌䅁䭁䅉䅁呂䡁䅑兙あ䝁䅕兌療䡁䅣杢求䝁䅑䅉䉂䡁䅍督求䡁䅑督杁䙁䅍兤睂䝁䅕杣㉂䝁䅫督灂䝁䄸杢杁䝁䅅杢歂䍁䅁兑歂䝁䄰兡畂䝁䅫督あ䡁䅉兙あ䝁䅫睢畂䍁䅁睑療䝁䄰兢灂䡁䅍督灂䝁䄸杢杁䝁䄸杚杁䡁䅑䅡求䍁䅁睕あ䝁䅅䅤求䍁䅁睑療䡁䅕杢橂䝁䅫䅁睁䅁䅁䅎䅁䕁䅙兡畂䝁䄴兡穂䝁䅧䅉乂䝁䅫杢求䡁䅉兙獂䡁䅍䅉䡂䡁䅉睢ㅂ䡁䅁䅉偂䡁䅫䅁ㅁ䅁䅁杋䅁䕁䅍睢畂䝁䅍䅢桂䡁䅙党杁䙁䅁䅖䑂䍁䅁䅔灂䝁䄰兡あ䝁䅕䅚䅁䑁䅙䅁允䅁䅁䅎穁䑁䅕䅍㍁䑁䅍䅎䅁䑁䅣䅁佁䅁䅁睕㍂䝁䅕䅚求䝁䄴䅁㕁䅁䅁䅅䅁䑁䅣兎㍁䑁䅑䅍硁䑁䅕䅁㥁䅁䅁䅅䅁䑁䅙兎硁䑁䅅䅏㉁䑁䅙䅁⭁䅁䅁杇䅁䙁䅍睢ㅂ䡁䅑䅡杁䕁䅅杚祂䝁䅫睙桂䅁䅁䅑䅁䉁䅁䅁ぁ䑁䅕䅏硁䑁䅁杍ぁ䅁䅁兑䅁䭁䅉䅁呂䡁䅑兙あ䝁䅕兌偂䡁䅣杢求䝁䅑䅉䉂䡁䅍督求䡁䅑督杁䙁䅍兤睂䝁䅕杣㉂䝁䅫督灂䝁䄸杢杁䕁䅅杢歂䍁䅁兑歂䝁䄰兡畂䝁䅫督あ䡁䅉兙あ䝁䅫睢畂䍁䅁睑療䝁䄰兢灂䡁䅍督灂䝁䄸杢杁䕁䄸杚杁䕁䅣兙畂䡁䅍兤杁䙁䅁杣療䡁䅙兡畂䝁䅍兡桂䝁䅷䅁䍂䅁䅁村䅁䕁䅫兢睂䝁䅅䅢桂䍁䅁䅕獂䝁䅅䅤灂䝁䄴兤瑂䍁䅁䅓療䝁䅷䅚灂䝁䄴睚穂䍁䅁䅔灂䝁䄰兡あ䝁䅕䅚䅁䙁䅍䅁允䅁䅁䅏穁䑁䅫睍祁䑁䅙睍䅁䕁䅍䅁佁䅁䅁杕ㅂ䡁䅍督灂䝁䅅䅁䕂䅁䅁䅅䅁䕁䅙兡畂䝁䅷兙畂䝁䅑䅁䙂䅁䅁䅅䅁䕁䅉兙潂䝁䅅兢桂䡁䅍䅁䝂䅁䅁杅䅁䑁䅅䅍㕁䑁䅕兏㍁䑁䅙䅎䅁䕁䅣䅁坁䅁䅁睓桂䡁䅯兙牂䝁䅧督あ䝁䅅杢䅁䕁䅧䅁䕂䅁䅁兒ㅂ䡁䅉兙穂䝁䅫兙畂䍁䅁杕求䡁䅍睢ㅂ䡁䅉睙求䡁䅍䅉䡂䡁䅉睢ㅂ䡁䅁䅉呂䍁䄴䄴杁䡁䅉杌獂䍁䄴䅁䩂䅁䅁权䅁䕁䅍兤楂䝁䅅䅁䭂䅁䅁䅆䅁䕁䅫杢歂䝁䄸杢求䡁䅍兡桂䅁䅁睓䅁䉁䅑䅁䥂䝁䄸杢湂䍁䅁睓療䝁䄴睚䅁䕁䅷䅁十䅁䅁睒ㅂ䝁䅕杣畂䡁䅍党㕂䅁䅁杔䅁䉁䅧䅁兂䝁䅧兡獂䝁䅫䅣睂䝁䅫杢求䡁䅍䅁偂䅁䅁䅇䅁䕁䄴党あ䝁䅧党祂䝁䅷兙畂䝁䅑督䅁䙁䅁䅁十䅁䅁免穁䑁䅉兏㑁䑁䅅睍㉁䅁䅁兕䅁䉁䅁䅁ぁ䑁䅑免睁䑁䅅睍硁䅁䅁杕䅁䍁䅧䅁橁䕁䅫杔坂䕁䅅䅔䩂䕁䅑䅉䑂䕁䄸兔兂䕁䅅杔婂䍁䅁兓䕂䅁䅁䅖䅁䍁䘴䅁䵁䅉䅅䅁䑁䅁䅁睁䵁䅁䅁兂䅁䅁䅃っ偂兑䅯䅁䅁䅁䅅䅁䉁䅁䅁权䉁䅁䅁䍄䉁䅁䅁睁䅁䅁䅍䅄䅁䅁䅕䅁䅁䡑批䕕䭅䅁䅣䅁䉁䅁䅁允䅁䅁䅯兂䅁䅁杷允䅁䅁䅍䅁䑁䅁䅷䅁䙁䅁䅁䥁浂噮䉂权䅁䅁䅁允䅁䅁䅅䅁䭁䅁䅅䅁䵁䅉䅅䅁䑁䅁䅁睁䵁䅁䅁兂䅁䅁䅁楮剰兑䅯䅂䅁䅁䅅䅁䉁䅁䅁权䙁䅁䅁䍄䉁䅁䅁睁䅁䅁䅍䅄䅁䅁䅕䅁䅁䥧摓䕕䭅䅁䅁䅁䉁䅁䅁允䅁䅁䅯允䅁䅁杷允䅁䅁䅍䅁䑁䅁䅷䅁䙁䅁䅁䵁牄䙈䉂权慁䅁䅁允䅁䅁䅅䅁䭁䅁䅕䅁䵁䅉䅅䅁䑁䅁䅁睁䵁䅁䅁兂䅁䅁䅃坂剸兑䅯䅁䅁䅁䅅䅁䉁䅁䅁权䍁䅁䅁䍄䉁䅁䅁睁䅁䅁䅍䅄䅁䅁䅕䅁䅁䡁挶啕䭅䉁䅳䅁䉁䅁䅁允䅁䅁䅯兂䅁䅁杷允䅁䅁䅍䅁䑁䅁䅷䅁䙁䅁䅁䅁敄ㅵ䉆权䝁䅁䅁允䅁䅁䅅䅁䭁䅁䅕䅁䵁䅉䅅䅁䑁䅁䅁睁䵁䅁䅁兂䅁䅁䅄婲公兑䅯䅁䅁䅁䅅䅁䉁䅁䅁权䍁䅁䅁䍄䉁䅁䅁睁䅁䅁䅍䅄䅁䅁䅕䅁䅁䥧搶䕕䭅䍁䅧䅁䉁䅁䅁允䅁䅁䅯兂䅁䅁杷允䅁䅁䅍䅁䑁䅁䅷䅁䙁䅁䅁䵁敃汙䉆权橁䅁䅁允䅁䅁䅅䅁䭁䅁䅕䅁䵁䅉䅅䅁䑁䅁䅁睁䵁䅁䅁兂䅁䅁䅂婢兰兑䅯兊䅁䅁䅅䅁䉁䅁䅁权䙁䅁䅁䍄䉁䅁䅁睁䅁䅁䅍䅄䅁䅁䅕䅁䅁䅑㑔じ䭅䅁䅙䅁䉁䅁䅁允䅁䅁䅯兂䅁䅁杷允䅁䅁䅍䅁䑁䅁䅷䅁䙁䅁䅁䅁捁唴䈵权扁䅁䅁允䅁䅁䅅䅁䭁䅁䅕䅁䵁䅉䅅䅁䑁䅁䅁睁䵁䅁䅁兂䅁䅁䅂娱兰兑䅯䅄䅁䅁䅅䅁䉁䅁䅁兂硂児塲㍯䡁䅑杷允䅁䅁䅍䅁䑁䅁䅷䅁䙁䅁䅁䅁獂ㅭ䉂权敁䅁䅁允䅁䅁䅅䅁䭁䅁䅕䅁䵁䅉䅅䅁䑁䅁䅁睁䵁䅁䅁兂䅁䅁䅁灏兤兑䅯杂䅁䅁䅅䅁䉁䅁䅁权䙁䅁䅁䍄䉁䅁䅁睁䅁䅁䅍䅄䅁䅁䅕䅁䅁䥧搶䕕䭅䅁䅫䅁䉁䅁䅁允䅁䅁䅯权䅁䅁杷允䅁䅁䅍䅁䑁䅁䅷䅁䙁䅁䅁䅁敄ㅇ䉬权䅁䅁䅁允䅁䅁䅅䅁䭁䅁䅅䅁䵁䅉䅅䅁䑁䅁䅁睁䵁䅁䅁兂䅁䅁䅁佈但兑䅯䅁䅁䅁䅅䅁䉁䅁䅁权䉁䅁䅁䍄䉁䅁䅁睁䅁䅁䅍䅄䅁䅁䅕䅁䅁䡑婏䕕䭅䍁䅧䅁䉁䅁䅁允䅁䅁䅯兂䅁䅁杷允䅁䅁䅍䅁䑁䅁䅷䅁䙁䅁䅁䅁敄ㅵ䉆权䥁䅁䅁允䅁䅁䅅䅁䭁䅁䅕䅁䵁䅉䅅䅁䑁䅁䅁睁䵁䅁䅁兂䅁䅁䅃㕵党兑䅯杅䅁䅁䅅䅁䉁䅁䅁权剁䅁䅁䍄䉁䅁䅁睁䅁䅁䅍䅄䅁䅁䅕䅁䅁乁㜶啕䭅䉁䅣䅁䉁䅁䅁允䅁䅁䅯兎䅁䅁杷允䅁䅁䅍䅁䑁䅁䅷䅁䙁䅁䅁䥁ㅁ噭䉂权塁䅁䅁允䅁䅁䅅䅁䭁䉁䅅䅁䵁䅉䅅䅁䑁䅁䅁睁䵁䅁䅁兂䅁䅁䅃䩨儱兑䅯睂䅁䅁䅅䅁䉁䅁䅁权䙁䅁䅁䍄䉁䅁䅁睁䅁䅁䅍䅄䅁䅁䅕䅁䅁䩁焴啕䭅䅁䅁䅁䉁䅁䅁允䅁䅁䅯杁䅁䅁杷允䅁䅁䅍䅁䑁䅁䅷䅁䙁䅁䅁䅁捁唴䈵权佁䅁䅁允䅁䅁䅅䅁䭁䅁䅕䅁䵁䅉䅅䅁䑁䅁䅁睁䵁䅁䅁兂䅁䅁䅂㕣公兑䅯䅁䅁䅁䅅䅁䉁䅁䅁权䍁䅁䅁䍄䉁䅁䅁睁䅁䅁䅍䅄䅁䅁䅕䅁䅁䍑ㅏ䕕䭅䅁䅁䅁䉁䅁䅁允䅁䅁䅯允䅁䅁杷允䅁䅁䅍䅁䑁䅁䅷䅁䙁䅁䅁䕁穂噭䉂权敁䅁䅁允䅁䅁䅅䅁䭁䅁䅕䅁䵁䅉䅅䅁䑁䅁䅁睁䵁䅁䅁兂䅁䅁䅄煤兤兑䅯杈䅁䅁䅅䅁䉁䅁䅁权䙁䅁䅁䍄䉁䅁䅁睁䅁䅁䅍䅄䅁䅁䅕䅁䅁䑧婗䕕䭅䅁䅑䅁䉁䅁䅁允䅁䅁䅯兂䅁䅁杷允䅁䅁䅍䅁䑁䅁䅷䅁䙁䅁䅁䕁噄汭䉂权允䅁䅁允䅁䅁䅅䅁䭁䉁䅅䅁䵁䅉䅅䅁䑁䅁䅁睁䵁䅁䅁兂䅁䅁䅃灪儱兑䅯䅁䅁䅁䅅䅁䉁䅁䅁权䉁䅁䅁䍄䉁䅁䅁睁䅁䅁䅍䅄䅁䅁䅕䅁䅁䥧獙啕䭅䉁䄸䅁䉁䅁䅁允䅁䅁䅯兂䅁䅁杷允䅁䅁䅍䅁䑁䅁䅷䅁䙁䅁䅁䕁橁噴䉂权䝁䅁䅁允䅁䅁䅅䅁䙁䝁浚浚浚癚⽙䍄䉁䅁䅁睁䅁䅁䅍䅄䅁䅁䅕䅁䅁䭁䘷䕕䭅䍁䅙䅁䉁䅁䅁允䅁䅁䅯兂䅁䅁杷允䅁䅁䅍䅁䑁䅁䅷䅁䙁䅁䅁䕁䕁䘫䈹权䅁䅁䅁允䅁䅁䅅䅁䭁䅁䅉䅁䵁䅉䅅䅁䑁䅁䅁睁䵁䅁䅁兂䅁䅁䅁灚全兑䅯䅁䅁䅁䅅䅁䉁䅁䅁权䍁䅁䅁䍄䉁䅁䅁睁䅁䅁䅍䅄䅁䅁䅕䅁䅁䩷椵啕䭅䉁䅷䅁䉁䅁䅁允䅁䅁䅕䅁䅁䅁䅃䕍䵁䅉䅅䅁䑁䅁䅁睁䵁䅁䅁兂䅁䅁䅃坂剸兑䅯䅄䅁䅁䅅䅁䉁䅁䅁权䙁䅁䅁䍄䉁䅁䅁睁䅁䅁䅍䅄䅁䅁䅕䅁䅁䩷椵啕䭅䍁䅕䅁䉁䅁䅁允䅁䅁䅯兂䅁䅁杷允䅁䅁䅍䅁䑁䅁䅷䅁䙁䅁䅁䵁畄噭䉂权䅁䅁䅁允䅁䅁䅅䅁䭁䅁䅅䅁䵁䅉䅅䅁䑁䅁䅁睁䵁䅁䅁兂䅁䅁䅄煤兤兑䅯元䅁䅁䅅䅁䉁䅁䅁权㝁䅁䅁䍄䉁䅁䅁睁䅁䅁䅍䅄䅁䅁䅕䅁䅁䭷娲䕕䭅䉁䅫䅁䉁䅁䅁允䅁䅁䅯兂䅁䅁杷允䅁䅁䅍䅁䑁䅁䅷䅁䙁䅁䅁䵁㕁ㅯ䉂权流䅁䅁允䅁䅁䅅䅁䭁䅁䅕䅁䵁䅉䅅䅁䑁䅁䅁睁䵁䅁䅁兂䅁䅁䅂婢兰兑䅯睂䅁䅁䅅䅁䉁䅁䅁权䙁䅁䅁䍄䉁䅁䅁睁䅁䅁䅍䅄䅁䅁䅕䅁䅁䡑批䕕䭅䅁䅁䅁䉁䅁䅁允䅁䅁䅯允䅁䅁杷允䅁䅁䅍䅁䑁䅁䅷䅁䙁䅁䅁䅁敃汋䉆权牁䅁䅁允䅁䅁䅅䅁䭁䅁䅕䅁䵁䅉䅅䅁䑁䅁䅁睁䵁䅁䅁兂䅁䅁䅁灏兤兑䅯䅁䅁䅁䅅䅁䉁䅁䅁权䉁䅁䅁䍄䉁䅁䅁睁䅁䅁䅍䅄䅁䅁䅕䅁䅁䑁塱䕕䭅䅁䅳䅁䉁䅁䅁允䅁䅁䅯兂䅁䅁杷允䅁䅁䅍䅁䑁䅁䅷䅁䙁䅁䅁䅁獂ㅭ䉂权䕁䅁䅁允䅁䅁䅅䅁䭁䅁䅕䅁䵁䅉䅅䅁䑁䅁䅁睁䵁䅁䅁兂䅁䅁䅃楨剸兑䅯睉䅁䅁䅅䅁䉁䅁䅁权䙁䅁䅁䍄䉁䅁䅁睁䅁䅁䅍䅄䅁䅁䅕䅁䅁䵧奏䕕䭅䅁䅁䅁䉁䅁䅁允䅁䅁䅯睁䅁䅁杷允䅁䅁䅍䅁䑁䅁䅷䅁䙁䅁䅁䅁楃歙䈹权䅁䅁䅁允䅁䅁䅅䅁䭁䅁䅅䅁䵁䅉䅅䅁䑁䅁䅁睁䵁䅁䅁兂䅁䅁䅁爳剴兑䅯䅁䅁䅁䅅䅁䉁䅁䅁权䍁䅁䅁䍄䉁䅁䅁睁䅁䅁䅍䅄䅁䅁䅕䅁䅁䭷娲䕕䭅䅁䅙䅁䉁䅁䅁允䅁䅁䅯兂䅁䅁杷允䅁䅁䅍䅁䑁䅁䅷䅁䙁䅁䅁䵁瑃噭䉂权杁䅁䅁允䅁䅁䅅䅁䭁䅁䅕䅁䵁䅉䅅䅁䑁䅁䅁睁䵁䅁䅁兂䅁䅁䅁灚全兑䅯杉䅁䅁䅅䅁䉁䅁䅁权䙁䅁䅁䍄䉁䅁䅁睁䅁䅁䅍䅄䅁䅁䅕䅁䅁䩑摃䕕䭅䉁䄸䅁䉁䅁䅁允䅁䅁䅯兂䅁䅁杷允䅁䅁䅍䅁䑁䅁䅷䅁䙁䅁䅁䵁㉂ㅰ䉂权䅁䅁䅁允䅁䅁䅅䅁䭁䅁䅉䅁䵁䅉䅅䅁䑁䅁䅁睁䵁䅁䅁兂䅁䅁䅃㕵党兑䅯䅆䅁䅁䅅䅁䉁䅁䅁权䙁䅁䅁䍄䉁䅁䅁睁䅁䅁䅍䅄䅁䅁䅕䅁䅁䩁焴啕䭅䅁䅳䅁䉁䅁䅁允䅁䅁䅯兂䅁䅁杷允䅁䅁䅍䅁䑁䅁䅷䅁䙁䅁䅁䥁䑄䙭䉂权佁䅁䅁允䅁䅁䅅䅁䭁䅁䅕䅁䵁䅉䅅䅁䑁䅁䅁睁䵁䅁䅁兂䅁䅁䅃楨剸兑䅯䅁䅁䅁䅅䅁䉁䅁䅁权䍁䅁䅁䍄䉁䅁䅁睁䅁䅁䅍䅄䅁䅁䅕䅁䅁䥧獙啕䭅䅁䄴䅁䉁䅁䅁允䅁䅁䅯兂䅁䅁杷允䅁䅁䅍䅁䑁䅁䅷䅁䙁䅁䅁䵁瑃噭䉂权捁䅁䅁允䅁䅁䅅䅁䭁䅁䅕䅁䵁䅉䅅䅁䑁䅁䅁睁䵁䅁䅁兂䅁䅁䅄㥹橊兑䅯杄䅁䅁䅅䅁䉁䅁䅁权䙁䅁䅁䍄䉁䅁䅁睁䅁䅁䅍䅄䅁䅁䅕䅁䅁䥧摓䕕䭅䍁䅑䅁䉁䅁䅁允䅁䅁䅯兂䅁䅁杷允䅁䅁䅍䅁䑁䅁䅷䅁䙁䅁䅁䥁坁湘䉴权䅁䅁䅁允䅁䅁䅅䅁䭁䅁䅉䅁䵁䅉䅅䅁䑁䅁䅁睁䵁䅁䅁兂䅁䅁䅃婎公兑䅯䅁䅁䅁䅅䅁䉁䅁䅁权䉁䅁䅁䍄䉁䅁䅁睁䅁䅁䅍䅄䅁䅁䅕䅁䅁䉧敚づ䭅䉁䅣䅁䉁䅁䅁允䅁䅁䅯充䅁䅁杷允䅁䅁䅍䅁䑁䅁䅷䅁䙁䅁䅁䵁䱄洰䉎权扁䅁䅁允䅁䅁䅅䅁䭁䅁䅕䅁䵁䅉䅅䅁䑁䅁䅁睁䵁䅁䅁兂䅁䅁䅃坂剸兑䅯元䅁䅁䅅䅁䉁䅁䅁权桁䅁䅁䍄䉁䅁䅁睁䅁䅁䅍䅄䅁䅁䅕䅁䅁䥧搶䕕䭅䍁䅍䅁䉁䅁䅁允䅁䅁䅯兂䅁䅁杷允䅁䅁䅍䅁䑁䅁䅷䅁䙁䅁䅁䕁元噮䉂权佁䅁䅁允䅁䅁䅅䅁䙁䵁ㅐ䙋偹瑷⽕䍄䉁䅁䅁睁䅁䅁䅍䅄䅁䅁䅕䅁䅁䍑ㅏ䕕䭅䍁䅍䅁䉁䅁䅁允䅁䅁䅯兂䅁䅁杷允䅁䅁䅍䅁䑁䅁䅷䅁䙁䅁䅁䅁㍁ㅬ䉂权婁䅁䅁允䅁䅁䅅䅁䙁䍁捬㡪ㅌ䐶䅨䍄䉁䅁䅁睁䅁䅁䅍䅄䅁䅁䅕䅁䅁䝑愲䕕䭅䅁䅁䅁䉁䅁䅁允䅁䅁䅯杁䅁䅁杷允䅁䅁䅍䅁䑁䅁䅷䅁䙁䅁䅁䕁㕁汭䉂权乁䅁䅁允䅁䅁䅅䅁䭁䅁䅯䅁䵁䅉䅅䅁䑁䅁䅁睁䵁䅁䅁兂䅁䅁䅃汆㜵兑䅯元䅁䅁䅅䅁䉁䅁䅁权獁䅁䅁䍄䉁䅁䅁睁䅁䅁䅍䅄䅁䅁䅕䅁䅁䭁楊ご䭅䉁䅷䅁䉁䅁䅁允䅁䅁䅕⽷潕䥘椯歔䵁䅉䅅䅁䑁䅁䅁睁䵁䅁䅁兂䅁䅁䅁䩢兴兑䅯䅁䅁䅁䅅䅁䉁䅁䅁权䍁䅁䅁䍄䉁䅁䅁睁䅁䅁䅍䅄䅁䅁䅕䅁䅁䝁奡䕕䭅䍁䅁䅁䉁䅁䅁允䅁䅁䅯兂䅁䅁杷允䅁䅁䅍䅁䑁䅁䅷䅁䙁䅁䅁䡁㍄湦䉊权䡁䅁䅁允䅁䅁䅅䅁䭁䅁䅕䅁䵁䅉䅅䅁䑁䅁䅁睁䵁䅁䅁兂䅁䅁䅃灪儱兑䅯䅈䅁䅁䅅䅁䉁䅁䅁兂獄払敧敨⽳䅑杷允䅁䅁䅍䅁䑁䅁䅷䅁䙁䅁䅁䵁祂噭䉂权䅁䅁䅁允䅁䅁䅅䅁䭁䅁䅉䅁䵁䅉䅅䅁䑁䅁䅁睁䵁䅁䅁兂䅁䅁䅄瀷公兑䅯杂䅁䅁䅅䅁䉁䅁䅁兂穁積積積䑐睐杷允䅁䅁䅍䅁䑁䅁䅷䅁䙁䅁䅁䅁畃噸䉂权䱁䅁䅁允䅁䅁䅅䅁䭁䅁䅕䅁䵁䅉䅅䅁䑁䅁䅁睁䵁䅁䅁兂䅁䅁䅁䱹剸兑䅯䅁䅁䅁䅅䅁䉁䅁䅁权䉁䅁䅁䍄䉁䅁䅁睁䅁䅁䅍䅄䅁䅁䅕䅁䅁䱧坵䕕䭅䅁䅁䅁䉁䅁䅁允䅁䅁䅯允䅁䅁杷允䅁䅁䅍䅁䑁䅁䅷䅁䙁䅁䅁䵁瑃噭䉂权䡁䅁䅁允䅁䅁䅅䅁䭁䅁䅕䅁䵁䅉䅅䅁䑁䅁䅁睁䵁䅁䅁兂䅁䅁䅁䱹剸兑䅯䅋䅁䅁䅅䅁䉁䅁䅁权䙁䅁䅁䍄䉁䅁䅁睁䅁䅁䅍䅄䅁䅁䅕䅁䅁䍑ㅏ䕕䭅䅁䅧䅁䉁䅁䅁允䅁䉁䅑䅁䅁䅁䅁䅁䵁䅉䅅䅁䑁䅁䅁睁䵁䅁䅁兂䅁䅁䅁婹兰兑䅯睊䅁䅁䅅䅁䉁䅁䅁权䙁䅁䅁䍄䉁䅁䅁睁䅁䅁䅍䅄䅁䅁䅕䅁䅁䉧敚づ䭅䍁䅕䅁䉁䅁䅁允䅁䅁䅯兂䅁䅁杷允䅁䅁䅍䅁䑁䅁䅷䅁䙁䅁䅁䅁㍁ㅬ䉂权䅁䅁䅁允䅁䅁䅅䅁䭁䅁䅅䅁䵁䅉䅅䅁䑁䅁䅁睁䵁䅁䅁兂䅁䅁䅁㕎兤兑䅯杊䅁䅁䅅䅁䉁䅁䅁权䙁䅁䅁䍄䉁䅁䅁睁䅁䅁䅍䅄䅁䅁䅕䅁䅁䝁奡䕕䭅䉁䅣䅁䉁䅁䅁允䅁䅁䅯光䅁䅁杷允䅁䅁䅍䅁䑁䅁䅷䅁䙁䅁䅁䵁牄䙈䉂权䅁䅁䅁允䅁䅁䅅䅁䭁䅁䅅䅁䵁䅉䅅䅁䑁䅁䅁睁䵁䅁䅁兂䅁䅁䅁灦剸兑䅯杂䅁䅁䅅䅁䉁䅁䅁权䙁䅁䅁䍄䉁䅁䅁睁䅁䅁䅍䅄䅁䅁䅕䅁䅁䉁乚ご䭅䅁䅁䅁䉁䅁䅁允䅁䅁䅯允䅁䅁杷允䅁䅁䅍䅁䑁䅁䅷䅁䙁䅁䅁䥁䕃噮䉂权流䅁䅁允䅁䅁䅅䅁䭁䅁䅕䅁䵁䅉䅅䅁䑁䅁䅁睁䵁䅁䅁兂䅁䅁䅃㕵党兑䅯兇䅁䅁䅅䅁䉁䅁䅁权䙁䅁䅁䍄䉁䅁䅁睁䅁䅁䅍䅄䅁䅁䅕䅁䅁䡷婋䕕䭅䅁䄰䅁䉁䅁䅁允䅁䅁䅯充䅁䅁杷允䅁䅁䅍䅁䑁䅁䅷䅁䙁䅁䅁䕁㡂ㅭ䉂权啁䅁䅁允䅁䅁䅅䅁䭁䅁䅕䅁䵁䅉䅅䅁䑁䅁䅁睁䵁䅁䅁兂䅁䅁䅁獲兖兑䅯䅁䅁䅁䅅䅁䉁䅁䅁权䍁䅁䅁䍄䉁䅁䅁睁䅁䅁䅍䅄䅁䅁䅕䅁䅁䡑婏䕕䭅䉁䅉䅁䉁䅁䅁允䅁䅁䅯睑䅁䅁杷允䅁䅁䅍䅁䑁䅁䅷䅁䙁䅁䅁䅁⭂䙮䉆权䅁䅁䅁允䅁䅁䅅䅁䭁䅁䅉䅁䵁䅉䅅䅁䑁䅁䅁睁䵁䅁䅁兂䅁䅁䅃灪儱兑䅯杅䅁䅁䅅䅁䉁䅁䅁权剁䅁䅁䍄䉁䅁䅁睁䅁䅁䅍䅄䅁䅁䅕䅁䅁䡑婏䕕䭅䅁䅷䅁䉁䅁䅁允䅁䅁䅯兂䅁䅁杷允䅁䅁䅍䅁䑁䅁䅷䅁䙁䅁䅁䅁敄ㅇ䉬权允䅁䅁允䅁䅁䅅䅁䭁䉁䅅䅁䵁䅉䅅䅁䑁䅁䅁睁䵁䅁䅁兂䅁䅁䅄慏兎兑䅯䅁䅁䅁䅅䅁䉁䅁䅁权䉁䅁䅁䍄䉁䅁䅁睁䅁䅁䅍䅄䅁䅁䅕䅁䅁䑁塱䕕䭅䍁䅣䅁䉁䅁䅁允䅁䅁䅯兂䅁䅁杷允䅁䅁䅍䅁䑁䅁䅷䅁䙁䅁䅁䕁㕁汭䉂权䡁䅁䅁允䅁䅁䅅䅁䭁䅁䅕䅁䵁䅉䅅䅁䑁䅁䅁睁䵁䅁䅁兂䅁䅁䅃坂剸兑䅯杆䅁䅁䅅䅁䉁䅁䅁权䙁䅁䅁䍄䉁䅁䅁睁䅁䅁䅍䅄䅁䅁䅕䅁䅁䑑慭䕕䭅䅁䅁䅁䉁䅁䅁允䅁䅁䅯允䅁䅁杷允䅁䅁䅍䅁䑁䅁䅷䅁䙁䅁䅁䕁㡂ㅭ䉂权捁䅁䅁允䅁䅁䅅䅁䙁䅁䅁䅁䅁䉁䄵䍄䉁䅁䅁睁䅁䅁䅍䅄䅁䅁䅕䅁䅁䅑㑔じ䭅䉁䅑䅁䉁䅁䅁允䅁䉁䅑佯䙚䅁䅁䅁䵁䅉䅅䅁䑁䅁䅁睁䵁䅁䅁兂䅁䅁䅂娱兰兑䅯䅁䅁䅁䅅䅁䉁䅁䅁权䉁䅁䅁䍄䉁䅁䅁睁䅁䅁䅍䅄䅁䅁䅕䅁䅁䱧坵䕕䭅䅁䄴䅁䉁䅁䅁允䅁䅁䅯兂䅁䅁杷允䅁䅁䅍䅁䑁䅁䅷䅁䙁䅁䅁䅁敄ㅵ䉆权汁䅁䅁允䅁䅁䅅䅁䭁䅁䅕䅁䵁䅉䅅䅁䑁䅁䅁睁䵁䅁䅁兂䅁䅁䅁䩥公兑䅯䅁䅁䅁䅅䅁䉁䅁䅁权䍁䅁䅁䍄䉁䅁䅁睁䅁䅁䅍䅄䅁䅁䅕䅁䅁䥧摓䕕䭅䍁䅳䅁䉁䅁䅁允䅁䅁䅕㡪ㅌ䙋偺歐䵁䅉䅅䅁䑁䅁䅁睁䵁䅁䅁兂䅁䅁䅃灪儱兑䅯睄䅁䅁䅅䅁䉁䅁䅁兂獄払敧敨㕶睐杷允䅁䅁䅍䅁䑁䅁䅷䅁䙁䅁䅁䅁敄ㅵ䉆权十䅁䅁允䅁䅁䅅䅁䭁䙁䅅䅁䵁䅉䅅䅁䑁䅁䅁睁䵁䅁䅁兂䅁䅁䅁栳婴兑䅯杈䅁䅁䅅䅁䉁䅁䅁兂䑄匹捨㡪湉䅑杷允䅁䅁䅍䅁䑁䅁䅷䅁䙁䅁䅁䥁坁湘䉴权䕁䅁䅁允䅁䅁䅅䅁䭁䅁䅕䅁䵁䅉䅅䅁䑁䅁䅁睁䵁䅁䅁兂䅁䅁䅁灏兤兑䅯睄䅁䅁䅅䅁䉁䅁䅁权䙁䅁䅁䍄䉁䅁䅁睁䅁䅁䅍䅄䅁䅁䅕䅁䅁䵷卶す䭅䅁䅁䅁䉁䅁䅁允䅁䅁䅯杁䅁䅁杷允䅁䅁䅍䅁䑁䅁䅷䅁䙁䅁䅁䵁敃汙䉆权䅁䅁䅁允䅁䅁䅅䅁䭁䅁䅅䅁䵁䅉䅅䅁䑁䅁䅁睁䵁䅁䅁兂䅁䅁䅄浮削兑䅯䅉䅁䅁䅅䅁䉁䅁䅁权䙁䅁䅁䍄䉁䅁䅁睁䅁䅁䅍䅄䅁䅁䅕䅁䅁䵁㡩啕䭅䉁䅉䅁䉁䅁䅁允䅁䅁䅯充䅁䅁杷允䅁䅁䅍䅁䑁䅁䅷䅁䙁䅁䅁䡁㍄湦䉊权䅁䅁䅁允䅁䅁䅅䅁䭁䅁䅅䅁䵁䅉䅅䅁䑁䅁䅁睁䵁䅁䅁兂䅁䅁䅁婹兰兑䅯䅁䅁䅁䅅䅁䉁䅁䅁权䉁䅁䅁䍄䉁䅁䅁睁䅁䅁䅍䅄䅁䅁䅕䅁䅁佷捳䕕䭅䉁䅁䅁䉁䅁䅁允䅁䅁䅯充䅁䅁杷允䅁䅁䅍䅁䑁䅁䅷䅁䙁䅁䅁䕁穂噭䉂权流䅁䅁允䅁䅁䅅䅁䭁䅁䅕䅁䵁䅉䅅䅁䑁䅁䅁睁䵁䅁䅁兂䅁䅁䅂䩫儱兑䅯䅁䅁䅁䅅䅁䉁䅁䅁权䉁䅁䅁䍄䉁䅁䅁睁䅁䅁䅍䅄䅁䅁䅕䅁䅁䭁楊ご䭅䉁䅁䅁䉁䅁䅁允䅁䅁䅯充䅁䅁杷允䅁䅁䅍䅁䑁䅁䅷䅁䙁䅁䅁䵁祂噭䉂权䕁䅁䅁允䅁䅁䅅䅁䭁䅁䅕䅁䵁䅉䅅䅁䑁䅁䅁睁䵁䅁䅁兂䅁䅁䅁灦剸兑䅯元䅁䅁䅅䅁䉁䅁䅁权㝁䅁䅁䍄䉁䅁䅁睁䅁䅁䅍䅄䅁䅁䅕䅁䅁䑁塥䕕䭅䍁䅑䅁䉁䅁䅁允䅁䅁䅕䉵䘶ㄶ㑇橶䴸䅉䅅䅁䑁䅁䅁睁䵁䅁䅁兂䅁䅁䅃楨剸兑䅯杆䅁䅁䅅䅁䉁䅁䅁权䙁䅁䅁䍄䉁䅁䅁睁䅁䅁䅍䅄䅁䅁䅕䅁䅁䝧摡䕕䭅䉁䅣䅁䉁䅁䅁允䅁䅁䅯䅇䅁䅁杷允䅁䅁䅍䅁䑁䅁䅷䅁䙁䅁䅁䥁䕃噮䉂权汁䅁䅁允䅁䅁䅅䅁䭁䅁䅕䅁䵁䅉䅅䅁䑁䅁䅁睁䵁䅁䅁兂䅁䅁䅂㕣公兑䅯杆䅁䅁䅅䅁䉁䅁䅁权䙁䅁䅁䍄䉁䅁䅁睁䅁䅁䅍䅄䅁䅁䅕䅁䅁佷娶䕕䭅䅁䅧䅁䉁䅁䅁允䅁䅁䅯兂䅁䅁杷允䅁䅁䅍䅁䑁䅁䅷䅁䙁䅁䅁䅁㙁ㅬ䉂权䕁䅁䅁允䅁䅁䅅䅁䭁䅁䅕䅁䵁䅉䅅䅁䑁䅁䅁睁䵁䅁䅁兂䅁䅁䅁䩥公兑䅯䅈䅁䅁䅅䅁䉁䅁䅁权䙁䅁䅁䍄䉁䅁䅁睁䅁䅁䅍䅄䅁䅁䅕䅁䅁䝧摡䕕䭅䅁䅫䅁䉁䅁䅁允䅁䅁䅯权䅁䅁杷允䅁䅁䅍䅁䑁䅁䅷䅁䙁䅁䅁䥁坁湘䉴权敁䅁䅁允䅁䅁䅅䅁䭁䅁䅕䅁䵁䅉䅅䅁䑁䅁䅁睁䵁䅁䅁兂䅁䅁䅁佈但兑䅯䅄䅁䅁䅅䅁䉁䅁䅁兂硂児塲⽯⽁䅑杷允䅁䅁䅍䅁䑁䅁䅷䅁䙁䅁䅁䥁穂䕑䈹权䱁䅁䅁允䅁䅁䅅䅁䙁䱁敧敨剴䭵⼴䍄䉁䅁䅁睁䅁䅁䅍䅄䅁䅁䅕䅁䅁䱧坵䕕䭅䍁䅧䅁䉁䅁䅁允䅁䅁䅯兂䅁䅁杷允䅁䅁䅍䅁䑁䅁䅷䅁䙁䅁䅁䥁䑄䙭䉂权䩁䅁䅁允䅁䅁䅅䅁䭁䍁䅅䅁䵁䅉䅅䅁䑁䅁䅁睁䵁䅁䅁兂䅁䅁䅁灦剸兑䅯兊䅁䅁䅅䅁䉁䅁䅁权䙁䅁䅁䍄䉁䅁䅁睁䅁䅁䅍䅄䅁䅁䅕䅁䅁䝁奡䕕䭅䉁䅷䅁䉁䅁䅁允䅁䅁䅯兂䅁䅁杷允䅁䅁䅍䅁䑁䅁䅷䅁䙁䅁䅁䕁㕁汭䉂权扁䅁䅁允䅁䅁䅅䅁䭁䅁䅕䅁䵁䅉䅅䅁䑁䅁䅁睁䵁䅁䅁兂䅁䅁䅃灚儱兑䅯兄䅁䅁䅅䅁䉁䅁䅁权䭁䅁䅁䍄䉁䅁䅁睁䅁䅁䅍䅄䅁䅁䅕䅁䅁䉁桺歔䭅䅁䅙䅁䉁䅁䅁允䅁䅁䅕積積積積啁䵁䅉䅅䅁䑁䅁䅁睁䵁䅁䅁兂䅁䅁䅃㕵党兑䅯睄䅁䅁䅅䅁䉁䅁䅁兂灁䥘䌯匹䵪睐杷允䅁䅁䅍䅁䑁䅁䅷䅁䙁䅁䅁䥁䑄䙭䉂权坁䅁䅁允䅁䅁䅅䅁䭁䅁䅕䅁䵁䅉䅅䅁䑁䅁䅁睁䵁䅁䅁兂䅁䅁䅁灚全兑䅯兇䅁䅁䅅䅁䉁䅁䅁权䙁䅁䅁䍄䉁䅁䅁睁䅁䅁䅍䅄䅁䅁䅕䅁䅁䝧摡䕕䭅䉁䅉䅁䉁䅁䅁允䅁䅁䅯睅䅁䅁杷允䅁䅁䅍䅁䑁䅁䅷䅁䙁䅁䅁䥁穂䕑䈹权啁䅁䅁允䅁䅁䅅䅁䭁䅁䅕䅁䵁䅉䅅䅁䑁䅁䅁睁䵁䅁䅁兂䅁䅁䅄瀷公兑䅯睋䅁䅁䅅䅁䉁䅁䅁权䙁䅁䅁䍄䉁䅁䅁睁䅁䅁䅍䅄䅁䅁䅕䅁䅁䡁挶啕䭅䉁䅁䅁䉁䅁䅁允䅁䅁䅯充䅁䅁杷允䅁䅁䅍䅁䑁䅁䅷䅁䙁䅁䅁䵁瑃噭䉂权乁䅁䅁允䅁䅁䅅䅁䭁䉁䅕䅁䵁䅉䅅䅁䑁䅁䅁睁䵁䅁䅁兂䅁䅁䅃坂剸兑䅯睄䅁䅁䅅䅁䉁䅁䅁权䙁䅁䅁䍄䉁䅁䅁睁䅁䅁䅍䅄䅁䅁䅕䅁䅁䝧摡䕕䭅䉁䅯䅁䉁䅁䅁允䅁䅁䅯兂䅁䅁杷允䅁䅁䅍䅁䑁䅁䅷䅁䙁䅁䅁䅁浂䙭䉂权坁䅁䅁允䅁䅁䅅䅁䭁䅁䅕䅁䵁䅉䅅䅁䑁䅁䅁睁䵁䅁䅁兂䅁䅁䅃㕷全兑䅯睇䅁䅁䅅䅁䉁䅁䅁权䙁䅁䅁䍄䉁䅁䅁睁䅁䅁䅍䅄䅁䅁䅕䅁䅁乁㜶啕䭅䍁䅉䅁䉁䅁䅁允䅁䅁䅯兂䅁䅁杷允䅁䅁䅍䅁䑁䅁䅷䅁䙁䅁䅁䥁佃噮䉂权䝁䅁䅁允䅁䅁䅅䅁䙁䡁啳歲桦灥⽑䍄䉁䅁䅁睁䅁䅁䅍䅄䅁䅁䅕䅁䅁䡷湡䕕䭅䉁䅷䅁䉁䅁䅁允䅁䅁䅯兂䅁䅁杷允䅁䅁䅍䅁䑁䅁䅷䅁䙁䅁䅁䥁浂噮䉂权允䅁䅁允䅁䅁䅅䅁䭁䅁䅯䅁䵁䅉䅅䅁䑁䅁䅁睁䵁䅁䅁兂䅁䅁䅄慏兎兑䅯䅅䅁䅁䅅䅁䉁䅁䅁权䭁䅁䅁䍄䉁䅁䅁睁䅁䅁䅍䅄䅁䅁䅕䅁䅁乁戴啗䭅䅁䅙䅁䉁䅁䅁允䅁䅁䅕硥畓⭒㙆䑬䴸䅉䅅䅁䑁䅁䅁睁䵁䅁䅁兂䅁䅁䅄慏兎兑䅯䅃䅁䅁䅅䅁䉁䅁䅁权䙁䅁䅁䍄䉁䅁䅁睁䅁䅁䅍䅄䅁䅁䅕䅁䅁䉁乚ご䭅䍁䅕䅁䉁䅁䅁允䅁䅁䅯兂䅁䅁杷允䅁䅁䅍䅁䑁䅁䅷䅁䙁䅁䅁䅁䩄汭䉂权楁䅁䅁允䅁䅁䅅䅁䭁䅁䅕䅁䵁䅉䅅䅁䑁䅁䅁睁䵁䅁䅁兂䅁䅁䅃灚儱兑䅯睇䅁䅁䅅䅁䉁䅁䅁权䙁䅁䅁䍄䉁䅁䅁睁䅁䅁䅍䅄䅁䅁䅕䅁䅁佷娶䕕䭅䍁䅍䅁䉁䅁䅁允䅁䅁䅯兂䅁䅁杷允䅁䅁䅍䅁䑁䅁䅷䅁䙁䅁䅁䕁瑂汭䉂权坁䅁䅁允䅁䅁䅅䅁䭁䅁䅕䅁䵁䅉䅅䅁䑁䅁䅁睁䵁䅁䅁兂䅁䅁䅃灚儱兑䅯䅆䅁䅁䅅䅁䉁䅁䅁䅆㥁䕙䅍䅁䅁䅁杷允䅁䅁䅍䅁䑁䅁䅷䅁䙁䅁䅁䥁佃噮䉂权䕁䅁䅁允䅁䅁䅅䅁䭁䅁䅕䅁䵁䅉䅅䅁䑁䅁䅁睁䵁䅁䅁兂䅁䅁䅄㥹橊兑䅯䅄䅁䅁䅅䅁䉁䅁䅁权䙁䅁䅁䍄䉁䅁䅁睁䅁䅁䅍䅄䅁䅁䅕䅁䅁䱧坵䕕䭅䉁䅯䅁䉁䅁䅁允䅁䅁䅯兂䅁䅁杷允䅁䅁䅍䅁䑁䅁䅷䅁䙁䅁䅁䕁㡂ㅭ䉂权塁䅁䅁允䅁䅁䅅䅁䭁䉁䅅䅁䵁䅉䅅䅁䑁䅁䅁睁䵁䅁䅁兂䅁䅁䅂偂晨兑䅯睈䅁䅁䅅䅁䉁䅁䅁权䙁䅁䅁䍄䉁䅁䅁睁䅁䅁䅍䅄䅁䅁䅕䅁䅁䝑愲䕕䭅䍁䅧䅁䉁䅁䅁允䅁䅁䅯兂䅁䅁杷允䅁䅁䅍䅁䑁䅁䅷䅁䙁䅁䅁䅁敄ㅇ䉬权婁䅁䅁允䅁䅁䅅䅁䙁䵁䴳䵺䵺佺⽷䍄䉁䅁䅁睁䅁䅁䅍䅄䅁䅁䅕䅁䅁䝧摡䕕䭅䉁䅷䅁䉁䅁䅁允䅁䅁䅕児塲㍯㥁歆䵁䅉䅅䅁䑁䅁䅁睁䵁䅁䅁兂䅁䅁䅁㕎兤兑䅯䅂䅁䅁䅅䅁䉁䅁䅁权䙁䅁䅁䍄䉁䅁䅁睁䅁䅁䅍䅄䅁䅁䅕䅁䅁䡷婋䕕䭅䍁䅑䅁䉁䅁䅁允䅁䅁䅯兂䅁䅁杷允䅁䅁䅍䅁䑁䅁䅷䅁䙁䅁䅁䕁穂噭䉂权湁䅁䅁允䅁䅁䅅䅁䭁䅁䅕䅁䵁䅉䅅䅁䑁䅁䅁睁䵁䅁䅁兂䅁䅁䅂婏兰兑䅯䅄䅁䅁䅅䅁䉁䅁䅁兂㥁瑃橥䑣搰䅑杷允䅁䅁䅍䅁䑁䅁䅷䅁䙁䅁䅁䵁㉂ㅰ䉂权塁䅁䅁允䅁䅁䅅䅁䭁䉁䄰䅁䵁䅉䅅䅁䑁䅁䅁睁䵁䅁䅁兂䅁䅁䅁灚全兑䅯睃䅁䅁䅅䅁䉁䅁䅁权䙁䅁䅁䍄䉁䅁䅁睁䅁䅁䅍䅄䅁䅁䅕䅁䅁䑧婗䕕䭅䅁䅧䅁䉁䅁䅁允䅁䅁䅕硥畓⭒㙆䑨䴸䅉䅅䅁䑁䅁䅁睁䵁䅁䅁兂䅁䅁䅄婲公兑䅯睇䅁䅁䅅䅁䉁䅁䅁权䙁䅁䅁䍄䉁䅁䅁睁䅁䅁䅍䅄䅁䅁䅕䅁䅁佷捳䕕䭅䉁䅷䅁䉁䅁䅁允䅁䅁䅕椹捨㡪噊歓䵁䅉䅅䅁䑁䅁䅁睁䵁䅁䅁兂䅁䅁䅂䩦兴兑䅯杊䅁䅁䅅䅁䉁䅁䅁兂乄䵺䵺䵺歺睐杷允䅁䅁䅍䅁䑁䅁䅷䅁䙁䅁䅁䅁坁啔䈹权佁䅁䅁允䅁䅁䅅䅁䙁乁橥䑣䬰砱䅚䍄䉁䅁䅁睁䅁䅁䅍䅄䅁䅁䅕䅁䅁䅧獖啕䭅䉁䄴䅁䉁䅁䅁允䅁䅁䅯兂䅁䅁杷允䅁䅁䅍䅁䑁䅁䅷䅁䙁䅁䅁䕁元噮䉂权橁䅁䅁允䅁䅁䅅䅁䭁䅁䅕䅁䵁䅉䅅䅁䑁䅁䅁睁䵁䅁䅁兂䅁䅁䅃灚儱兑䅯杈䅁䅁䅅䅁䉁䅁䅁权䙁䅁䅁䍄䉁䅁䅁睁䅁䅁䅍䅄䅁䅁䅕䅁䅁䥧摓䕕䭅䉁䄸䅁䉁䅁䅁允䅁䅁䅯兂䅁䅁杷允䅁䅁䅍䅁䑁䅁䅷䅁䙁䅁䅁䕁㡂ㅭ䉂权楁䅁䅁允䅁䅁䅅䅁䭁䅁䅕䅁䵁䅉䅅䅁䑁䅁䅁睁䵁䅁䅁兂䅁䅁䅃灚儱兑䅯䅊䅁䅁䅅䅁䉁䅁䅁兂慃婭婭婭火䅑杷允䅁䅁䅍䅁䑁䅁䅷䅁䙁䅁䅁䥁浂噮䉂权䥁䅁䅁允䅁䅁䅅䅁䭁䅁䅕䅁䵁䅉䅅䅁䑁䅁䅁睁䵁䅁䅁兂䅁䅁䅄婲公兑䅯睈䅁䅁䅅䅁䉁䅁䅁权䙁䅁䅁䍄䉁䅁䅁睁䅁䅁䅍䅄䅁䅁䅕䅁䅁佷娶䕕䭅䉁䄴䅁䉁䅁䅁允䅁䅁䅕硥畓⭒㙆䑨䴸䅉䅅䅁䑁䅁䅁睁䵁䅁䅁兂䅁䅁䅁婹兰兑䅯䅈䅁䅁䅅䅁䉁䅁䅁兂䙃ㄶ㑇杈硕䅑杷允䅁䅁䅍䅁䑁䅁䅷䅁䙁䅁䅁䵁䱄洰䉎权允䅁䅁允䅁䅁䅅䅁䭁䉁䅅䅁䵁䅉䅅䅁䑁䅁䅁睁䵁䅁䅁兂䅁䅁䅂娱兰兑䅯䅉䅁䅁䅅䅁䉁䅁䅁兂䭁㘱睎児㍱睐杷允䅁䅁䅍䅁䑁䅁䅷䅁䙁䅁䅁䅁㍁ㅬ䉂权牁䅁䅁允䅁䅁䅅䅁䭁䅁䅕䅁䵁䅉䅅䅁䑁䅁䅁睁䵁䅁䅁兂䅁䅁䅃灚儱兑䅯兇䅁䅁䅅䅁䉁䅁䅁兂䙃ㄶ㑇潈䙕䅑杷允䅁䅁䅍䅁䑁䅁䅷䅁䙁䅁䅁䵁㕁ㅯ䉂权捁䅁䅁允䅁䅁䅅䅁䙁佁㙆䭆䠵卙䅤䍄䉁䅁䅁睁䅁䅁䅍䅄䅁䅁䅕䅁䅁䩁焴啕䭅䉁䅉䅁䉁䅁䅁允䅁䅁䅯充䅁䅁杷允䅁䅁䅍䅁䑁䅁䅷䅁䙁䅁䅁䅁㑂噭䉂权䥁䅁䅁允䅁䅁䅅䅁䭁䅁䅕䅁䵁䅉䅅䅁䑁䅁䅁睁䵁䅁䅁兂䅁䅁䅃灪儱兑䅯䅄䅁䅁䅅䅁䉁䅁䅁兂卂䉵䘶㤶㝅䅑杷允䅁䅁䅍䅁䑁䅁䅷䅁䙁䅁䅁䥁浂噮䉂权䡁䅁䅁允䅁䅁䅅䅁䭁䅁䅕䅁䵁䅉䅅䅁䑁䅁䅁睁䵁䅁䅁兂䅁䅁䅃灪儱兑䅯睃䅁䅁䅅䅁䉁䅁䅁兂㝂䭆䠵場歱睐杷允䅁䅁䅍䅁䑁䅁䅷䅁䙁䅁䅁䥁坁湘䉴权楁䅁䅁允䅁䅁䅅䅁䭁䅁䅕䅁䵁䅉䅅䅁䑁䅁䅁睁䵁䅁䅁兂䅁䅁䅁楮剰兑䅯䅅䅁䅁䅅䅁䉁䅁䅁权剁䅁䅁䍄䉁䅁䅁睁䅁䅁䅍䅄䅁䅁䅕䅁䅁偣⭤正䭅䉁䅳䅁䉁䅁䅁允䅁䅁䅯兂䅁䅁杷允䅁䅁䅍䅁䑁䅁䅷䅁䙁䅁䅁䥁㝃汬䉂权䕁䅁䅁允䅁䅁䅅䅁䭁䅁䅕䅁䵁䅉䅅䅁䑁䅁䅁睁䵁䅁䅁兂䅁䅁䅄慏兎兑䅯杆䅁䅁䅅䅁䉁䅁䅁权䙁䅁䅁䍄䉁䅁䅁睁䅁䅁䅍䅄䅁䅁䅕䅁䅁䉧敚づ䭅䉁䄸䅁䉁䅁䅁允䅁䅁䅯兂䅁䅁杷允䅁䅁䅍䅁䑁䅁䅷䅁䙁䅁䅁䵁祂噭䉂权佁䅁䅁允䅁䅁䅅䅁䭁䅁䅕䅁䵁䅉䅅䅁䑁䅁䅁睁䵁䅁䅁兂䅁䅁䅃灚儱兑䅯杉䅁䅁䅅䅁䉁䅁䅁权䙁䅁䅁䍄䉁䅁䅁睁䅁䅁䅍䅄䅁䅁䅕䅁䅁䝧摡䕕䭅䉁䅙䅁䉁䅁䅁允䅁䅁䅯兂䅁䅁杷允䅁䅁䅍䅁䑁䅁䅷䅁䙁䅁䅁䵁敃汙䉆权䵁䅁䅁允䅁䅁䅅䅁䙁䱁敧敨剴䑥䅒䍄䉁䅁䅁睁䅁䅁䅍䅄䅁䅁䅕䅁䅁䡁挶啕䭅䉁䅙䅁䉁䅁䅁允䅁䅁䅯兂䅁䅁杷允䅁䅁䅍䅁䑁䅁䅷䅁䙁䅁䅁䅁䥄䙶䉆权佁䅁䅁允䅁䅁䅅䅁䙁䡁㥅瑃橥䐸䅆䍄䉁䅁䅁睁䅁䅁䅍䅄䅁䅁䅕䅁䅁䑑慭䕕䭅䍁䅍䅁䉁䅁䅁允䅁䅁䅯兂䅁䅁杷允䅁䅁䅍䅁䑁䅁䅷䅁䙁䅁䅁䥁浂噮䉂权佁䅁䅁允䅁䅁䅅䅁䙁䭁䠵場啯歔䅤䍄䉁䅁䅁睁䅁䅁䅍䅄䅁䅁䅕䅁䅁䑁塥䕕䭅䍁䅍䅁䉁䅁䅁允䅁䅁䅯兂䅁䅁杷允䅁䅁䅍䅁䑁䅁䅷䅁䙁䅁䅁䅁㑂噭䉂权歁䅁䅁允䅁䅁䅅䅁䭁䅁䅕䅁䵁䅉䅅䅁䑁䅁䅁睁䵁䅁䅁兂䅁䅁䅁婹兰兑䅯䅋䅁䅁䅅䅁䉁䅁䅁权䙁䅁䅁䍄䉁䅁䅁睁䅁䅁䅍䅄䅁䅁䅕䅁䅁䩑摃䕕䭅䉁䅣䅁䉁䅁䅁允䅁䅁䅯睕䅁䅁杷允䅁䅁䅍䅁䑁䅁䅷䅁䙁䅁䅁䡁㍄湦䉊权䥁䅁䅁允䅁䅁䅅䅁䭁䅁䅕䅁䵁䅉䅅䅁䑁䅁䅁睁䵁䅁䅁兂䅁䅁䅁灚全兑䅯睋䅁䅁䅅䅁䉁䅁䅁权䙁䅁䅁䍄䉁䅁䅁睁䅁䅁䅍䅄䅁䅁䅕䅁䅁䝁批䕕䭅䅁䄰䅁䉁䅁䅁允䅁䅁䅯充䅁䅁杷允䅁䅁䅍䅁䑁䅁䅷䅁䙁䅁䅁䥁浂噮䉂权杁䅁䅁允䅁䅁䅅䅁䭁䅁䅕䅁䵁䅉䅅䅁䑁䅁䅁睁䵁䅁䅁兂䅁䅁䅁䩢兴兑䅯杆䅁䅁䅅䅁䉁䅁䅁权䙁䅁䅁䍄䉁䅁䅁睁䅁䅁䅍䅄䅁䅁䅕䅁䅁䝁奡䕕䭅䉁䄸䅁䉁䅁䅁允䅁䅁䅯兂䅁䅁杷允䅁䅁䅍䅁䑁䅁䅷䅁䙁䅁䅁䥁浂噮䉂权流䅁䅁允䅁䅁䅅䅁䭁䅁䅕䅁䵁䅉䅅䅁䑁䅁䅁睁䵁䅁䅁兂䅁䅁䅄煤兤兑䅯睋䅁䅁䅅䅁䉁䅁䅁权䙁䅁䅁䍄䉁䅁䅁睁䅁䅁䅍䅄䅁䅁䅕䅁䅁乁戴啗䭅䉁䄸䅁䉁䅁䅁允䅁䅁䅯兂䅁䅁杷允䅁䅁䅍䅁䑁䅁䅷䅁䙁䅁䅁䥁㝃汬䉂权敁䅁䅁允䅁䅁䅅䅁啁䅁䅁䅁䅁䅁䅁䍄䉁䅁䅁睁䅁䅁䅍䅄䅁䅁䅕䅁䅁䝑愲䕕䭅䉁䅣䅁䉁䅁䅁允䅁䅁䅯充䅁䅁杷允䅁䅁䅍䅁䑁䅁䅷䅁䙁䅁䅁䅁敃汋䉆权偁䅁䅁允䅁䅁䅅䅁䭁䅁䅕䅁䵁䅉䅅䅁䑁䅁䅁睁䵁䅁䅁兂䅁䅁䅃坂剸兑䅯䅋䅁䅁䅅䅁䉁䅁䅁权䙁䅁䅁䍄䉁䅁䅁睁䅁䅁䅍䅄䅁䅁䅕䅁䅁䝧摡䕕䭅䅁䅷䅁䉁䅁䅁允䅁䅁䅕児塲㍯㥁歆䵁䅉䅅䅁䑁䅁䅁睁䵁䅁䅁兂䅁䅁䅄砶典兑䅯兄䅁䅁䅅䅁䉁䅁䅁权剁䅁䅁䍄䉁䅁䅁睁䅁䅁䅍䅄䅁䅁䅕䅁䅁乁㜶啕䭅䅁䅣䅁䉁䅁䅁允䅁䅁䅯兂䅁䅁杷允䅁䅁䅍䅁䑁䅁䅷䅁䙁䅁䅁䅁楃歙䈹权汁䅁䅁允䅁䅁䅅䅁䭁䅁䅕䅁䵁䅉䅅䅁䑁䅁䅁睁䵁䅁䅁兂䅁䅁䅃䩨儱兑䅯睇䅁䅁䅅䅁䉁䅁䅁权䙁䅁䅁䍄䉁䅁䅁睁䅁䅁䅍䅄䅁䅁䅕䅁䅁䵧奏䕕䭅䍁䅍䅁䉁䅁䅁允䅁䅁䅯兂䅁䅁杷允䅁䅁䅍䅁䑁䅁䅷䅁䙁䅁䅁䅁敃汋䉆权婁䅁䅁允䅁䅁䅅䅁䭁䅁䅕䅁䵁䅉䅅䅁䑁䅁䅁睁䵁䅁䅁兂䅁䅁䅁䩢兴兑䅯兊䅁䅁䅅䅁䉁䅁䅁权䙁䅁䅁䍄䉁䅁䅁睁䅁䅁䅍䅄䅁䅁䅕䅁䅁䑷橭䕕䭅䅁䅙䅁䉁䅁䅁允䅁䅁䅯兂䅁䅁杷允䅁䅁䅍䅁䑁䅁䅷䅁䙁䅁䅁䅁捁唴䈵权䩁䅁䅁允䅁䅁䅅䅁䭁䍁䅫䅁䵁䅉䅅䅁䑁䅁䅁睁䵁䅁䅁兂䅁䅁䅃灚儱兑䅯睉䅁䅁䅅䅁䉁䅁䅁权䙁䅁䅁䍄䉁䅁䅁睁䅁䅁䅍䅄䅁䅁䅕䅁䅁䵧奏䕕䭅䍁䅧䅁䉁䅁䅁允䅁䅁䅯兂䅁䅁杷允䅁䅁䅍䅁䑁䅁䅷䅁䙁䅁䅁䅁䥄䙶䉆权汁䅁䅁允䅁䅁䅅䅁䭁䅁䅕䅁䵁䅉䅅䅁䑁䅁䅁睁䵁䅁䅁兂䅁䅁䅃っ偂兑䅯䅂䅁䅁䅅䅁䉁䅁䅁权䙁䅁䅁䍄䉁䅁䅁睁䅁䅁䅍䅄䅁䅁䅕䅁䅁佷捳䕕䭅䉁䅣䅁䉁䅁䅁允䅁䅁䅯充䅁䅁杷允䅁䅁䅍䅁䑁䅁䅷䅁䙁䅁䅁䅁畃噸䉂权䝁䅁䅁允䅁䅁䅅䅁䭁䅁䅕䅁䵁䅉䅅䅁䑁䅁䅁睁䵁䅁䅁兂䅁䅁䅄㥹橊兑䅯杉䅁䅁䅅䅁䉁䅁䅁权䙁䅁䅁䍄䉁䅁䅁睁䅁䅁䅍䅄䅁䅁䅕䅁䅁䉁桺歔䭅䉁䄸䅁䉁䅁䅁允䅁䅁䅯兂䅁䅁杷允䅁䅁䅍䅁䑁䅁䅷䅁䙁䅁䅁䥁浂噮䉂权䝁䅁䅁允䅁䅁䅅䅁䭁䅁䅕䅁䵁䅉䅅䅁䑁䅁䅁睁䵁䅁䅁兂䅁䅁䅂䩫儱兑䅯杂䅁䅁䅅䅁䉁䅁䅁权䙁䅁䅁䍄䉁䅁䅁睁䅁䅁䅍䅄䅁䅁䅕䅁䅁䵷卶す䭅䅁䅑䅁䉁䅁䅁允䅁䅁䅯兂䅁䅁杷允䅁䅁䅍䅁䑁䅁䅷䅁䙁䅁䅁䵁祂噭䉂权楁䅁䅁允䅁䅁䅅䅁䭁䅁䅕䅁䵁䅉䅅䅁䑁䅁䅁睁䵁䅁䅁兂䅁䅁䅂䩫儱兑䅯睃䅁䅁䅅䅁䉁䅁䅁权䙁䅁䅁䍄䉁䅁䅁睁䅁䅁䅍䅄䅁䅁䅕䅁䅁䍑ㅏ䕕䭅䅁䅷䅁䉁䅁䅁允䅁䅁䅕体㙆䭆㌵さ䵁䅉䅅䅁䑁䅁䅁睁䵁䅁䅁兂䅁䅁䅂㕣公兑䅯睆䅁䅁䅅䅁䉁䅁䅁权䍂䅁䅁䍄䉁䅁䅁睁䅁䅁䅍䅄䅁䅁䅕䅁䅁䑷橭䕕䭅䍁䅕䅁䉁䅁䅁允䅁䅁䅯兂䅁䅁杷允䅁䅁䅍䅁䑁䅁䅷䅁䙁䅁䅁䥁坁湘䉴权十䅁䅁允䅁䅁䅅䅁䭁䉁䅅䅁䵁䅉䅅䅁䑁䅁䅁睁䵁䅁䅁兂䅁䅁䅃㕷全兑䅯睆䅁䅁䅅䅁䉁䅁䅁权剁䅁䅁䍄䉁䅁䅁睁䅁䅁䅍䅄䅁䅁䅕䅁䅁䭷娲䕕䭅䅁䅳䅁䉁䅁䅁允䅁䅁䅯兂䅁䅁杷允䅁䅁䅍䅁䑁䅁䅷䅁䙁䅁䅁䅁䩄汭䉂权杁䅁䅁允䅁䅁䅅䅁䭁䅁䅕䅁䵁䅉䅅䅁䑁䅁䅁睁䵁䅁䅁兂䅁䅁䅃灚儱兑䅯兊䅁䅁䅅䅁䉁䅁䅁权䙁䅁䅁䍄䉁䅁䅁睁䅁䅁䅍䅄䅁䅁䅕䅁䅁䅧獖啕䭅䍁䅙䅁䉁䅁䅁允䅁䅁䅯兂䅁䅁杷允䅁䅁䅍䅁䑁䅁䅷䅁䙁䅁䅁䅁㍁ㅬ䉂权䱁䅁䅁允䅁䅁䅅䅁䙁䩁婱婭婭敭⽅䍄䉁䅁䅁睁䅁䅁䅍䅄䅁䅁䅕䅁䅁䵁慭䕕䭅䅁䅳䅁䉁䅁䅁允䅁䅁䅯兂䅁䅁杷允䅁䅁䅍䅁䑁䅁䅷䅁䙁䅁䅁䵁畄噭䉂权扁䅁䅁允䅁䅁䅅䅁䭁䅁䅕䅁䵁䅉䅅䅁䑁䅁䅁睁䵁䅁䅁兂䅁䅁䅁爳剴兑䅯兇䅁䅁䅅䅁䉁䅁䅁权䙁䅁䅁䍄䉁䅁䅁睁䅁䅁䅍䅄䅁䅁䅕䅁䅁䝧摡䕕䭅䅁䅳䅁䉁䅁䅁允䅁䅁䅯兂䅁䅁杷允䅁䅁䅍䅁䑁䅁䅷䅁䙁䅁䅁䕁元噮䉂权楁䅁䅁允䅁䅁䅅䅁䭁䅁䅕䅁䵁䅉䅅䅁䑁䅁䅁睁䵁䅁䅁兂䅁䅁䅄㥹橊兑䅯睃䅁䅁䅅䅁䉁䅁䅁权䙁䅁䅁䍄䉁䅁䅁睁䅁䅁䅍䅄䅁䅁䅕䅁䅁䵁慭䕕䭅䅁䄴䅁䉁䅁䅁允䅁䅁䅕場啯歲桥問䵁䅉䅅䅁䑁䅁䅁睁䵁䅁䅁兂䅁䅁䅄婲公兑䅯杈䅁䅁䅅䅁䉁䅁䅁权䙁䅁䅁䍄䉁䅁䅁睁䅁䅁䅍䅄䅁䅁䅕䅁䅁䭁楊ご䭅䉁䅣䅁䉁䅁䅁允䅁䅁䅯充䅁䅁杷允䅁䅁䅍䅁䑁䅁䅷䅁䙁䅁䅁䅁⭂䙮䉆权䱁䅁䅁允䅁䅁䅅䅁䭁䅁䅕䅁䵁䅉䅅䅁䑁䅁䅁睁䵁䅁䅁兂䅁䅁䅂偂晨兑䅯睊䅁䅁䅅䅁䉁䅁䅁权䙁䅁䅁䍄䉁䅁䅁睁䅁䅁䅍䅄䅁䅁䅕䅁䅁䭷娲䕕䭅䅁䅑䅁䉁䅁䅁允䅁䅁䅯兂䅁䅁杷允䅁䅁䅍䅁䑁䅁䅷䅁䙁䅁䅁䵁瑃噭䉂权湁䅁䅁允䅁䅁䅅䅁䭁䅁䅕䅁䵁䅉䅅䅁䑁䅁䅁睁䵁䅁䅁兂䅁䅁䅁䱹剸兑䅯䅈䅁䅁䅅䅁䉁䅁䅁兂㑃潈牘払瑧䅑杷允䅁䅁䅍䅁䑁䅁䅷䅁䙁䅁䅁䥁穂䕑䈹权潁䅁䅁允䅁䅁䅅䅁䭁䅁䅕䅁䵁䅉䅅䅁䑁䅁䅁睁䵁䅁䅁兂䅁䅁䅁灦剸兑䅯䅋䅁䅁䅅䅁䉁䅁䅁权䙁䅁䅁䍄䉁䅁䅁睁䅁䅁䅍䅄䅁䅁䅕䅁䅁䭁楊ご䭅䍁䅙䅁䉁䅁䅁允䅁䅁䅕硥畓⭒㙆䑴䴸䅉䅅䅁䑁䅁䅁睁䵁䅁䅁兂䅁䅁䅁獲兖兑䅯杉䅁䅁䅅䅁䉁䅁䅁权䙁䅁䅁䍄䉁䅁䅁睁䅁䅁䅍䅄䅁䅁䅕䅁䅁䵁㡩啕䭅䅁䅙䅁䉁䅁䅁允䅁䉁䅑䅁䅁䅁䅁䅁䵁䅉䅅䅁䑁䅁䅁睁䵁䅁䅁兂䅁䅁䅃っ偂兑䅯兇䅁䅁䅅䅁䉁䅁䅁权䙁䅁䅁䍄䉁䅁䅁睁䅁䅁䅍䅄䅁䅁䅕䅁䅁䥧獙啕䭅䍁䅑䅁䉁䅁䅁允䅁䅁䅯兂䅁䅁杷允䅁䅁䅍䅁䑁䅁䅷䅁䙁䅁䅁䅁捁唴䈵权塁䅁䅁允䅁䅁䅅䅁䭁䉁䅅䅁䵁䅉䅅䅁䑁䅁䅁睁䵁䅁䅁兂䅁䅁䅁浯偊兑䅯杂䅁䅁䅅䅁䉁䅁䅁兂穁積積積䑐睐杷允䅁䅁䅍䅁䑁䅁䅷䅁䙁䅁䅁䥁祂㈵䉒权䅁䅁䅁允䅁䅁䅅䅁䭁䅁䅉䅁䵁䅉䅅䅁䑁䅁䅁睁䵁䅁䅁兂䅁䅁䅃楨剸兑䅯杇䅁䅁䅅䅁䉁䅁䅁权䙁䅁䅁䍄䉁䅁䅁睁䅁䅁䅍䅄䅁䅁䅕䅁䅁䭷娲䕕䭅䅁䄸䅁䉁䅁䅁允䅁䅁䅯兂䅁䅁杷允䅁䅁䅍䅁䑁䅁䅷䅁䙁䅁䅁䥁䕃噮䉂权䕁䅁䅁允䅁䅁䅅䅁䭁䅁䅕䅁䵁䅉䅅䅁䑁䅁䅁睁䵁䅁䅁兂䅁䅁䅁楮剰兑䅯杉䅁䅁䅅䅁䉁䅁䅁权䙁䅁䅁䍄䉁䅁䅁睁䅁䅁䅍䅄䅁䅁䅕䅁䅁䑧婗䕕䭅䉁䅯䅁䉁䅁䅁允䅁䅁䅯兂䅁䅁杷允䅁䅁䅍䅁䑁䅁䅷䅁䙁䅁䅁䵁瑃噭䉂权慁䅁䅁允䅁䅁䅅䅁䭁䅁䅕䅁䵁䅉䅅䅁䑁䅁䅁睁䵁䅁䅁兂䅁䅁䅃っ偂兑䅯杂䅁䅁䅅䅁䉁䅁䅁兂偃癷潕䥘⬯睐杷允䅁䅁䅍䅁䑁䅁䅷䅁䙁䅁䅁䥁穂䕑䈹权䩁䅁䅁允䅁䅁䅅䅁䭁䍁䅫䅁䵁䅉䅅䅁䑁䅁䅁睁䵁䅁䅁兂䅁䅁䅁獲兖兑䅯杆䅁䅁䅅䅁䉁䅁䅁权䙁䅁䅁䍄䉁䅁䅁睁䅁䅁䅍䅄䅁䅁䅕䅁䅁䡷湡䕕䭅䉁䅑䅁䉁䅁䅁允䅁䉁䅑㔯穆䅁䅁䅁䵁䅉䅅䅁䑁䅁䅁睁䵁䅁䅁兂䅁䅁䅁灏兤兑䅯䅈䅁䅁䅅䅁䉁䅁䅁兂㝂䭆䠵場橯䅑杷允䅁䅁䅍䅁䑁䅁䅷䅁䙁䅁䅁䥁ㅁ噭䉂权歁䅁䅁允䅁䅁䅅䅁䙁䱁敧敨剴䭵⼴䍄䉁䅁䅁睁䅁䅁䅍䅄䅁䅁䅕䅁䅁䩷椵啕䭅䉁䄸䅁䉁䅁䅁允䅁䅁䅯兂䅁䅁杷允䅁䅁䅍䅁䑁䅁䅷䅁䙁䅁䅁䥁ㅁ噭䉂权十䅁䅁允䅁䅁䅅䅁䭁䉁䅅䅁䵁䅉䅅䅁䑁䅁䅁睁䵁䅁䅁兂䅁䅁䅃灚儱兑䅯睊䅁䅁䅅䅁䉁䅁䅁权䙁䅁䅁䍄䉁䅁䅁睁䅁䅁䅍䅄䅁䅁䅕䅁䅁䭷娲䕕䭅䍁䅧䅁䉁䅁䅁允䅁䅁䅯兂䅁䅁杷允䅁䅁䅍䅁䑁䅁䅷䅁䙁䅁䅁䥁浂噮䉂权偁䅁䅁允䅁䅁䅅䅁䭁䅁䅕䅁䵁䅉䅅䅁䑁䅁䅁睁䵁䅁䅁兂䅁䅁䅁歆倱兑䅯䅆䅁䅁䅅䅁䉁䅁䅁权䙁䅁䅁䍄䉁䅁䅁睁䅁䅁䅍䅄䅁䅁䅕䅁䅁䅑㑔じ䭅䅁䄴䅁䉁䅁䅁允䅁䅁䅯兂䅁䅁杷允䅁䅁䅍䅁䑁䅁䅷䅁䙁䅁䅁䅁䥄䙶䉆权䵁䅁䅁允䅁䅁䅅䅁䙁䵁䴳䵺䵺䍺䅖䍄䉁䅁䅁睁䅁䅁䅍䅄䅁䅁䅕䅁䅁䝧摡䕕䭅䅁䅑䅁䉁䅁䅁允䅁䅁䅯兂䅁䅁杷允䅁䅁䅍䅁䑁䅁䅷䅁䙁䅁䅁䡁㍄湦䉊权晁䅁䅁允䅁䅁䅅䅁䭁䅁䅕䅁䵁䅉䅅䅁䑁䅁䅁睁䵁䅁䅁兂䅁䅁䅃㕵党兑䅯元䅁䅁䅅䅁䉁䅁䅁权㕁䅁䅁䍄䉁䅁䅁睁䅁䅁䅍䅄䅁䅁䅕䅁䅁䑁塥䕕䭅䅁䄸䅁䉁䅁䅁允䅁䅁䅯兂䅁䅁杷允䅁䅁䅍䅁䑁䅁䅷䅁䙁䅁䅁䥁䙁䙢䉆权啁䅁䅁允䅁䅁䅅䅁䭁䅁䅕䅁䵁䅉䅅䅁䑁䅁䅁睁䵁䅁䅁兂䅁䅁䅁灚全兑䅯䅂䅁䅁䅅䅁䉁䅁䅁权䙁䅁䅁䍄䉁䅁䅁睁䅁䅁䅍䅄䅁䅁䅕䅁䅁䑧婗䕕䭅䅁䄴䅁䉁䅁䅁允䅁䅁䅯兂䅁䅁杷允䅁䅁䅍䅁䑁䅁䅷䅁䙁䅁䅁䅁楃歙䈹权佁䅁䅁允䅁䅁䅅䅁䙁䡁啳歲桦灥⽑䍄䉁䅁䅁睁䅁䅁䅍䅄䅁䅁䅕䅁䅁䑧婗䕕䭅䅁䅳䅁䉁䅁䅁允䅁䅁䅯兂䅁䅁杷允䅁䅁䅍䅁䑁䅁䅷䅁䙁䅁䅁䵁瑃噭䉂权䥁䅁䅁允䅁䅁䅅䅁䭁䅁䅕䅁䵁䅉䅅䅁䑁䅁䅁睁䵁䅁䅁兂䅁䅁䅁灏兤兑䅯兇䅁䅁䅅䅁䉁䅁䅁权䙁䅁䅁䍄䉁䅁䅁睁䅁䅁䅍䅄䅁䅁䅕䅁䅁䅑㑔じ䭅䅁䅧䅁䉁䅁䅁允䅁䅁䅯兂䅁䅁杷允䅁䅁䅍䅁䑁䅁䅷䅁䙁䅁䅁䅁䩄汭䉂权偁䅁䅁允䅁䅁䅅䅁䙁䡁啳歲桦来䅨䍄䉁䅁䅁睁䅁䅁䅍䅄䅁䅁䅕䅁䅁䝧摡䕕䭅䍁䅳䅁䉁䅁䅁允䅁䅁䅯兂䅁䅁杷允䅁䅁䅍䅁䑁䅁䅷䅁䙁䅁䅁䅁獂ㅭ䉂权婁䅁䅁允䅁䅁䅅䅁䭁䅁䅕䅁䵁䅉䅅䅁䑁䅁䅁睁䵁䅁䅁兂䅁䅁䅃灚儱兑䅯睈䅁䅁䅅䅁䉁䅁䅁权䙁䅁䅁䍄䉁䅁䅁睁䅁䅁䅍䅄䅁䅁䅕䅁䅁䉁桺歔䭅䉁䅯䅁䉁䅁䅁允䅁䅁䅯兂䅁䅁杷允䅁䅁䅍䅁䑁䅁䅷䅁䙁䅁䅁䕁瑂汭䉂权䝁䅁䅁允䅁䅁䅅䅁䭁䅁䅕䅁䵁䅉䅅䅁䑁䅁䅁睁䵁䅁䅁兂䅁䅁䅄砶典兑䅯兊䅁䅁䅅䅁䉁䅁䅁权䙁䅁䅁䍄䉁䅁䅁睁䅁䅁䅍䅄䅁䅁䅕䅁䅁䡁挶啕䭅䉁䅷䅁䉁䅁䅁允䅁䅁䅯兂䅁䅁杷允䅁䅁䅍䅁䑁䅁䅷䅁䙁䅁䅁䅁䥄䙶䉆权乁䅁䅁允䅁䅁䅅䅁䭁䉁䅅䅁䵁䅉䅅䅁䑁䅁䅁睁䵁䅁䅁兂䅁䅁䅂婏兰兑䅯杊䅁䅁䅅䅁䉁䅁䅁权䙁䅁䅁䍄䉁䅁䅁睁䅁䅁䅍䅄䅁䅁䅕䅁䅁䥧搶䕕䭅䉁䅯䅁䉁䅁䅁允䅁䅁䅯兂䅁䅁杷允䅁䅁䅍䅁䑁䅁䅷䅁䙁䅁䅁䵁祂噭䉂权偁䅁䅁允䅁䅁䅅䅁䭁䅁䅕䅁䵁䅉䅅䅁䑁䅁䅁睁䵁䅁䅁兂䅁䅁䅁䱹剸兑䅯䅆䅁䅁䅅䅁䉁䅁䅁权䙁䅁䅁䍄䉁䅁䅁睁䅁䅁䅍䅄䅁䅁䅕䅁䅁乁㜶啕䭅䉁䅯䅁䉁䅁䅁允䅁䅁䅯兂䅁䅁杷允䅁䅁䅍䅁䑁䅁䅷䅁䙁䅁䅁䅁䥄䙶䉆权橁䅁䅁允䅁䅁䅅䅁䭁䅁䅕䅁䵁䅉䅅䅁䑁䅁䅁睁䵁䅁䅁兂䅁䅁䅁灏兤兑䅯睂䅁䅁䅅䅁䉁䅁䅁权䙁䅁䅁䍄䉁䅁䅁睁䅁䅁䅍䅄䅁䅁䅯児䅁䅁䅯䅁䅁䅁䅅䅁䉁䅁䅁权䍁䅁䅁䍄䉁䅁䅁睁䅁䅁䅍䅄䅁䅁䅕䅁䅁䅑㑔じ䭅䅁䄰䅁䉁䅁䅁允䅁䅁䅯杋䅁䅁杷允䅁䅁䅍䅁䑁䅁䅷䅁䙁䅁䅁䵁畄噭䉂权偁䅁䅁允䅁䅁䅅䅁䭁䅁䅕䅁䵁䅉䅅䅁䑁䅁䅁睁䵁䅁䅁兂䅁䅁䅃灚儱兑䅯䅋䅁䅁䅅䅁䉁䅁䅁权䙁䅁䅁䍄䉁䅁䅁睁䅁䅁䅍䅄䅁䅁䅕䅁䅁䡁㡡啕䭅䅁䅁䅁䉁䅁䅁允䅁䅁䅯睁䅁䅁杷允䅁䅁䅍䅁䑁䅁䅷䅁䙁䅁䅁䕁橁噴䉂权婁䅁䅁允䅁䅁䅅䅁䭁䅁䅕䅁䵁䅉䅅䅁䑁䅁䅁睁䵁䅁䅁兂䅁䅁䅁獲兖兑䅯睂䅁䅁䅅䅁䉁䅁䅁权䙁䅁䅁䍄䉁䅁䅁睁䅁䅁䅍䅄䅁䅁䅕䅁䅁䩁焴啕䭅䍁䅁䅁䉁䅁䅁允䅁䅁䅯兂䅁䅁杷允䅁䅁䅍䅁䑁䅁䅷䅁䙁䅁䅁䅁坁啔䈹权楁䅁䅁允䅁䅁䅅䅁䭁䅁䅕䅁䵁䅉䅅䅁䑁䅁䅁睁䵁䅁䅁兂䅁䅁䅃汆㜵兑䅯兄䅁䅁䅅䅁䉁䅁䅁权剁䅁䅁䍄䉁䅁䅁睁䅁䅁䅍䅄䅁䅁䅕䅁䅁䑁塥䕕䭅䉁䅯䅁䉁䅁䅁允䅁䅁䅯兂䅁䅁杷允䅁䅁䅍䅁䑁䅁䅷䅁䙁䅁䅁䅁㑂噭䉂权潁䅁䅁允䅁䅁䅅䅁䭁䅁䅕䅁䵁䅉䅅䅁䑁䅁䅁睁䵁䅁䅁兂䅁䅁䅄瀷公兑䅯䅆䅁䅁䅅䅁䉁䅁䅁权䙁䅁䅁䍄䉁䅁䅁睁䅁䅁䅍䅄䅁䅁䅕䅁䅁䅧獖啕䭅䉁䅣䅁䉁䅁䅁允䅁䅁䅯充䅁䅁杷允䅁䅁䅍䅁䑁䅁䅷䅁䙁䅁䅁䥁䑄䙭䉂权歁䅁䅁允䅁䅁䅅䅁䭁䅁䅕䅁䵁䅉䅅䅁䑁䅁䅁睁䵁䅁䅁兂䅁䅁䅄婲公兑䅯睉䅁䅁䅅䅁䉁䅁䅁权䙁䅁䅁䍄䉁䅁䅁睁䅁䅁䅍䅄䅁䅁䅕䅁䅁䡑婏䕕䭅䅁䄴䅁䉁䅁䅁允䅁䅁䅯兂䅁䅁杷允䅁䅁䅍䅁䑁䅁䅷䅁䙁䅁䅁䅁㑂噭䉂权十䅁䅁允䅁䅁䅅䅁䭁䕁䅍䅁䵁䅉䅅䅁䑁䅁䅁睁䵁䅁䅁兂䅁䅁䅃坂剸兑䅯兊䅁䅁䅅䅁䉁䅁䅁权䙁䅁䅁䍄䉁䅁䅁睁䅁䅁䅍䅄䅁䅁䅕䅁䅁䭷娲䕕䭅䍁䅙䅁䉁䅁䅁允䅁䅁䅯兂䅁䅁杷允䅁䅁䅍䅁䑁䅁䅷䅁䙁䅁䅁䥁䝃䙌䉆权塁䅁䅁允䅁䅁䅅䅁䭁䉁䅅䅁䵁䅉䅅䅁䑁䅁䅁睁䵁䅁䅁兂䅁䅁䅁䩢兴兑䅯杅䅁䅁䅅䅁䉁䅁䅁权剁䅁䅁䍄䉁䅁䅁睁䅁䅁䅍䅄䅁䅁䅕䅁䅁䑷橭䕕䭅䅁䄸䅁䉁䅁䅁允䅁䅁䅯兂䅁䅁杷允䅁䅁䅍䅁䑁䅁䅷䅁䙁䅁䅁䕁穂噭䉂权汁䅁䅁允䅁䅁䅅䅁䭁䅁䅕䅁䵁䅉䅅䅁䑁䅁䅁睁䵁䅁䅁兂䅁䅁䅄婲公兑䅯元䅁䅁䅅䅁䉁䅁䅁权噁䅁䅁䍄䉁䅁䅁睁䅁䅁䅍䅄䅁䅁䅕䅁䅁䑁塱䕕䭅䅁䄰䅁䉁䅁䅁允䅁䅁䅯杌䅁䅁杷允䅁䅁䅍䅁䑁䅁䅷䅁䙁䅁䅁䅁㑂噭䉂权䩁䅁䅁允䅁䅁䅅䅁䭁䅁䅯䅁䵁䅉䅅䅁䑁䅁䅁睁䵁䅁䅁兂䅁䅁䅁獲兖兑䅯睊䅁䅁䅅䅁䉁䅁䅁权䙁䅁䅁䍄䉁䅁䅁睁䅁䅁䅍䅄䅁䅁䅕䅁䅁偣⭤正䭅䉁䅣䅁䉁䅁䅁允䅁䅁䅯充䅁䅁杷允䅁䅁䅍䅁䑁䅁䅷䅁䙁䅁䅁䵁瑃噭䉂权十䅁䅁允䅁䅁䅅䅁䭁䍁䄰䅁䵁䅉䅅䅁䑁䅁䅁睁䵁䅁䅁兂䅁䅁䅁灚全兑䅯睇䅁䅁䅅䅁䉁䅁䅁权䙁䅁䅁䍄䉁䅁䅁睁䅁䅁䅍䅄䅁䅁䅕䅁䅁䭷娲䕕䭅䅁䅷䅁䉁䅁䅁允䅁䅁䅯兂䅁䅁杷允䅁䅁䅍䅁䑁䅁䅷䅁䙁䅁䅁䅁㙁ㅬ䉂权䩁䅁䅁允䅁䅁䅅䅁䭁䅁䅯䅁䵁䅉䅅䅁䑁䅁䅁睁䵁䅁䅁兂䅁䅁䅁䩢兴兑䅯杇䅁䅁䅅䅁䉁䅁䅁权䙁䅁䅁䍄䉁䅁䅁睁䅁䅁䅍䅄䅁䅁䅕䅁䅁䭷娲䕕䭅䉁䅣䅁䉁䅁䅁允䅁䅁䅯兆䅁䅁杷允䅁䅁䅍䅁䑁䅁䅷䅁䙁䅁䅁䕁㕁汭䉂权䝁䅁䅁允䅁䅁䅅䅁啁䅁䅁䅁䅁䅁䅁䍄䉁䅁䅁睁䅁䅁䅍䅄䅁䅁䅕䅁䅁䭁䘷䕕䭅䉁䅉䅁䉁䅁䅁允䅁䅁䅯睒䅁䅁杷允䅁䅁䅍䅁䑁䅁䅷䅁䙁䅁䅁䵁瑃噭䉂权允䅁䅁允䅁䅁䅅䅁䭁䉁䅕䅁䵁䅉䅅䅁䑁䅁䅁睁䵁䅁䅁兂䅁䅁䅂䩫儱兑䅯䅅䅁䅁䅅䅁䉁䅁䅁权䅂䅁䅁䍄䉁䅁䅁睁䅁䅁䅍䅄䅁䅁䅕䅁䅁䡷湡䕕䭅䅁䅳䅁䉁䅁䅁允䅁䅁䅯兂䅁䅁杷允䅁䅁䅍䅁䑁䅁䅷䅁䙁䅁䅁䵁敃汙䉆权十䅁䅁允䅁䅁䅅䅁䭁䉁䅅䅁䵁䅉䅅䅁䑁䅁䅁睁䵁䅁䅁兂䅁䅁䅄婲公兑䅯䅆䅁䅁䅅䅁䉁䅁䅁䅆穃欸䅑䅁䅁䅁杷允䅁䅁䅍䅁䑁䅁䅷䅁䙁䅁䅁䵁瑃噭䉂权楁䅁䅁允䅁䅁䅅䅁䭁䅁䅕䅁䵁䅉䅅䅁䑁䅁䅁睁䵁䅁䅁兂䅁䅁睂㌹礵兑䅯杊䅁䅁䅅䅁䉁䅁䅁权䙁䅁䅁䍄䉁䅁䅁睁䅁䅁䅍䅄䅁䅁䅕䅁䅁䡷湡䕕䭅䉁䄸䅁䉁䅁䅁允䅁䅁䅯兂䅁䅁杷允䅁䅁䅍䅁䑁䅁䅷䅁䙁䅁䅁䅁獂ㅭ䉂权杁䅁䅁允䅁䅁䅅䅁䭁䅁䅕䅁䵁䅉䅅䅁䑁䅁䅁睁䵁䅁䅁兂䅁䅁䅃㕷全兑䅯睂䅁䅁䅅䅁䉁䅁䅁权䙁䅁䅁䍄䉁䅁䅁睁䅁䅁䅍䅄䅁䅁䅕䅁䅁䍑ㅏ䕕䭅䉁䅁䅁䉁䅁䅁允䅁䅁䅯充䅁䅁杷允䅁䅁䅍䅁䑁䅁䅷䅁䙁䅁䅁䕁㕁汭䉂权歁䅁䅁允䅁䅁䅅䅁啁䅁䅁䅁䅁䅁䅁䍄䉁䅁䅁睁䅁䅁䅍䅄䅁䅁䅕䅁䅁䵷卶す䭅䉁䅑䅁䉁䅁䅁允䅁䅁䅯兂䅁䅁杷允䅁䅁䅍䅁䑁䅁䅷䅁䙁䅁䅁䵁牄䙈䉂权楁䅁䅁允䅁䅁䅅䅁䙁䅁塲㍯㥁牃⽣䍄䉁䅁䅁睁䅁䅁䅍䅄䅁䅁䅕䅁䅁䑑慭䕕䭅䉁䅣䅁䉁䅁䅁允䅁䅁䅯䅍䅁䅁杷允䅁䅁䅍䅁䑁䅁䅷䅁䙁䅁䅁䕁瑂汭䉂权湁䅁䅁允䅁䅁䅅䅁䭁䅁䅕䅁䵁䅉䅅䅁䑁䅁䅁睁䵁䅁䅁兂䅁䅁䅃㕵党兑䅯䅅䅁䅁䅅䅁䉁䅁䅁权剁䅁䅁䍄䉁䅁䅁睁䅁䅁䅍䅄䅁䅁䅕䅁䅁䥧搶䕕䭅䍁䅙䅁䉁䅁䅁允䅁䅁䅯兂䅁䅁杷允䅁䅁䅍䅁䑁䅁䅷䅁䙁䅁䅁䵁瑃噭䉂权汁䅁䅁允䅁䅁䅅䅁䭁䅁䅕䅁䵁䅉䅅䅁䑁䅁䅁睁䵁䅁䅁兂䅁䅁䅂娱兰兑䅯䅂䅁䅁䅅䅁䉁䅁䅁权䙁䅁䅁䍄䉁䅁䅁睁䅁䅁䅍䅄䅁䅁䅕䅁䅁䅑㑔じ䭅䉁䅳䅁䉁䅁䅁允䅁䅁䅯兂䅁䅁杷允䅁䅁䅍䅁䑁䅁䅷䅁䙁䅁䅁䵁瑃噭䉂权牁䅁䅁允䅁䅁䅅䅁䭁䅁䅕䅁䵁䅉䅅䅁䑁䅁䅁睁䵁䅁䅁兂䅁䅁䅁䩥公兑䅯䅆䅁䅁䅅䅁䉁䅁䅁䅆癁潅䅁䅁䅁䅁杷允䅁䅁䅍䅁䑁䅁䅷䅁䙁䅁䅁䅁敃汋䉆权流䅁䅁允䅁䅁䅅䅁䭁䅁䅕䅁䵁䅉䅅䅁䑁䅁䅁睁䵁䅁䅁兂䅁䅁䅄瀷公兑䅯睃䅁䅁䅅䅁䉁䅁䅁䅆䅁䅁䅁䅁䅁䅁杷允䅁䅁䅍䅁䑁䅁䅷䅁䙁䅁䅁䅁獂ㅭ䉂权䥁䅁䅁允䅁䅁䅅䅁䭁䅁䅕䅁䵁䅉䅅䅁䑁䅁䅁睁䵁䅁䅁兂䅁䅁䅁灦剸兑䅯杇䅁䅁䅅䅁䉁䅁䅁权䙁䅁䅁䍄䉁䅁䅁睁䅁䅁䅍䅄䅁䅁䅯睍䅁䅁䅯䅁䅁䅁䅅䅁䉁䅁䅁权䑁䅁䅁䍄䉁䅁䅁睁䅁䅁䅍䅄䅁䅁䅕䅁䅁䡑批䕕䭅䅁䄰䅁䉁䅁䅁允䅁䅁䅯充䅁䅁杷允䅁䅁䅍䅁䑁䅁䅷䅁䙁䅁䅁䵁㕁ㅯ䉂权敁䅁䅁允䅁䅁䅅䅁䭁䅁䅕䅁䵁䅉䅅䅁䑁䅁䅁睁䵁䅁䅁兂䅁䅁䅄婲公兑䅯䅊䅁䅁䅅䅁䉁䅁䅁权䙁䅁䅁䍄䉁䅁䅁睁䅁䅁䅍䅄䅁䅁䅕䅁䅁䝑愲䕕䭅䉁䅳䅁䉁䅁䅁允䅁䅁䅯兂䅁䅁杷允䅁䅁䅍䅁䑁䅁䅷䅁䙁䅁䅁䥁䙁䙢䉆权䱁䅁䅁允䅁䅁䅅䅁䭁䅁䅕䅁䵁䅉䅅䅁䑁䅁䅁睁䵁䅁䅁兂䅁䅁䅄瀷公兑䅯杆䅁䅁䅅䅁䉁䅁䅁权䙁䅁䅁䍄䉁䅁䅁睁䅁䅁䅍䅄䅁䅁䅕䅁䅁䑑慭䕕䭅䍁䅕䅁䉁䅁䅁允䅁䅁䅯兂䅁䅁杷允䅁䅁䅍䅁䑁䅁䅷䅁䙁䅁䅁䕁橁噴䉂权䡁䅁䅁允䅁䅁䅅䅁䭁䅁䅕䅁䵁䅉䅅䅁䑁䅁䅁睁䵁䅁䅁兂䅁䅁䅃㕵党兑䅯䅈䅁䅁䅅䅁䉁䅁䅁兂灁䥘䌯儹䝨䅑杷允䅁䅁䅍䅁䑁䅁䅷䅁䙁䅁䅁䅁獂ㅭ䉂权塁䅁䅁允䅁䅁䅅䅁䭁䉁䅅䅁䵁䅉䅅䅁䑁䅁䅁睁䵁䅁䅁兂䅁䅁䅁獲兖兑䅯䅄䅁䅁䅅䅁䉁䅁䅁权䙁䅁䅁䍄䉁䅁䅁睁䅁䅁䅍䅄䅁䅁䅕䅁䅁䭷娲䕕䭅䉁䅙䅁䉁䅁䅁允䅁䅁䅯兂䅁䅁杷允䅁䅁䅍䅁䑁䅁䅷䅁䙁䅁䅁䵁畄噭䉂权䵁䅁䅁允䅁䅁䅅䅁䙁䥁牘払敧啚䅤䍄䉁䅁䅁睁䅁䅁䅍䅄䅁䅁䅕䅁䅁䭷娲䕕䭅䅁䄴䅁䉁䅁䅁允䅁䅁䅯兂䅁䅁杷允䅁䅁䅍䅁䑁䅁䅷䅁䙁䅁䅁䕁橁噴䉂权十䅁䅁允䅁䅁䅅䅁䭁䉁䅅䅁䵁䅉䅅䅁䑁䅁䅁睁䵁䅁䅁兂䅁䅁䅁栳婴兑䅯䅃䅁䅁䅅䅁䉁䅁䅁䅆䅁䅁䅁䅁䅁䅁杷允䅁䅁䅍䅁䑁䅁䅷䅁䙁䅁䅁䵁敃汙䉆权䩁䅁䅁允䅁䅁䅅䅁䭁䍁䅫䅁䵁䅉䅅䅁䑁䅁䅁睁䵁䅁䅁兂䅁䅁䅄慏兎兑䅯杄䅁䅁䅅䅁䉁䅁䅁兂䥂場啯潲兤䅑杷允䅁䅁䅍䅁䑁䅁䅷䅁䙁䅁䅁䅁捁唴䈵权乁䅁䅁允䅁䅁䅅䅁䭁䉁䅅䅁䵁䅉䅅䅁䑁䅁䅁睁䵁䅁䅁兂䅁䅁䅁爳剴兑䅯䅆䅁䅁䅅䅁䉁䅁䅁䅆奄挶䅯䅁䅁䅁杷允䅁䅁䅍䅁䑁䅁䅷䅁䙁䅁䅁䅁㙁ㅬ䉂权歁䅁䅁允䅁䅁䅅䅁䭁䅁䅕䅁䵁䅉䅅䅁䑁䅁䅁睁䵁䅁䅁兂䅁䅁䅂偂晨兑䅯睉䅁䅁䅅䅁䉁䅁䅁权䙁䅁䅁䍄䉁䅁䅁睁䅁䅁䅍䅄䅁䅁䅕䅁䅁䉁桺歔䭅䉁䅉䅁䉁䅁䅁允䅁䅁䅯充䅁䅁杷允䅁䅁䅍䅁䑁䅁䅷䅁䙁䅁䅁䡁㍄湦䉊权啁䅁䅁允䅁䅁䅅䅁䭁䅁䅕䅁䵁䅉䅅䅁䑁䅁䅁睁䵁䅁䅁兂䅁䅁䅄慏兎兑䅯兇䅁䅁䅅䅁䉁䅁䅁权䙁䅁䅁䍄䉁䅁䅁睁䅁䅁䅍䅄䅁䅁䅕䅁䅁乁㜶啕䭅䅁䅳䅁䉁䅁䅁允䅁䅁䅯兂䅁䅁杷允䅁䅁䅍䅁䑁䅁䅷䅁䙁䅁䅁䕁䕁䘫䈹权牁䅁䅁允䅁䅁䅅䅁䭁䅁䅕䅁䵁䅉䅅䅁䑁䅁䅁睁䵁䅁䅁兂䅁䅁䅃っ偂兑䅯䅊䅁䅁䅅䅁䉁䅁䅁兂䭁㘱睎児䡲睐杷允䅁䅁䅍䅁䑁䅁䅷䅁䙁䅁䅁䅁浂䙭䉂权啁䅁䅁允䅁䅁䅅䅁啁䅁樵村䅁䅁䅁䍄䉁䅁䅁睁䅁䅁䅍䅄䅁䅁䅕䅁䅁䉧敚づ䭅䉁䅳䅁䉁䅁䅁允䅁䅁䅯兂䅁䅁杷允䅁䅁䅍䅁䑁䅁䅷䅁䙁䅁䅁䥁㝃汬䉂权牁䅁䅁允䅁䅁䅅䅁䭁䅁䅕䅁䵁䅉䅅䅁䑁䅁䅁睁䵁䅁䅁兂䅁䅁䅃坂剸兑䅯兄䅁䅁䅅䅁䉁䅁䅁权剁䅁䅁䍄䉁䅁䅁睁䅁䅁䅍䅄䅁䅁䅕䅁䅁䑁塥䕕䭅䅁䅙䅁䉁䅁䅁允䅁䅁䅕硥畓⭒㙆䑬䴸䅉䅅䅁䑁䅁䅁睁䵁䅁䅁兂䅁䅁䅂䩦兴兑䅯䅄䅁䅁䅅䅁䉁䅁䅁兂硂児塲㍯呁䅑杷允䅁䅁䅍䅁䑁䅁䅷䅁䙁䅁䅁䕁㕁汭䉂权䩁䅁䅁允䅁䅁䅅䅁䭁䅁䅯䅁䵁䅉䅅䅁䑁䅁䅁睁䵁䅁䅁兂䅁䅁䅁佈但兑䅯䅅䅁䅁䅅䅁䉁䅁䅁权剁䅁䅁䍄䉁䅁䅁睁䅁䅁䅍䅄䅁䅁䅕䅁䅁䩑摃䕕䭅䍁䅕䅁䉁䅁䅁允䅁䅁䅯兂䅁䅁杷允䅁䅁䅍䅁䑁䅁䅷䅁䙁䅁䅁䅁捁唴䈵权䡁䅁䅁允䅁䅁䅅䅁䭁䅁䅕䅁䵁䅉䅅䅁䑁䅁䅁睁䵁䅁䅁兂䅁䅁䅁灚全兑䅯䅊䅁䅁䅅䅁䉁䅁䅁权䙁䅁䅁䍄䉁䅁䅁睁䅁䅁䅍䅄䅁䅁䅕䅁䅁佷娶䕕䭅䉁䅉䅁䉁䅁䅁允䅁䅁䅯充䅁䅁杷允䅁䅁䅍䅁䑁䅁䅷䅁䙁䅁䅁䥁䙁䙢䉆权䡁䅁䅁允䅁䅁䅅䅁䭁䅁䅕䅁䵁䅉䅅䅁䑁䅁䅁睁䵁䅁䅁兂䅁䅁䅁栳婴兑䅯兄䅁䅁䅅䅁䉁䅁䅁权剁䅁䅁䍄䉁䅁䅁睁䅁䅁䅍䅄䅁䅁䅕䅁䅁䉁桺歔䭅䍁䅍䅁䉁䅁䅁允䅁䅁䅯兂䅁䅁杷允䅁䅁䅍䅁䑁䅁䅷䅁䙁䅁䅁䅁捁唴䈵权啁䅁䅁允䅁䅁䅅䅁䭁䅁䅕䅁䵁䅉䅅䅁䑁䅁䅁睁䵁䅁䅁兂䅁䅁䅃灪儱兑䅯兄䅁䅁䅅䅁䉁䅁䅁权剁䅁䅁䍄䉁䅁䅁睁䅁䅁䅍䅄䅁䅁䅕䅁䅁䱧坵䕕䭅䉁䅳䅁䉁䅁䅁允䅁䅁䅯兂䅁䅁杷允䅁䅁䅍䅁䑁䅁䅷䅁䙁䅁䅁䅁㙁ㅬ䉂权流䅁䅁允䅁䅁䅅䅁䭁䅁䅕䅁䵁䅉䅅䅁䑁䅁䅁睁䵁䅁䅁兂䅁䅁䅁佈但兑䅯䅈䅁䅁䅅䅁䉁䅁䅁兂畃⭒㙆䝆䨵䅑杷允䅁䅁䅍䅁䑁䅁䅷䅁䙁䅁䅁䅁浂䙭䉂权敁䅁䅁允䅁䅁䅅䅁䭁䅁䅕䅁䵁䅉䅅䅁䑁䅁䅁睁䵁䅁䅁兂䅁䅁䅁楮剰兑䅯睆䅁䅁䅅䅁䉁䅁䅁权剁䅁䅁䍄䉁䅁䅁睁䅁䅁䅍䅄䅁䅁䅕䅁䅁䵧奏䕕䭅䉁䄸䅁䉁䅁䅁允䅁䅁䅯兂䅁䅁杷允䅁䅁䅍䅁䑁䅁䅷䅁䙁䅁䅁䅁捁唴䈵权敁䅁䅁允䅁䅁䅅䅁䙁䥁䌯匹捨⭪⽉䍄䉁䅁䅁睁䅁䅁䅍䅄䅁䅁䅕䅁䅁䑁塥䕕䭅䍁䅣䅁䉁䅁䅁允䅁䅁䅕䉵䘶ㄶ㑇橮䴸䅉䅅䅁䑁䅁䅁睁䵁䅁䅁兂䅁䅁䅂偂晨兑䅯睄䅁䅁䅅䅁䉁䅁䅁权䙁䅁䅁䍄䉁䅁䅁睁䅁䅁䅍䅄䅁䅁䅕䅁䅁䉁桺歔䭅䍁䅉䅁䉁䅁䅁允䅁䉁䅑䅁䅁䅁䅁䅁䵁䅉䅅䅁䑁䅁䅁睁䵁䅁䅁兂䅁䅁䅁栳婴兑䅯杄䅁䅁䅅䅁䉁䅁䅁兂歃䑣䬰㘱㑐睐杷允䅁䅁䅍䅁䑁䅁䅷䅁䙁䅁䅁䥁坁湘䉴权湁䅁䅁允䅁䅁䅅䅁䭁䅁䅕䅁䵁䅉䅅䅁䑁䅁䅁睁䵁䅁䅁兂䅁䅁䅁佈但兑䅯䅃䅁䅁䅅䅁䉁䅁䅁权䙁䅁䅁䍄䉁䅁䅁睁䅁䅁䅍䅄䅁䅁䅕䅁䅁乑慗䕕䭅䉁䅣䅁䉁䅁䅁允䅁䅁䅯充䅁䅁杷允䅁䅁䅍䅁䑁䅁䅷䅁䙁䅁䅁䅁㙁ㅬ䉂权允䅁䅁允䅁䅁䅅䅁䭁䅁䅯䅁䵁䅉䅅䅁䑁䅁䅁睁䵁䅁䅁兂䅁䅁䅁栳婴兑䅯䅂䅁䅁䅅䅁䉁䅁䅁权䙁䅁䅁䍄䉁䅁䅁睁䅁䅁䅍䅄䅁䅁䅕䅁䅁佷娶䕕䭅䅁䄴䅁䉁䅁䅁允䅁䅁䅕歲桦桥畑䕎䵁䅉䅅䅁䑁䅁䅁睁䵁䅁䅁兂䅁䅁䅂䩫儱兑䅯䅄䅁䅁䅅䅁䉁䅁䅁兂灁䥘䌯匹捪睐杷允䅁䅁䅍䅁䑁䅁䅷䅁䙁䅁䅁䅁敃汋䉆权慁䅁䅁允䅁䅁䅅䅁䭁䅁䅕䅁䵁䅉䅅䅁䑁䅁䅁睁䵁䅁䅁兂䅁䅁䅄㥹橊兑䅯杂䅁䅁䅅䅁䉁䅁䅁权䙁䅁䅁䍄䉁䅁䅁睁䅁䅁䅍䅄䅁䅁䅕䅁䅁䉁桺歔䭅䍁䅁䅁䉁䅁䅁允䅁䅁䅕浚浚浚浚樱䴸䅉䅅䅁䑁䅁䅁睁䵁䅁䅁兂䅁䅁䅁歆倱兑䅯睉䅁䅁䅅䅁䉁䅁䅁权䙁䅁䅁䍄䉁䅁䅁睁䅁䅁䅍䅄䅁䅁䅕䅁䅁䝁奡䕕䭅䅁䄴䅁䉁䅁䅁允䅁䅁䅯兂䅁䅁杷允䅁䅁䅍䅁䑁䅁䅷䅁䙁䅁䅁䥁佃噮䉂权䥁䅁䅁允䅁䅁䅅䅁䭁䅁䅕䅁䵁䅉䅅䅁䑁䅁䅁睁䵁䅁䅁兂䅁䅁䅁浯偊兑䅯䅂䅁䅁䅅䅁䉁䅁䅁权䙁䅁䅁䍄䉁䅁䅁睁䅁䅁䅍䅄䅁䅁䅕䅁䅁䉁乚ご䭅䍁䅣䅁䉁䅁䅁允䅁䅁䅯兂䅁䅁杷允䅁䅁䅍䅁䑁䅁䅷䅁䙁䅁䅁䥁坁湘䉴权䥁䅁䅁允䅁䅁䅅䅁䭁䅁䅕䅁䵁䅉䅅䅁䑁䅁䅁睁䵁䅁䅁兂䅁䅁䅃灪儱兑䅯䅅䅁䅁䅅䅁䉁䅁䅁权剁䅁䅁䍄䉁䅁䅁睁䅁䅁䅍䅄䅁䅁䅕䅁䅁䉁桺歔䭅䍁䅙䅁䉁䅁䅁允䅁䅁䅕呣䬰㘱睎䕌䵁䅉䅅䅁䑁䅁䅁睁䵁䅁䅁兂䅁䅁䅁歆倱兑䅯䅈䅁䅁䅅䅁䉁䅁䅁兂乄䵺䵺䵺獺睐杷允䅁䅁䅍䅁䑁䅁䅷䅁䙁䅁䅁䅁楃歙䈹权晁䅁䅁允䅁䅁䅅䅁䙁䙁偹癷潕䌳䅆䍄䉁䅁䅁睁䅁䅁䅍䅄䅁䅁䅕䅁䅁䡷婋䕕䭅䅁䅫䅁䉁䅁䅁允䅁䅁䅯权䅁䅁杷允䅁䅁䅍䅁䑁䅁䅷䅁䙁䅁䅁䕁㡂ㅭ䉂权潁䅁䅁允䅁䅁䅅䅁䭁䅁䅕䅁䵁䅉䅅䅁䑁䅁䅁睁䵁䅁䅁兂䅁䅁䅃䩨儱兑䅯杄䅁䅁䅅䅁䉁䅁䅁权䙁䅁䅁䍄䉁䅁䅁睁䅁䅁䅍䅄䅁䅁䅕䅁䅁䉁桺歔䭅䍁䅕䅁䉁䅁䅁允䅁䅁䅯兂䅁䅁杷允䅁䅁䅍䅁䑁䅁䅷䅁䙁䅁䅁䕁瑂汭䉂权歁䅁䅁允䅁䅁䅅䅁䭁䅁䅕䅁䵁䅉䅅䅁䑁䅁䅁睁䵁䅁䅁兂䅁䅁䅁佈但兑䅯睊䅁䅁䅅䅁䉁䅁䅁兂歃䑣䬰㘱児睐杷允䅁䅁䅍䅁䑁䅁䅷䅁䙁䅁䅁䕁橁噴䉂权杁䅁䅁允䅁䅁䅅䅁䙁䑁積積積⭍⽍䍄䉁䅁䅁睁䅁䅁䅍䅄䅁䅁䅕䅁䅁䉁桺歔䭅䅁䄸䅁䉁䅁䅁允䅁䅁䅕体㙆䭆䠵吹䴸䅉䅅䅁䑁䅁䅁睁䵁䅁䅁兂䅁䅁䅁䩥公兑䅯睋䅁䅁䅅䅁䉁䅁䅁权䙁䅁䅁䍄䉁䅁䅁睁䅁䅁䅍䅄䅁䅁䅕䅁䅁佷娶䕕䭅䍁䅉䅁䉁䅁䅁允䅁䅁䅯兂䅁䅁杷允䅁䅁䅍䅁䑁䅁䅷䅁䙁䅁䅁䅁⭂䙮䉆权佁䅁䅁允䅁䅁䅅䅁䭁䅁䅕䅁䵁䅉䅅䅁䑁䅁䅁睁䵁䅁䅁兂䅁䅁䅁歆倱兑䅯睆䅁䅁䅅䅁䉁䅁䅁权剁䅁䅁䍄䉁䅁䅁睁䅁䅁䅍䅄䅁䅁䅕䅁䅁䡁婩䕕䭅䍁䅙䅁䉁䅁䅁允䅁䅁䅯兂䅁䅁杷允䅁䅁䅍䅁䑁䅁䅷䅁䙁䅁䅁䅁捁唴䈵权䱁䅁䅁允䅁䅁䅅䅁䙁䡁啳歲桦灥⽑䍄䉁䅁䅁睁䅁䅁䅍䅄䅁䅁䅕䅁䅁䡧䅎ご䭅䅁䄰䅁䉁䅁䅁允䅁䅁䅯充䅁䅁杷允䅁䅁䅍䅁䑁䅁䅷䅁䙁䅁䅁䕁穂噭䉂权捁䅁䅁允䅁䅁䅅䅁䭁䅁䅕䅁䵁䅉䅅䅁䑁䅁䅁睁䵁䅁䅁兂䅁䅁䅁䩥公兑䅯䅂䅁䅁䅅䅁䉁䅁䅁权䙁䅁䅁䍄䉁䅁䅁睁䅁䅁䅍䅄䅁䅁䅕䅁䅁䝁奡䕕䭅䉁䅯䅁䉁䅁䅁允䅁䅁䅯兂䅁䅁杷允䅁䅁䅍䅁䑁䅁䅷䅁䙁䅁䅁䅁浂䙭䉂权偁䅁䅁允䅁䅁䅅䅁䭁䅁䅕䅁䵁䅉䅅䅁䑁䅁䅁睁䵁䅁䅁兂䅁䅁䅂㕣公兑䅯兇䅁䅁䅅䅁䉁䅁䅁权䙁䅁䅁䍄䉁䅁䅁睁䅁䅁䅍䅄䅁䅁䅕䅁䅁䡑婏䕕䭅䍁䅑䅁䉁䅁䅁允䅁䅁䅯兂䅁䅁杷允䅁䅁䅍䅁䑁䅁䅷䅁䙁䅁䅁䥁坁湘䉴权䡁䅁䅁允䅁䅁䅅䅁䭁䅁䅕䅁䵁䅉䅅䅁䑁䅁䅁睁䵁䅁䅁兂䅁䅁䅃䩨儱兑䅯䅃䅁䅁䅅䅁䉁䅁䅁权䙁䅁䅁䍄䉁䅁䅁睁䅁䅁䅍䅄䅁䅁䅕䅁䅁䉁桺歔䭅䍁䅑䅁䉁䅁䅁允䅁䅁䅕灭婭婭婭呱䴸䅉䅅䅁䑁䅁䅁睁䵁䅁䅁兂䅁䅁䅁爳剴兑䅯睋䅁䅁䅅䅁䉁䅁䅁权䙁䅁䅁䍄䉁䅁䅁睁䅁䅁䅍䅄䅁䅁䅕䅁䅁䉁桺歔䭅䅁䅑䅁䉁䅁䅁允䅁䅁䅯兂䅁䅁杷允䅁䅁䅍䅁䑁䅁䅷䅁䙁䅁䅁䕁㡂ㅭ䉂权偁䅁䅁允䅁䅁䅅䅁䙁䵁ㅐ䙋偹癷⽫䍄䉁䅁䅁睁䅁䅁䅍䅄䅁䅁䅕䅁䅁䩷椵啕䭅䅁䄴䅁䉁䅁䅁允䅁䅁䅕歲桦桥畓商䵁䅉䅅䅁䑁䅁䅁睁䵁䅁䅁兂䅁䅁䅁㕎兤兑䅯䅄䅁䅁䅅䅁䉁䅁䅁兂塄㍯㥁瑃汣䅑杷允䅁䅁䅍䅁䑁䅁䅷䅁䙁䅁䅁䅁㍁ㅬ䉂权塁䅁䅁允䅁䅁䅅䅁䭁䉁䅅䅁䵁䅉䅅䅁䑁䅁䅁睁䵁䅁䅁兂䅁䅁䅁䱹剸兑䅯䅊䅁䅁䅅䅁䉁䅁䅁兂䭁㘱睎児㍲睐杷允䅁䅁䅍䅁䑁䅁䅷䅁䙁䅁䅁䵁牄䙈䉂权扁䅁䅁允䅁䅁䅅䅁䭁䅁䅕䅁䵁䅉䅅䅁䑁䅁䅁睁䵁䅁䅁兂䅁䅁䅁婹兰兑䅯䅊䅁䅁䅅䅁䉁䅁䅁兂畃⭒㙆䭆栴䅑杷允䅁䅁䅍䅁䑁䅁䅷䅁䙁䅁䅁䅁敃汋䉆权䡁䅁䅁允䅁䅁䅅䅁䭁䅁䅕䅁䵁䅉䅅䅁䑁䅁䅁睁䵁䅁䅁兂䅁䅁䅃灪儱兑䅯兊䅁䅁䅅䅁䉁䅁䅁权䙁䅁䅁䍄䉁䅁䅁睁䅁䅁䅍䅄䅁䅁䅕䅁䅁䑁塱䕕䭅䍁䅧䅁䉁䅁䅁允䅁䅁䅯兂䅁䅁杷允䅁䅁䅍䅁䑁䅁䅷䅁䙁䅁䅁䥁佃噮䉂权湁䅁䅁允䅁䅁䅅䅁䙁䱁敧敨剴䭵⼴䍄䉁䅁䅁睁䅁䅁䅍䅄䅁䅁䅕䅁䅁䡷湡䕕䭅䍁䅕䅁䉁䅁䅁允䅁䅁䅯兂䅁䅁杷允䅁䅁䅍䅁䑁䅁䅷䅁䙁䅁䅁䅁捁唴䈵权潁䅁䅁允䅁䅁䅅䅁䭁䅁䅕䅁䵁䅉䅅䅁䑁䅁䅁睁䵁䅁䅁兂䅁䅁䅁灚全兑䅯睉䅁䅁䅅䅁䉁䅁䅁权䙁䅁䅁䍄䉁䅁䅁睁䅁䅁䅍䅄䅁䅁䅕䅁䅁䵧奏䕕䭅䉁䅉䅁䉁䅁䅁允䅁䅁䅯充䅁䅁杷允䅁䅁䅍䅁䑁䅁䅷䅁䙁䅁䅁䕁橁噴䉂权汁䅁䅁允䅁䅁䅅䅁䭁䅁䅕䅁䵁䅉䅅䅁䑁䅁䅁睁䵁䅁䅁兂䅁䅁䅄煤兤兑䅯睂䅁䅁䅅䅁䉁䅁䅁权䙁䅁䅁䍄䉁䅁䅁睁䅁䅁䅍䅄䅁䅁䅕䅁䅁䉁桺歔䭅䉁䅙䅁䉁䅁䅁允䅁䅁䅯兂䅁䅁杷允䅁䅁䅍䅁䑁䅁䅷䅁䙁䅁䅁䥁䑄䙭䉂权流䅁䅁允䅁䅁䅅䅁䭁䅁䅕䅁䵁䅉䅅䅁䑁䅁䅁睁䵁䅁䅁兂䅁䅁䅄煤兤兑䅯杄䅁䅁䅅䅁䉁䅁䅁权䙁䅁䅁䍄䉁䅁䅁睁䅁䅁䅍䅄䅁䅁䅕䅁䅁䉁桺歔䭅䍁䅳䅁䉁䅁䅁允䅁䅁䅯兂䅁䅁杷允䅁䅁䅍䅁䑁䅁䅷䅁䙁䅁䅁䵁祂噭䉂权牁䅁䅁允䅁䅁䅅䅁䭁䅁䅕䅁䵁䅉䅅䅁䑁䅁䅁睁䵁䅁䅁兂䅁䅁䅁㕎兤兑䅯睈䅁䅁䅅䅁䉁䅁䅁兂䭁㘱睎奐㍯䅑杷允䅁䅁䅍䅁䑁䅁䅷䅁䙁䅁䅁䅁㙁ㅬ䉂权橁䅁䅁允䅁䅁䅅䅁䭁䅁䅕䅁䵁䅉䅅䅁䑁䅁䅁睁䵁䅁䅁兂䅁䅁䅁䩥公兑䅯睃䅁䅁䅅䅁䉁䅁䅁权䙁䅁䅁䍄䉁䅁䅁睁䅁䅁䅍䅄䅁䅁䅕䅁䅁䝁批䕕䭅䍁䅳䅁䉁䅁䅁允䅁䅁䅯兂䅁䅁杷允䅁䅁䅍䅁䑁䅁䅷䅁䙁䅁䅁䅁捁唴䈵权婁䅁䅁允䅁䅁䅅䅁䭁䅁䅕䅁䵁䅉䅅䅁䑁䅁䅁睁䵁䅁䅁兂䅁䅁䅁灏兤兑䅯睆䅁䅁䅅䅁䉁䅁䅁权睁䅁䅁䍄䉁䅁䅁睁䅁䅁䅍䅄䅁䅁䅕䅁䅁䵷卶す䭅䍁䅣䅁䉁䅁䅁允䅁䅁䅯兂䅁䅁杷允䅁䅁䅍䅁䑁䅁䅷䅁䙁䅁䅁䥁䙁䙢䉆权捁䅁䅁允䅁䅁䅅䅁䭁䅁䅕䅁䵁䅉䅅䅁䑁䅁䅁睁䵁䅁䅁兂䅁䅁䅄㥹橊兑䅯杆䅁䅁䅅䅁䉁䅁䅁权䙁䅁䅁䍄䉁䅁䅁睁䅁䅁䅍䅄䅁䅁䅕䅁䅁䥧摓䕕䭅䅁䄸䅁䉁䅁䅁允䅁䅁䅯兂䅁䅁杷允䅁䅁䅍䅁䑁䅁䅷䅁䙁䅁䅁䡁㍄湦䉊权牁䅁䅁允䅁䅁䅅䅁䭁䅁䅕䅁䵁䅉䅅䅁䑁䅁䅁睁䵁䅁䅁兂䅁䅁䅄瀷公兑䅯兄䅁䅁䅅䅁䉁䅁䅁权剁䅁䅁䍄䉁䅁䅁睁䅁䅁䅍䅄䅁䅁䅕䅁䅁䡑批䕕䭅䅁䅙䅁䉁䅁䅁允䅁䅁䅕硥畓⭒㙆䑨䴸䅉䅅䅁䑁䅁䅁睁䵁䅁䅁兂䅁䅁䅃坂剸兑䅯杇䅁䅁䅅䅁䉁䅁䅁权䙁䅁䅁䍄䉁䅁䅁睁䅁䅁䅍䅄䅁䅁䅕䅁䅁䑁塱䕕䭅䉁䅉䅁䉁䅁䅁允䅁䅁䅯睌䅁䅁杷允䅁䅁䅍䅁䑁䅁䅷䅁䙁䅁䅁䕁橁噴䉂权坁䅁䅁允䅁䅁䅅䅁䭁䅁䅕䅁䵁䅉䅅䅁䑁䅁䅁睁䵁䅁䅁兂䅁䅁䅃楨剸兑䅯䅃䅁䅁䅅䅁䉁䅁䅁权䙁䅁䅁䍄䉁䅁䅁睁䅁䅁䅍䅄䅁䅁䅕䅁䅁䑑慭䕕䭅䍁䅁䅁䉁䅁䅁允䅁䅁䅯兂䅁䅁杷允䅁䅁䅍䅁䑁䅁䅷䅁䙁䅁䅁䕁㕁汭䉂权婁䅁䅁允䅁䅁䅅䅁䭁䅁䅕䅁䵁䅉䅅䅁䑁䅁䅁睁䵁䅁䅁兂䅁䅁䅃汆㜵兑䅯杇䅁䅁䅅䅁䉁䅁䅁权䙁䅁䅁䍄䉁䅁䅁睁䅁䅁䅍䅄䅁䅁䅕䅁䅁䵷卶す䭅䉁䅣䅁䉁䅁䅁允䅁䅁䅯充䅁䅁杷允䅁䅁䅍䅁䑁䅁䅷䅁䙁䅁䅁䥁ㅁ噭䉂权坁䅁䅁允䅁䅁䅅䅁䭁䅁䅕䅁䵁䅉䅅䅁䑁䅁䅁睁䵁䅁䅁兂䅁䅁䅁獲兖兑䅯睇䅁䅁䅅䅁䉁䅁䅁权䙁䅁䅁䍄䉁䅁䅁睁䅁䅁䅍䅄䅁䅁䅕䅁䅁䑁塱䕕䭅䉁䅑䅁䉁䅁䅁允䅁䉁䅑倲䝆䅁䅁䅁䵁䅉䅅䅁䑁䅁䅁睁䵁䅁䅁兂䅁䅁䅁㕎兤兑䅯䅈䅁䅁䅅䅁䉁䅁䅁兂乄䵺䵺䕺湷䅑杷允䅁䅁䅍䅁䑁䅁䅷䅁䙁䅁䅁䥁佃噮䉂权塁䅁䅁允䅁䅁䅅䅁䭁䉁䅅䅁䵁䅉䅅䅁䑁䅁䅁睁䵁䅁䅁兂䅁䅁䅁婹兰兑䅯睆䅁䅁䅅䅁䉁䅁䅁权剁䅁䅁䍄䉁䅁䅁睁䅁䅁䅍䅄䅁䅁䅕䅁䅁䉧敚づ䭅䅁䅳䅁䉁䅁䅁允䅁䅁䅯兂䅁䅁杷允䅁䅁䅍䅁䑁䅁䅷䅁䙁䅁䅁䕁㡂ㅭ䉂权允䅁䅁允䅁䅁䅅䅁䭁䉁䅅䅁䵁䅉䅅䅁䑁䅁䅁睁䵁䅁䅁兂䅁䅁䅄慏兎兑䅯兄䅁䅁䅅䅁䉁䅁䅁权畁䅁䅁䍄䉁䅁䅁睁䅁䅁䅍䅄䅁䅁䅕䅁䅁䝁批䕕䭅䉁䅁䅁䉁䅁䅁允䅁䅁䅯充䅁䅁杷允䅁䅁䅍䅁䑁䅁䅷䅁䙁䅁䅁䵁㕁ㅯ䉂权䱁䅁䅁允䅁䅁䅅䅁䭁䅁䅕䅁䵁䅉䅅䅁䑁䅁䅁睁䵁䅁䅁兂䅁䅁䅄慏兎兑䅯杇䅁䅁䅅䅁䉁䅁䅁权䙁䅁䅁䍄䉁䅁䅁睁䅁䅁䅍䅄䅁䅁䅕䅁䅁䑁塱䕕䭅䉁䄴䅁䉁䅁䅁允䅁䅁䅕䉵䘶ㄶ㑇橲䴸䅉䅅䅁䑁䅁䅁睁䵁䅁䅁兂䅁䅁䅃婎公兑䅯䅄䅁䅁䅅䅁䉁䅁䅁兂䙃ㄶ㑇杈乖䅑杷允䅁䅁䅍䅁䑁䅁䅷䅁䙁䅁䅁䅁㍁ㅬ䉂权允䅁䅁允䅁䅁䅅䅁䭁䉁䅅䅁䵁䅉䅅䅁䑁䅁䅁睁䵁䅁䅁兂䅁䅁䅂婢兰兑䅯睄䅁䅁䅅䅁䉁䅁䅁权䙁䅁䅁䍄䉁䅁䅁睁䅁䅁䅍䅄䅁䅁䅕䅁䅁䝁奡䕕䭅䍁䅕䅁䉁䅁䅁允䅁䅁䅯兂䅁䅁杷允䅁䅁䅍䅁䑁䅁䅷䅁䙁䅁䅁䵁㕁ㅯ䉂权䕁䅁䅁允䅁䅁䅅䅁䭁䅁䅕䅁䵁䅉䅅䅁䑁䅁䅁睁䵁䅁䅁兂䅁䅁䅃楨剸兑䅯䅆䅁䅁䅅䅁䉁䅁䅁权䙁䅁䅁䍄䉁䅁䅁睁䅁䅁䅍䅄䅁䅁䅕䅁䅁䩁焴啕䭅䅁䅙䅁䉁䅁䅁允䅁䅁䅯兂䅁䅁杷允䅁䅁䅍䅁䑁䅁䅷䅁䙁䅁䅁䅁㙁ㅬ䉂权扁䅁䅁允䅁䅁䅅䅁䭁䅁䅕䅁䵁䅉䅅䅁䑁䅁䅁睁䵁䅁䅁兂䅁䅁䅁䱹剸兑䅯睆䅁䅁䅅䅁䉁䅁䅁权剁䅁䅁䍄䉁䅁䅁睁䅁䅁䅍䅄䅁䅁䅕䅁䅁䅑㑔じ䭅䉁䅷䅁䉁䅁䅁允䅁䅁䅯兂䅁䅁杷允䅁䅁䅍䅁䑁䅁䅷䅁䙁䅁䅁䅁獂ㅭ䉂权䵁䅁䅁允䅁䅁䅅䅁䭁䅁䅕䅁䵁䅉䅅䅁䑁䅁䅁睁䵁䅁䅁兂䅁䅁䅁灏兤兑䅯䅃䅁䅁䅅䅁䉁䅁䅁权䙁䅁䅁䍄䉁䅁䅁睁䅁䅁䅍䅄䅁䅁䅕䅁䅁䩁焴啕䭅䅁䅧䅁䉁䅁䅁允䅁䅁䅯兂䅁䅁杷允䅁䅁䅍䅁䑁䅁䅷䅁䙁䅁䅁䥁䙁䙢䉆权晁䅁䅁允䅁䅁䅅䅁䭁䅁䅕䅁䵁䅉䅅䅁䑁䅁䅁睁䵁䅁䅁兂䅁䅁䅃灪儱兑䅯䅆䅁䅁䅅䅁䉁䅁䅁权䙁䅁䅁䍄䉁䅁䅁睁䅁䅁䅍䅄䅁䅁䅕䅁䅁乁戴啗䭅䉁䅯䅁䉁䅁䅁允䅁䅁䅯兂䅁䅁杷允䅁䅁䅍䅁䑁䅁䅷䅁䙁䅁䅁䅁㙁ㅬ䉂权楁䅁䅁允䅁䅁䅅䅁䭁䅁䅕䅁䵁䅉䅅䅁䑁䅁䅁睁䵁䅁䅁兂䅁䅁䅁䩢兴兑䅯睈䅁䅁䅅䅁䉁䅁䅁权䙁䅁䅁䍄䉁䅁䅁睁䅁䅁䅍䅄䅁䅁䅕䅁䅁䑧婗䕕䭅䉁䄴䅁䉁䅁䅁允䅁䉁䅑䅁䅁䅁䅁䅁䵁䅉䅅䅁䑁䅁䅁睁䵁䅁䅁兂䅁䅁䅄灣公兑䅯睂䅁䅁䅅䅁䉁䅁䅁权䙁䅁䅁䍄䉁䅁䅁睁䅁䅁䅍䅄䅁䅁䅕䅁䅁䑧婗䕕䭅䍁䅧䅁䉁䅁䅁允䅁䅁䅯兂䅁䅁杷允䅁䅁䅍䅁䑁䅁䅷䅁䙁䅁䅁䕁瑂汭䉂权流䅁䅁允䅁䅁䅅䅁䭁䅁䅕䅁䵁䅉䅅䅁䑁䅁䅁睁䵁䅁䅁兂䅁䅁䅁灏兤兑䅯䅉䅁䅁䅅䅁䉁䅁䅁权䙁䅁䅁䍄䉁䅁䅁睁䅁䅁䅍䅄䅁䅁䅕䅁䅁䥧摓䕕䭅䉁䅯䅁䉁䅁䅁允䅁䅁䅯兂䅁䅁杷允䅁䅁䅍䅁䑁䅁䅷䅁䙁䅁䅁䅁䩄汭䉂权乁䅁䅁允䅁䅁䅅䅁䭁䉁䅅䅁䵁䅉䅅䅁䑁䅁䅁睁䵁䅁䅁兂䅁䅁䅂㝉兖兑䅯杊䅁䅁䅅䅁䉁䅁䅁权䙁䅁䅁䍄䉁䅁䅁睁䅁䅁䅍䅄䅁䅁䅕䅁䅁䡁挶啕䭅䉁䅉䅁䉁䅁䅁允䅁䅁䅯充䅁䅁杷允䅁䅁䅍䅁䑁䅁䅷䅁䙁䅁䅁䥁䑄䙭䉂权湁䅁䅁允䅁䅁䅅䅁䭁䅁䅕䅁䵁䅉䅅䅁䑁䅁䅁睁䵁䅁䅁兂䅁䅁䅃汆㜵兑䅯睉䅁䅁䅅䅁䉁䅁䅁权䙁䅁䅁䍄䉁䅁䅁睁䅁䅁䅍䅄䅁䅁䅕䅁䅁䝑愲䕕䭅䍁䅉䅁䉁䅁䅁允䅁䅁䅯兂䅁䅁杷允䅁䅁䅍䅁䑁䅁䅷䅁䙁䅁䅁䥁佃噮䉂权坁䅁䅁允䅁䅁䅅䅁䙁䡁啳歲桦獥⽑䍄䉁䅁䅁睁䅁䅁䅍䅄䅁䅁䅕䅁䅁䩁焴啕䭅䅁䄴䅁䉁䅁䅁允䅁䅁䅯兂䅁䅁杷允䅁䅁䅍䅁䑁䅁䅷䅁䙁䅁䅁䅁楃歙䈹权䩁䅁䅁允䅁䅁䅅䅁䭁䑁䅅䅁䵁䅉䅅䅁䑁䅁䅁睁䵁䅁䅁兂䅁䅁䅁灚全兑䅯睂䅁䅁䅅䅁䉁䅁䅁权䙁䅁䅁䍄䉁䅁䅁睁䅁䅁䅍䅄䅁䅁䅕䅁䅁䭁䘷䕕䭅䉁䅫䅁䉁䅁䅁允䅁䅁䅯兂䅁䅁杷允䅁䅁䅍䅁䑁䅁䅷䅁䙁䅁䅁䥁佃噮䉂权敁䅁䅁允䅁䅁䅅䅁䙁䱁敧敨剴䅵䅊䍄䉁䅁䅁睁䅁䅁䅍䅄䅁䅁䅕䅁䅁䑁塱䕕䭅䅁䅷䅁䉁䅁䅁允䅁䅁䅕場啯歲桤ぉ䵁䅉䅅䅁䑁䅁䅁睁䵁䅁䅁兂䅁䅁䅂㝉兖兑䅯杄䅁䅁䅅䅁䉁䅁䅁权䙁䅁䅁䍄䉁䅁䅁睁䅁䅁䅍䅄䅁䅁䅕䅁䅁䝑愲䕕䭅䅁䄴䅁䉁䅁䅁允䅁䅁䅯兂䅁䅁杷允䅁䅁䅍䅁䑁䅁䅷䅁䙁䅁䅁䥁䕃噮䉂权允䅁䅁允䅁䅁䅅䅁䭁䑁䅉䅁䵁䅉䅅䅁䑁䅁䅁睁䵁䅁䅁兂䅁䅁䅁栳婴兑䅯䅋䅁䅁䅅䅁䉁䅁䅁权䙁䅁䅁䍄䉁䅁䅁睁䅁䅁䅍䅄䅁䅁䅕䅁䅁䥧搶䕕䭅䍁䅉䅁䉁䅁䅁允䅁䅁䅯兂䅁䅁杷允䅁䅁䅍䅁䑁䅁䅷䅁䙁䅁䅁䅁敃汋䉆权汁䅁䅁允䅁䅁䅅䅁䭁䅁䅕䅁䵁䅉䅅䅁䑁䅁䅁睁䵁䅁䅁兂䅁䅁䅄㥹橊兑䅯䅃䅁䅁䅅䅁䉁䅁䅁权䙁䅁䅁䍄䉁䅁䅁睁䅁䅁䅍䅄䅁䅁䅕䅁䅁䑁塱䕕䭅䍁䅕䅁䉁䅁䅁允䅁䅁䅯兂䅁䅁杷允䅁䅁䅍䅁䑁䅁䅷䅁䙁䅁䅁䅁䩄汭䉂权敁䅁䅁允䅁䅁䅅䅁䙁䕁桪桥畓祒䅰䍄䉁䅁䅁睁䅁䅁䅍䅄䅁䅁䅕䅁䅁䱧坵䕕䭅䉁䄸䅁䉁䅁䅁允䅁䅁䅯兂䅁䅁杷允䅁䅁䅍䅁䑁䅁䅷䅁䙁䅁䅁䅁獂ㅭ䉂权捁䅁䅁允䅁䅁䅅䅁䭁䅁䅕䅁䵁䅉䅅䅁䑁䅁䅁睁䵁䅁䅁兂䅁䅁䅄浮削兑䅯睆䅁䅁䅅䅁䉁䅁䅁权剁䅁䅁䍄䉁䅁䅁睁䅁䅁䅍䅄䅁䅁䅕䅁䅁佷捳䕕䭅䉁䄴䅁䉁䅁䅁允䅁䅁䅕⽷潕䥘䌯启䴸䅉䅅䅁䑁䅁䅁睁䵁䅁䅁兂䅁䅁䅂㕣公兑䅯元䅁䅁䅅䅁䉁䅁䅁权䭁䅁䅁䍄䉁䅁䅁睁䅁䅁䅍䅄䅁䅁䅕䅁䅁䥧摓䕕䭅䅁䅙䅁䉁䅁䅁允䅁䅁䅯兂䅁䅁杷允䅁䅁䅍䅁䑁䅁䅷䅁䙁䅁䅁䥁ㅁ噭䉂权汁䅁䅁允䅁䅁䅅䅁䭁䅁䅕䅁䵁䅉䅅䅁䑁䅁䅁睁䵁䅁䅁兂䅁䅁䅄瀷公兑䅯元䅁䅁䅅䅁䉁䅁䅁权㑁䅁䅁䍄䉁䅁䅁睁䅁䅁䅍䅄䅁䅁䅕䅁䅁䝁批䕕䭅䅁䅳䅁䉁䅁䅁允䅁䅁䅯兂䅁䅁杷允䅁䅁䅍䅁䑁䅁䅷䅁䙁䅁䅁䅁畃噸䉂权敁䅁䅁允䅁䅁䅅䅁䭁䅁䅕䅁䵁䅉䅅䅁䑁䅁䅁睁䵁䅁䅁兂䅁䅁䅁歆倱兑䅯兇䅁䅁䅅䅁䉁䅁䅁权䙁䅁䅁䍄䉁䅁䅁睁䅁䅁䅍䅄䅁䅁䅕䅁䅁䑧婗䕕䭅䅁䄸䅁䉁䅁䅁允䅁䅁䅕䭆䠵場啯歂䵁䅉䅅䅁䑁䅁䅁睁䵁䅁䅁兂䅁䅁䅁灚全兑䅯䅃䅁䅁䅅䅁䉁䅁䅁权䙁䅁䅁䍄䉁䅁䅁睁䅁䅁䅍䅄䅁䅁䅕䅁䅁䉧敚づ䭅䅁䄸䅁䉁䅁䅁允䅁䅁䅯兂䅁䅁杷允䅁䅁䅍䅁䑁䅁䅷䅁䙁䅁䅁䥁䑄䙭䉂权偁䅁䅁允䅁䅁䅅䅁䭁䅁䅕䅁䵁䅉䅅䅁䑁䅁䅁睁䵁䅁䅁兂䅁䅁䅄瀷公兑䅯睂䅁䅁䅅䅁䉁䅁䅁权䙁䅁䅁䍄䉁䅁䅁睁䅁䅁䅍䅄䅁䅁䅕䅁䅁䅑㑔じ䭅䍁䅙䅁䉁䅁䅁允䅁䅁䅯兂䅁䅁杷允䅁䅁䅍䅁䑁䅁䅷䅁䙁䅁䅁䅁㙁ㅬ䉂权晁䅁䅁允䅁䅁䅅䅁䭁䅁䅕䅁䵁䅉䅅䅁䑁䅁䅁睁䵁䅁䅁兂䅁䅁䅄灣公兑䅯睉䅁䅁䅅䅁䉁䅁䅁权䙁䅁䅁䍄䉁䅁䅁睁䅁䅁䅍䅄䅁䅁䅕䅁䅁䝑愲䕕䭅䍁䅍䅁䉁䅁䅁允䅁䅁䅯兂䅁䅁杷允䅁䅁䅍䅁䑁䅁䅷䅁䙁䅁䅁䅁獂ㅭ䉂权䝁䅁䅁允䅁䅁䅅䅁䭁䅁䅕䅁䵁䅉䅅䅁䑁䅁䅁睁䵁䅁䅁兂䅁䅁䅃婎公兑䅯杊䅁䅁䅅䅁䉁䅁䅁权䙁䅁䅁䍄䉁䅁䅁睁䅁䅁䅍䅄䅁䅁䅕䅁䅁䝁奡䕕䭅䅁䅷䅁䉁䅁䅁允䅁䅁䅯兂䅁䅁杷允䅁䅁䅍䅁䑁䅁䅷䅁䙁䅁䅁䵁㉂ㅰ䉂权楁䅁䅁允䅁䅁䅅䅁䭁䅁䅕䅁䵁䅉䅅䅁䑁䅁䅁睁䵁䅁䅁兂䅁䅁䅃㕵党兑䅯兄䅁䅁䅅䅁䉁䅁䅁权剁䅁䅁䍄䉁䅁䅁睁䅁䅁䅍䅄䅁䅁䅕䅁䅁䑁塱䕕䭅䉁䅙䅁䉁䅁䅁允䅁䅁䅯兂䅁䅁杷允䅁䅁䅍䅁䑁䅁䅷䅁䙁䅁䅁䕁噄汭䉂权婁䅁䅁允䅁䅁䅅䅁䭁䅁䅕䅁䵁䅉䅅䅁䑁䅁䅁睁䵁䅁䅁兂䅁䅁䅁灦剸兑䅯䅄䅁䅁䅅䅁䉁䅁䅁权䙁䅁䅁䍄䉁䅁䅁睁䅁䅁䅍䅄䅁䅁䅕䅁䅁䑁塱䕕䭅䉁䅯䅁䉁䅁䅁允䅁䅁䅯兂䅁䅁杷允䅁䅁䅍䅁䑁䅁䅷䅁䙁䅁䅁䵁㉂ㅰ䉂权湁䅁䅁允䅁䅁䅅䅁䭁䅁䅕䅁䵁䅉䅅䅁䑁䅁䅁睁䵁䅁䅁兂䅁䅁䅃楨剸兑䅯䅈䅁䅁䅅䅁䉁䅁䅁权䙁䅁䅁䍄䉁䅁䅁睁䅁䅁䅍䅄䅁䅁䅕䅁䅁䝁奡䕕䭅䅁䅫䅁䉁䅁䅁允䅁䅁䅯光䅁䅁杷允䅁䅁䅍䅁䑁䅁䅷䅁䙁䅁䅁䥁ㅁ噭䉂权䝁䅁䅁允䅁䅁䅅䅁䙁䑁䬰㘱睎敐⽯䍄䉁䅁䅁睁䅁䅁䅍䅄䅁䅁䅕䅁䅁䅧獖啕䭅䅁䄴䅁䉁䅁䅁允䅁䅁䅯兂䅁䅁杷允䅁䅁䅍䅁䑁䅁䅷䅁䙁䅁䅁䅁坁啔䈹权䝁䅁䅁允䅁䅁䅅䅁䭁䅁䅕䅁䵁䅉䅅䅁䑁䅁䅁睁䵁䅁䅁兂䅁䅁䅁灚全兑䅯兄䅁䅁䅅䅁䉁䅁䅁权桁䅁䅁䍄䉁䅁䅁睁䅁䅁䅍䅄䅁䅁䅕䅁䅁䑁塱䕕䭅䍁䅳䅁䉁䅁䅁允䅁䅁䅯兂䅁䅁杷允䅁䅁䅍䅁䑁䅁䅷䅁䙁䅁䅁䵁畄噭䉂权捁䅁䅁允䅁䅁䅅䅁䙁䅁塲㍯㥁歓䅤䍄䉁䅁䅁睁䅁䅁䅍䅄䅁䅁䅕䅁䅁䅑㑔じ䭅䉁䅫䅁䉁䅁䅁允䅁䅁䅯兂䅁䅁杷允䅁䅁䅍䅁䑁䅁䅷䅁䙁䅁䅁䅁䥄䙶䉆权坁䅁䅁允䅁䅁䅅䅁䭁䅁䅕䅁䵁䅉䅅䅁䑁䅁䅁睁䵁䅁䅁兂䅁䅁䅁㕎兤兑䅯䅆䅁䅁䅅䅁䉁䅁䅁权䙁䅁䅁䍄䉁䅁䅁睁䅁䅁䅍䅄䅁䅁䅕䅁䅁䥧獙啕䭅䅁䅷䅁䉁䅁䅁允䅁䅁䅯兂䅁䅁杷允䅁䅁䅍䅁䑁䅁䅷䅁䙁䅁䅁䅁㙁ㅬ䉂权佁䅁䅁允䅁䅁䅅䅁䙁䱁敧敨剴䙱䅂䍄䉁䅁䅁睁䅁䅁䅍䅄䅁䅁䅕䅁䅁䡧䅎ご䭅䉁䅣䅁䉁䅁䅁允䅁䅁䅯充䅁䅁杷允䅁䅁䅍䅁䑁䅁䅷䅁䙁䅁䅁䥁䕃噮䉂权䩁䅁䅁允䅁䅁䅅䅁䭁䑁䅉䅁䵁䅉䅅䅁䑁䅁䅁睁䵁䅁䅁兂䅁䅁䅃楨剸兑䅯睄䅁䅁䅅䅁䉁䅁䅁权䙁䅁䅁䍄䉁䅁䅁睁䅁䅁䅍䅄䅁䅁䅕䅁䅁䑧婗䕕䭅䍁䅍䅁䉁䅁䅁允䅁䅁䅯兂䅁䅁杷允䅁䅁䅍䅁䑁䅁䅷䅁䙁䅁䅁䥁䕃噮䉂权乁䅁䅁允䅁䅁䅅䅁䭁䑁䅉䅁䵁䅉䅅䅁䑁䅁䅁睁䵁䅁䅁兂䅁䅁䅃䩨儱兑䅯䅋䅁䅁䅅䅁䉁䅁䅁权䙁䅁䅁䍄䉁䅁䅁睁䅁䅁䅍䅄䅁䅁䅕䅁䅁䡁婩䕕䭅䉁䅙䅁䉁䅁䅁允䅁䅁䅯兂䅁䅁杷允䅁䅁䅍䅁䑁䅁䅷䅁䙁䅁䅁䕁㡂ㅭ䉂权婁䅁䅁允䅁䅁䅅䅁䙁䭁䠵場啯歲䅚䍄䉁䅁䅁睁䅁䅁䅍䅄䅁䅁䅕䅁䅁䉧敚づ䭅䅁䄴䅁䉁䅁䅁允䅁䅁䅯兂䅁䅁杷允䅁䅁䅍䅁䑁䅁䅷䅁䙁䅁䅁䥁䕃噮䉂权十䅁䅁允䅁䅁䅅䅁䭁䑁䅍䅁䵁䅉䅅䅁䑁䅁䅁睁䵁䅁䅁兂䅁䅁䅃䩨儱兑䅯睆䅁䅁䅅䅁䉁䅁䅁权ぁ䅁䅁䍄䉁䅁䅁睁䅁䅁䅍䅄䅁䅁䅕䅁䅁䩑摃䕕䭅䉁䅳䅁䉁䅁䅁允䅁䅁䅯兂䅁䅁杷允䅁䅁䅍䅁䑁䅁䅷䅁䙁䅁䅁䅁䥄䙶䉆权允䅁䅁允䅁䅁䅅䅁䭁䉁䅅䅁䵁䅉䅅䅁䑁䅁䅁睁䵁䅁䅁兂䅁䅁䅃䩨儱兑䅯䅆䅁䅁䅅䅁䉁䅁䅁䅆㉂お䅑䅁䅁䅁杷允䅁䅁䅍䅁䑁䅁䅷䅁䙁䅁䅁䥁䕃噮䉂权捁䅁䅁允䅁䅁䅅䅁䙁乁橥䑣䬰砱䅤䍄䉁䅁䅁睁䅁䅁䅍䅄䅁䅁䅕䅁䅁䡷湡䕕䭅䍁䅁䅁䉁䅁䅁允䅁䅁䅯兂䅁䅁杷允䅁䅁䅍䅁䑁䅁䅷䅁䙁䅁䅁䵁䱄洰䉎权晁䅁䅁允䅁䅁䅅䅁䭁䅁䅕䅁䵁䅉䅅䅁䑁䅁䅁睁䵁䅁䅁兂䅁䅁䅁㕎兤兑䅯杆䅁䅁䅅䅁䉁䅁䅁权䙁䅁䅁䍄䉁䅁䅁睁䅁䅁䅍䅄䅁䅁䅕䅁䅁䝁批䕕䭅䉁䅑䅁䉁䅁䅁允䅁䅁䅯兂䅁䅁杷允䅁䅁䅍䅁䑁䅁䅷䅁䙁䅁䅁䥁䕃噮䉂权敁䅁䅁允䅁䅁䅅䅁䭁䅁䅕䅁䵁䅉䅅䅁䑁䅁䅁睁䵁䅁䅁兂䅁䅁䅄煤兤兑䅯䅋䅁䅁䅅䅁䉁䅁䅁权䙁䅁䅁䍄䉁䅁䅁睁䅁䅁䅍䅄䅁䅁䅕䅁䅁䑧婗䕕䭅䍁䅳䅁䉁䅁䅁允䅁䅁䅯兂䅁䅁杷允䅁䅁䅍䅁䑁䅁䅷䅁䙁䅁䅁䅁⭂䙮䉆权流䅁䅁允䅁䅁䅅䅁䭁䅁䅕䅁䵁䅉䅅䅁䑁䅁䅁睁䵁䅁䅁兂䅁䅁䅁歆倱兑䅯䅂䅁䅁䅅䅁䉁䅁䅁兂捂㡪ㅌ之煷䅑杷允䅁䅁䅍䅁䑁䅁䅷䅁䙁䅁䅁䵁祂噭䉂权坁䅁䅁允䅁䅁䅅䅁䭁䅁䅕䅁䵁䅉䅅䅁䑁䅁䅁睁䵁䅁䅁兂䅁䅁䅁浯偊兑䅯杅䅁䅁䅅䅁䉁䅁䅁权剁䅁䅁䍄䉁䅁䅁睁䅁䅁䅍䅄䅁䅁䅕䅁䅁䡑婏䕕䭅䍁䅉䅁䉁䅁䅁允䅁䅁䅯兂䅁䅁杷允䅁䅁䅍䅁䑁䅁䅷䅁䙁䅁䅁䥁䕃噮䉂权楁䅁䅁允䅁䅁䅅䅁䭁䅁䅕䅁䵁䅉䅅䅁䑁䅁䅁睁䵁䅁䅁兂䅁䅁䅃䩨儱兑䅯䅉䅁䅁䅅䅁䉁䅁䅁兂塄㍯㥁瑃塣䅑杷允䅁䅁䅍䅁䑁䅁䅷䅁䙁䅁䅁䡁㍄湦䉊权杁䅁䅁允䅁䅁䅅䅁䭁䅁䅕䅁䵁䅉䅅䅁䑁䅁䅁睁䵁䅁䅁兂䅁䅁䅁浯偊兑䅯杆䅁䅁䅅䅁䉁䅁䅁兂卂䉵䘶ㄶ䥈睐杷允䅁䅁䅍䅁䑁䅁䅷䅁䙁䅁䅁䵁敃汙䉆权䱁䅁䅁允䅁䅁䅅䅁䭁䅁䅕䅁䵁䅉䅅䅁䑁䅁䅁睁䵁䅁䅁兂䅁䅁䅄浮削兑䅯睋䅁䅁䅅䅁䉁䅁䅁权䙁䅁䅁䍄䉁䅁䅁睁䅁䅁䅍䅄䅁䅁䅕䅁䅁䵁㡩啕䭅䉁䅯䅁䉁䅁䅁允䅁䅁䅯兂䅁䅁杷允䅁䅁䅍䅁䑁䅁䅷䅁䙁䅁䅁䅁坁啔䈹权杁䅁䅁允䅁䅁䅅䅁䭁䅁䅕䅁䵁䅉䅅䅁䑁䅁䅁睁䵁䅁䅁兂䅁䅁䅃坂剸兑䅯杂䅁䅁䅅䅁䉁䅁䅁权䙁䅁䅁䍄䉁䅁䅁睁䅁䅁䅍䅄䅁䅁䅕䅁䅁䅑㑔じ䭅䉁䅯䅁䉁䅁䅁允䅁䅁䅯兂䅁䅁杷允䅁䅁䅍䅁䑁䅁䅷䅁䙁䅁䅁䥁䕃噮䉂权䵁䅁䅁允䅁䅁䅅䅁䭁䅁䅕䅁䵁䅉䅅䅁䑁䅁䅁睁䵁䅁䅁兂䅁䅁䅁灦剸兑䅯睄䅁䅁䅅䅁䉁䅁䅁权䙁䅁䅁䍄䉁䅁䅁睁䅁䅁䅍䅄䅁䅁䅕䅁䅁䍑ㅏ䕕䭅䍁䅑䅁䉁䅁䅁允䅁䅁䅕呣䬰㘱睎呺䴸䅉䅅䅁䑁䅁䅁睁䵁䅁䅁兂䅁䅁䅃坂剸兑䅯睇䅁䅁䅅䅁䉁䅁䅁权䙁䅁䅁䍄䉁䅁䅁睁䅁䅁䅍䅄䅁䅁䅕䅁䅁䡁婩䕕䭅䍁䅕䅁䉁䅁䅁允䅁䅁䅯兂䅁䅁杷允䅁䅁䅍䅁䑁䅁䅷䅁䙁䅁䅁䥁䕃噮䉂权橁䅁䅁允䅁䅁䅅䅁䭁䅁䅕䅁䵁䅉䅅䅁䑁䅁䅁睁䵁䅁䅁兂䅁䅁䅁灚全兑䅯杂䅁䅁䅅䅁䉁䅁䅁权䙁䅁䅁䍄䉁䅁䅁睁䅁䅁䅍䅄䅁䅁䅕䅁䅁䡁婩䕕䭅䉁䅳䅁䉁䅁䅁允䅁䅁䅯兂䅁䅁杷允䅁䅁䅍䅁䑁䅁䅷䅁䙁䅁䅁䥁䕃噮䉂权湁䅁䅁允䅁䅁䅅䅁䭁䅁䅕䅁䵁䅉䅅䅁䑁䅁䅁睁䵁䅁䅁兂䅁䅁䅁歆倱兑䅯䅅䅁䅁䅅䅁䉁䅁䅁权剁䅁䅁䍄䉁䅁䅁睁䅁䅁䅍䅄䅁䅁䅕䅁䅁䡁婩䕕䭅䅁䄰䅁䉁䅁䅁允䅁䅁䅯权䅁䅁杷允䅁䅁䅍䅁䑁䅁䅷䅁䙁䅁䅁䥁佃噮䉂权牁䅁䅁允䅁䅁䅅䅁䭁䅁䅕䅁䵁䅉䅅䅁䑁䅁䅁睁䵁䅁䅁兂䅁䅁䅄煤兤兑䅯睄䅁䅁䅅䅁䉁䅁䅁权䙁䅁䅁䍄䉁䅁䅁睁䅁䅁䅍䅄䅁䅁䅕䅁䅁䥧獙啕䭅䉁䅁䅁䉁䅁䅁允䅁䅁䅯充䅁䅁杷允䅁䅁䅍䅁䑁䅁䅷䅁䙁䅁䅁䅁敄ㅵ䉆权允䅁䅁允䅁䅁䅅䅁䭁䕁䅕䅁䵁䅉䅅䅁䑁䅁䅁睁䵁䅁䅁兂䅁䅁䅁䩥公兑䅯睊䅁䅁䅅䅁䉁䅁䅁权䙁䅁䅁䍄䉁䅁䅁睁䅁䅁䅍䅄䅁䅁䅕䅁䅁䡑批䕕䭅䍁䅕䅁䉁䅁䅁允䅁䅁䅯兂䅁䅁杷允䅁䅁䅍䅁䑁䅁䅷䅁䙁䅁䅁䵁䱄洰䉎权䩁䅁䅁允䅁䅁䅅䅁䭁䅁䅯䅁䵁䅉䅅䅁䑁䅁䅁睁䵁䅁䅁兂䅁䅁䅃䩨儱兑䅯睃䅁䅁䅅䅁䉁䅁䅁权䙁䅁䅁䍄䉁䅁䅁睁䅁䅁䅍䅄䅁䅁䅕䅁䅁䝑愲䕕䭅䉁䅉䅁䉁䅁䅁允䅁䅁䅯充䅁䅁杷允䅁䅁䅍䅁䑁䅁䅷䅁䙁䅁䅁䥁䕃噮䉂权坁䅁䅁允䅁䅁䅅䅁䭁䅁䅕䅁䵁䅉䅅䅁䑁䅁䅁睁䵁䅁䅁兂䅁䅁䅃䩨儱兑䅯兇䅁䅁䅅䅁䉁䅁䅁权䙁䅁䅁䍄䉁䅁䅁睁䅁䅁䅍䅄䅁䅁䅕䅁䅁佷捳䕕䭅䅁䄸䅁䉁䅁䅁允䅁䉁䅑䅁䅁䅁䅁䅁䵁䅉䅅䅁䑁䅁䅁睁䵁䅁䅁兂䅁䅁䅂㝉兖兑䅯兄䅁䅁䅅䅁䉁䅁䅁权剁䅁䅁䍄䉁䅁䅁睁䅁䅁䅍䅄䅁䅁䅕䅁䅁䡑婏䕕䭅䅁䅣䅁䉁䅁䅁允䅁䅁䅯兂䅁䅁杷允䅁䅁䅍䅁䑁䅁䅷䅁䙁䅁䅁䅁坁啔䈹权敁䅁䅁允䅁䅁䅅䅁䭁䅁䅕䅁䵁䅉䅅䅁䑁䅁䅁睁䵁䅁䅁兂䅁䅁䅃㕷全兑䅯䅃䅁䅁䅅䅁䉁䅁䅁权䙁䅁䅁䍄䉁䅁䅁睁䅁䅁䅍䅄䅁䅁䅕䅁䅁䥧獙啕䭅䍁䅉䅁䉁䅁䅁允䅁䅁䅯兂䅁䅁杷允䅁䅁䅍䅁䑁䅁䅷䅁䙁䅁䅁䵁牄䙈䉂权湁䅁䅁允䅁䅁䅅䅁䙁乁橥䑣䬰眱䅎䍄䉁䅁䅁睁䅁䅁䅍䅄䅁䅁䅕䅁䅁乁㜶啕䭅䍁䅣䅁䉁䅁䅁允䅁䅁䅯兂䅁䅁杷允䅁䅁䅍䅁䑁䅁䅷䅁䙁䅁䅁䅁㍁ㅬ䉂权䩁䅁䅁允䅁䅁䅅䅁䭁䅁䅯䅁䵁䅉䅅䅁䑁䅁䅁睁䵁䅁䅁兂䅁䅁䅃㕷全兑䅯䅉䅁䅁䅅䅁䉁䅁䅁权䙁䅁䅁䍄䉁䅁䅁睁䅁䅁䅍䅄䅁䅁䅕䅁䅁䵧奏䕕䭅䅁䅙䅁䉁䅁䅁允䅁䅁䅯兂䅁䅁杷允䅁䅁䅍䅁䑁䅁䅷䅁䙁䅁䅁䕁瑂汭䉂权婁䅁䅁允䅁䅁䅅䅁䭁䅁䅕䅁䵁䅉䅅䅁䑁䅁䅁睁䵁䅁䅁兂䅁䅁䅃灪儱兑䅯睇䅁䅁䅅䅁䉁䅁䅁权䙁䅁䅁䍄䉁䅁䅁睁䅁䅁䅍䅄䅁䅁䅕䅁䅁䭁䘷䕕䭅䍁䅍䅁䉁䅁䅁允䅁䅁䅯兂䅁䅁杷允䅁䅁䅍䅁䑁䅁䅷䅁䙁䅁䅁䅁敃汋䉆权敁䅁䅁允䅁䅁䅅䅁䭁䅁䅕䅁䵁䅉䅅䅁䑁䅁䅁睁䵁䅁䅁兂䅁䅁䅃灪儱兑䅯睂䅁䅁䅅䅁䉁䅁䅁权䙁䅁䅁䍄䉁䅁䅁睁䅁䅁䅍䅄䅁䅁䅕䅁䅁䍑ㅏ䕕䭅䉁䅣䅁䉁䅁䅁允䅁䅁䅯充䅁䅁杷允䅁䅁䅍䅁䑁䅁䅷䅁䙁䅁䅁䕁穂噭䉂权牁䅁䅁允䅁䅁䅅䅁䭁䅁䅕䅁䵁䅉䅅䅁䑁䅁䅁睁䵁䅁䅁兂䅁䅁䅃灪儱兑䅯䅉䅁䅁䅅䅁䉁䅁䅁兂㝂䭆䠵場啱睐杷允䅁䅁䅍䅁䑁䅁䅷䅁䙁䅁䅁䅁楃歙䈹权潁䅁䅁允䅁䅁䅅䅁䭁䅁䅕䅁䵁䅉䅅䅁䑁䅁䅁睁䵁䅁䅁兂䅁䅁䅂婢兰兑䅯䅃䅁䅁䅅䅁䉁䅁䅁权䙁䅁䅁䍄䉁䅁䅁睁䅁䅁䅍䅄䅁䅁䅕䅁䅁䵷卶す䭅䍁䅁䅁䉁䅁䅁允䅁䅁䅯兂䅁䅁杷允䅁䅁䅍䅁䑁䅁䅷䅁䙁䅁䅁䅁浂䙭䉂权允䅁䅁允䅁䅁䅅䅁䭁䍁䅅䅁䵁䅉䅅䅁䑁䅁䅁睁䵁䅁䅁兂䅁䅁䅂娱兰兑䅯䅋䅁䅁䅅䅁䉁䅁䅁权䙁䅁䅁䍄䉁䅁䅁睁䅁䅁䅍䅄䅁䅁䅕䅁䅁䑑慭䕕䭅䅁䅳䅁䉁䅁䅁允䅁䅁䅯兂䅁䅁杷允䅁䅁䅍䅁䑁䅁䅷䅁䙁䅁䅁䅁敃汋䉆权橁䅁䅁允䅁䅁䅅䅁䭁䅁䅕䅁䵁䅉䅅䅁䑁䅁䅁睁䵁䅁䅁兂䅁䅁䅄砶典兑䅯䅆䅁䅁䅅䅁䉁䅁䅁权䙁䅁䅁䍄䉁䅁䅁睁䅁䅁䅍䅄䅁䅁䅕䅁䅁䥧獙啕䭅䅁䅑䅁䉁䅁䅁允䅁䅁䅯兂䅁䅁杷允䅁䅁䅍䅁䑁䅁䅷䅁䙁䅁䅁䥁佃噮䉂权歁䅁䅁允䅁䅁䅅䅁䙁䅁塲㍯㥁牃⽣䍄䉁䅁䅁睁䅁䅁䅍䅄䅁䅁䅕䅁䅁䥧搶䕕䭅䉁䄸䅁䉁䅁䅁允䅁䅁䅯兂䅁䅁杷允䅁䅁䅍䅁䑁䅁䅷䅁䙁䅁䅁䅁⭂䙮䉆权橁䅁䅁允䅁䅁䅅䅁䭁䅁䅕䅁䵁䅉䅅䅁䑁䅁䅁睁䵁䅁䅁兂䅁䅁䅂娱兰兑䅯睉䅁䅁䅅䅁䉁䅁䅁权䙁䅁䅁䍄䉁䅁䅁睁䅁䅁䅍䅄䅁䅁䅕䅁䅁䩁焴啕䭅䅁䅷䅁䉁䅁䅁允䅁䅁䅯兂䅁䅁杷允䅁䅁䅍䅁䑁䅁䅷䅁䙁䅁䅁䅁䥄䙶䉆权偁䅁䅁允䅁䅁䅅䅁䭁䅁䅕䅁䵁䅉䅅䅁䑁䅁䅁睁䵁䅁䅁兂䅁䅁䅄㥹橊兑䅯睉䅁䅁䅅䅁䉁䅁䅁权䙁䅁䅁䍄䉁䅁䅁睁䅁䅁䅍䅄䅁䅁䅕䅁䅁䥧搶䕕䭅䅁䄴䅁䉁䅁䅁允䅁䅁䅕䅁䅁䅁䅁䕏䵁䅉䅅䅁䑁䅁䅁睁䵁䅁䅁兂䅁䅁䅄浮削兑䅯䅂䅁䅁䅅䅁䉁䅁䅁权䙁䅁䅁䍄䉁䅁䅁睁䅁䅁䅍䅄䅁䅁䅕䅁䅁䑧婗䕕䭅䍁䅁䅁䉁䅁䅁允䅁䅁䅕䉵䘶ㄶ㑇橺䴸䅉䅅䅁䑁䅁䅁睁䵁䅁䅁兂䅁䅁䅃灪儱兑䅯兇䅁䅁䅅䅁䉁䅁䅁权䙁䅁䅁䍄䉁䅁䅁睁䅁䅁䅍䅄䅁䅁䅕䅁䅁佷捳䕕䭅䅁䄴䅁䉁䅁䅁允䅁䅁䅕䘷㑇潈牘吰䴸䅉䅅䅁䑁䅁䅁睁䵁䅁䅁兂䅁䅁䅃汆㜵兑䅯䅊䅁䅁䅅䅁䉁䅁䅁权䙁䅁䅁䍄䉁䅁䅁睁䅁䅁䅍䅄䅁䅁䅕䅁䅁䡁挶啕䭅䉁䅑䅁䉁䅁䅁允䅁䅁䅯兂䅁䅁杷允䅁䅁䅍䅁䑁䅁䅷䅁䙁䅁䅁䅁畃噸䉂权塁䅁䅁允䅁䅁䅅䅁䭁䑁䅙䅁䵁䅉䅅䅁䑁䅁䅁睁䵁䅁䅁兂䅁䅁䅂㝉兖兑䅯䅋䅁䅁䅅䅁䉁䅁䅁权䙁䅁䅁䍄䉁䅁䅁睁䅁䅁䅍䅄䅁䅁䅕䅁䅁䝑愲䕕䭅䉁䅑䅁䉁䅁䅁允䅁䅁䅯兂䅁䅁杷允䅁䅁䅍䅁䑁䅁䅷䅁䙁䅁䅁䅁浂䙭䉂权十䅁䅁允䅁䅁䅅䅁䭁䑁䅣䅁䵁䅉䅅䅁䑁䅁䅁睁䵁䅁䅁兂䅁䅁䅃っ偂兑䅯杅䅁䅁䅅䅁䉁䅁䅁权剁䅁䅁䍄䉁䅁䅁睁䅁䅁䅍䅄䅁䅁䅕䅁䅁䩑摃䕕䭅䉁䅉䅁䉁䅁䅁允䅁䅁䅯杕䅁䅁杷允䅁䅁䅍䅁䑁䅁䅷䅁䙁䅁䅁䵁畄噭䉂权允䅁䅁允䅁䅁䅅䅁䭁䉁䅅䅁䵁䅉䅅䅁䑁䅁䅁睁䵁䅁䅁兂䅁䅁䅁爳剴兑䅯兄䅁䅁䅅䅁䉁䅁䅁权䙂䅁䅁䍄䉁䅁䅁睁䅁䅁䅍䅄䅁䅁䅕䅁䅁䭁䘷䕕䭅䍁䅧䅁䉁䅁䅁允䅁䅁䅯兂䅁䅁杷允䅁䅁䅍䅁䑁䅁䅷䅁䙁䅁䅁䅁浂䙭䉂权流䅁䅁允䅁䅁䅅䅁䭁䅁䅕䅁䵁䅉䅅䅁䑁䅁䅁睁䵁䅁䅁兂䅁䅁䅁灚全兑䅯睊䅁䅁䅅䅁䉁䅁䅁权䙁䅁䅁䍄䉁䅁䅁睁䅁䅁䅍䅄䅁䅁䅕䅁䅁䩷椵啕䭅䍁䅉䅁䉁䅁䅁允䅁䅁䅯兂䅁䅁杷允䅁䅁䅍䅁䑁䅁䅷䅁䙁䅁䅁䅁䥄䙶䉆权扁䅁䅁允䅁䅁䅅䅁䭁䅁䅕䅁䵁䅉䅅䅁䑁䅁䅁睁䵁䅁䅁兂䅁䅁䅃婎公兑䅯䅆䅁䅁䅅䅁䉁䅁䅁权䙁䅁䅁䍄䉁䅁䅁睁䅁䅁䅍䅄䅁䅁䅕䅁䅁䉁乚ご䭅䉁䅉䅁䉁䅁䅁允䅁䅁䅯充䅁䅁杷允䅁䅁䅍䅁䑁䅁䅷䅁䙁䅁䅁䕁㕁汭䉂权十䅁䅁允䅁䅁䅅䅁䭁䑁䄴䅁䵁䅉䅅䅁䑁䅁䅁睁䵁䅁䅁兂䅁䅁䅁䱹剸兑䅯䅉䅁䅁䅅䅁䉁䅁䅁权䙁䅁䅁䍄䉁䅁䅁睁䅁䅁䅍䅄䅁䅁䅕䅁䅁䝁奡䕕䭅䍁䅧䅁䉁䅁䅁允䅁䅁䅯兂䅁䅁杷允䅁䅁䅍䅁䑁䅁䅷䅁䙁䅁䅁䵁㉂ㅰ䉂权䕁䅁䅁允䅁䅁䅅䅁䭁䅁䅕䅁䵁䅉䅅䅁䑁䅁䅁睁䵁䅁䅁兂䅁䅁䅃楨剸兑䅯睋䅁䅁䅅䅁䉁䅁䅁权䙁䅁䅁䍄䉁䅁䅁睁䅁䅁䅍䅄䅁䅁䅕䅁䅁䩷椵啕䭅䍁䅑䅁䉁䅁䅁允䅁䅁䅕噋偹癷潕䑺䴸䅉䅅䅁䑁䅁䅁睁䵁䅁䅁兂䅁䅁睂㌹礵兑䅯睊䅁䅁䅅䅁䉁䅁䅁权䙁䅁䅁䍄䉁䅁䅁睁䅁䅁䅍䅄䅁䅁䅕䅁䅁䑑慭䕕䭅䉁䄸䅁䉁䅁䅁允䅁䅁䅯兂䅁䅁杷允䅁䅁䅍䅁䑁䅁䅷䅁䙁䅁䅁䅁敃汋䉆权捁䅁䅁允䅁䅁䅅䅁䭁䅁䅕䅁䵁䅉䅅䅁䑁䅁䅁睁䵁䅁䅁兂䅁䅁䅁䩢兴兑䅯睇䅁䅁䅅䅁䉁䅁䅁权䙁䅁䅁䍄䉁䅁䅁睁䅁䅁䅍䅄䅁䅁䅕䅁䅁䡑婏䕕䭅䉁䅁䅁䉁䅁䅁允䅁䅁䅯权䅁䅁杷允䅁䅁䅍䅁䑁䅁䅷䅁䙁䅁䅁䵁㉂ㅰ䉂权婁䅁䅁允䅁䅁䅅䅁䭁䅁䅕䅁䵁䅉䅅䅁䑁䅁䅁睁䵁䅁䅁兂䅁䅁䅄灣公兑䅯杇䅁䅁䅅䅁䉁䅁䅁权䙁䅁䅁䍄䉁䅁䅁睁䅁䅁䅍䅄䅁䅁䅕䅁䅁䡑婏䕕䭅䍁䅍䅁䉁䅁䅁允䅁䅁䅯兂䅁䅁杷允䅁䅁䅍䅁䑁䅁䅷䅁䙁䅁䅁䵁㉂ㅰ䉂权十䅁䅁允䅁䅁䅅䅁䭁䑁䄰䅁䵁䅉䅅䅁䑁䅁䅁睁䵁䅁䅁兂䅁䅁䅁䩥公兑䅯杇䅁䅁䅅䅁䉁䅁䅁权䙁䅁䅁䍄䉁䅁䅁睁䅁䅁䅍䅄䅁䅁䅕䅁䅁佷娶䕕䭅䉁䅣䅁䉁䅁䅁允䅁䅁䅯充䅁䅁杷允䅁䅁䅍䅁䑁䅁䅷䅁䙁䅁䅁䕁橁噴䉂权晁䅁䅁允䅁䅁䅅䅁䭁䅁䅕䅁䵁䅉䅅䅁䑁䅁䅁睁䵁䅁䅁兂䅁䅁䅃坂剸兑䅯睊䅁䅁䅅䅁䉁䅁䅁权䙁䅁䅁䍄䉁䅁䅁睁䅁䅁䅍䅄䅁䅁䅕䅁䅁佷娶䕕䭅䍁䅁䅁䉁䅁䅁允䅁䅁䅕䅁䅁䅁䅁䐰䴸䅉䅅䅁䑁䅁䅁睁䵁䅁䅁兂䅁䅁䅃楨剸兑䅯䅉䅁䅁䅅䅁䉁䅁䅁权䙁䅁䅁䍄䉁䅁䅁睁䅁䅁䅍䅄䅁䅁䅕䅁䅁䩷椵啕䭅䉁䄴䅁䉁䅁䅁允䅁䅁䅕䥘䌯匹捨㡈䵁䅉䅅䅁䑁䅁䅁睁䵁䅁䅁兂䅁䅁䅄瀷公兑䅯杊䅁䅁䅅䅁䉁䅁䅁权䙁䅁䅁䍄䉁䅁䅁睁䅁䅁䅍䅄䅁䅁䅕䅁䅁䵁慭䕕䭅䉁䅫䅁䉁䅁䅁允䅁䅁䅕呣䬰㘱睐問䵁䅉䅅䅁䑁䅁䅁睁䵁䅁䅁兂䅁䅁䅂娱兰兑䅯杅䅁䅁䅅䅁䉁䅁䅁权剁䅁䅁䍄䉁䅁䅁睁䅁䅁䅍䅄䅁䅁䅕䅁䅁佷娶䕕䭅䅁䅑䅁䉁䅁䅁允䅁䅁䅯兂䅁䅁杷允䅁䅁䅍䅁䑁䅁䅷䅁䙁䅁䅁䕁噄汭䉂权湁䅁䅁允䅁䅁䅅䅁啁䅁䅁䅁䅁䅁䅁䍄䉁䅁䅁睁䅁䅁䅍䅄䅁䅁䅕䅁䅁䩑摃䕕䭅䉁䅯䅁䉁䅁䅁允䅁䅁䅯兂䅁䅁杷允䅁䅁䅍䅁䑁䅁䅷䅁䙁䅁䅁䥁䙁䙢䉆权允䅁䅁允䅁䅁䅅䅁䭁䉁䅅䅁䵁䅉䅅䅁䑁䅁䅁睁䵁䅁䅁兂䅁䅁䅄慏兎兑䅯杉䅁䅁䅅䅁䉁䅁䅁权䙁䅁䅁䍄䉁䅁䅁睁䅁䅁䅍䅄䅁䅁䅕䅁䅁䑧婗䕕䭅䉁䄸䅁䉁䅁䅁允䅁䅁䅯兂䅁䅁杷允䅁䅁䅍䅁䑁䅁䅷䅁䙁䅁䅁䥁穂䕑䈹权湁䅁䅁允䅁䅁䅅䅁䙁䵁ㅐ䙋偹獷⽕䍄䉁䅁䅁睁䅁䅁䅍䅄䅁䅁䅕䅁䅁䑧婗䕕䭅䅁䅫䅁䉁䅁䅁允䅁䅁䅯䅑䅁䅁杷允䅁䅁䅍䅁䑁䅁䅷䅁䙁䅁䅁䵁祂噭䉂权䵁䅁䅁允䅁䅁䅅䅁䭁䅁䅕䅁䵁䅉䅅䅁䑁䅁䅁睁䵁䅁䅁兂䅁䅁䅁䱹剸兑䅯睋䅁䅁䅅䅁䉁䅁䅁权䙁䅁䅁䍄䉁䅁䅁睁䅁䅁䅍䅄䅁䅁䅕䅁䅁乁戴啗䭅䅁䄸䅁䉁䅁䅁允䅁䅁䅕体㙆䭆䠵吶䴸䅉䅅䅁䑁䅁䅁睁䵁䅁䅁兂䅁䅁䅄瀷公兑䅯兊䅁䅁䅅䅁䉁䅁䅁权䙁䅁䅁䍄䉁䅁䅁睁䅁䅁䅍䅄䅁䅁䅕䅁䅁䍑ㅏ䕕䭅䍁䅣䅁䉁䅁䅁允䅁䅁䅕体㙆䭆䠵う䵁䅉䅅䅁䑁䅁䅁睁䵁䅁䅁兂䅁䅁䅄瀷公兑䅯睊䅁䅁䅅䅁䉁䅁䅁兂灁䥘䌯匹歪睶杷允䅁䅁䅍䅁䑁䅁䅷䅁䙁䅁䅁䅁獂ㅭ䉂权歁䅁䅁允䅁䅁䅅䅁䭁䅁䅕䅁䵁䅉䅅䅁䑁䅁䅁睁䵁䅁䅁兂䅁䅁䅂偂晨兑䅯䅄䅁䅁䅅䅁䉁䅁䅁权䙁䅁䅁䍄䉁䅁䅁睁䅁䅁䅍䅄䅁䅁䅕䅁䅁乁戴啗䭅䍁䅕䅁䉁䅁䅁允䅁䅁䅯兂䅁䅁杷允䅁䅁䅍䅁䑁䅁䅷䅁䙁䅁䅁䵁㕁ㅯ䉂权湁䅁䅁允䅁䅁䅅䅁䭁䅁䅕䅁䵁䅉䅅䅁䑁䅁䅁睁䵁䅁䅁兂䅁䅁䅁䩥公兑䅯兇䅁䅁䅅䅁䉁䅁䅁权䙁䅁䅁䍄䉁䅁䅁睁䅁䅁䅍䅄䅁䅁䅕䅁䅁佷娶䕕䭅䍁䅑䅁䉁䅁䅁允䅁䅁䅕体㙆䭆䠵吶䴸䅉䅅䅁䑁䅁䅁睁䵁䅁䅁兂䅁䅁䅄灣公兑䅯睃䅁䅁䅅䅁䉁䅁䅁权䙁䅁䅁䍄䉁䅁䅁睁䅁䅁䅍䅄䅁䅁䅕䅁䅁䑷橭䕕䭅䍁䅑䅁䉁䅁䅁允䅁䅁䅯兂䅁䅁杷允䅁䅁䅍䅁䑁䅁䅷䅁䙁䅁䅁䅁敄ㅵ䉆权䩁䅁䅁允䅁䅁䅅䅁䭁䕁䅕䅁䵁䅉䅅䅁䑁䅁䅁睁䵁䅁䅁兂䅁䅁䅂婏兰兑䅯睊䅁䅁䅅䅁䉁䅁䅁权䙁䅁䅁䍄䉁䅁䅁睁䅁䅁䅍䅄䅁䅁䅕䅁䅁䩁焴啕䭅䅁䄰䅁䉁䅁䅁允䅁䅁䅯充䅁䅁杷允䅁䅁䅍䅁䑁䅁䅷䅁䙁䅁䅁䥁穂䕑䈹权偁䅁䅁允䅁䅁䅅䅁䙁䥁牘払敧晨⽳䍄䉁䅁䅁睁䅁䅁䅍䅄䅁䅁䅕䅁䅁佷娶䕕䭅䉁䄸䅁䉁䅁䅁允䅁䅁䅯兂䅁䅁杷允䅁䅁䅍䅁䑁䅁䅷䅁䙁䅁䅁䕁噄汭䉂权偁䅁䅁允䅁䅁䅅䅁䭁䅁䅕䅁䵁䅉䅅䅁䑁䅁䅁睁䵁䅁䅁兂䅁䅁䅄煤兤兑䅯䅅䅁䅁䅅䅁䉁䅁䅁权㡁䅁䅁䍄䉁䅁䅁睁䅁䅁䅍䅄䅁䅁䅕䅁䅁乁㜶啕䭅䅁䅷䅁䉁䅁䅁允䅁䅁䅯兂䅁䅁杷允䅁䅁䅍䅁䑁䅁䅷䅁䙁䅁䅁䥁坁湘䉴权䝁䅁䅁允䅁䅁䅅䅁䭁䅁䅕䅁䵁䅉䅅䅁䑁䅁䅁睁䵁䅁䅁兂䅁䅁䅃㕷全兑䅯杈䅁䅁䅅䅁䉁䅁䅁权䙁䅁䅁䍄䉁䅁䅁睁䅁䅁䅍䅄䅁䅁䅕䅁䅁䍑ㅏ䕕䭅䉁䄴䅁䉁䅁䅁允䅁䅁䅕積積積積歈䵁䅉䅅䅁䑁䅁䅁睁䵁䅁䅁兂䅁䅁䅁䩥公兑䅯杉䅁䅁䅅䅁䉁䅁䅁权䙁䅁䅁䍄䉁䅁䅁睁䅁䅁䅍䅄䅁䅁䅕䅁䅁䅧獖啕䭅䍁䅁䅁䉁䅁䅁允䅁䅁䅯兂䅁䅁杷允䅁䅁䅍䅁䑁䅁䅷䅁䙁䅁䅁䵁畄噭䉂权潁䅁䅁允䅁䅁䅅䅁䭁䅁䅕䅁䵁䅉䅅䅁䑁䅁䅁睁䵁䅁䅁兂䅁䅁䅂㝉兖兑䅯杉䅁䅁䅅䅁䉁䅁䅁兂獄払敧敨噳䅑杷允䅁䅁䅍䅁䑁䅁䅷䅁䙁䅁䅁䵁畄噭䉂权慁䅁䅁允䅁䅁䅅䅁䭁䅁䅕䅁䵁䅉䅅䅁䑁䅁䅁睁䵁䅁䅁兂䅁䅁䅄瀷公兑䅯兇䅁䅁䅅䅁䉁䅁䅁权䙁䅁䅁䍄䉁䅁䅁睁䅁䅁䅍䅄䅁䅁䅕䅁䅁䱧坵䕕䭅䍁䅁䅁䉁䅁䅁允䅁䅁䅕児塲㍯㥁樴䴸䅉䅅䅁䑁䅁䅁睁䵁䅁䅁兂䅁䅁䅁獲兖兑䅯杄䅁䅁䅅䅁䉁䅁䅁权䙁䅁䅁䍄䉁䅁䅁睁䅁䅁䅍䅄䅁䅁䅕䅁䅁䩁焴啕䭅䅁䅫䅁䉁䅁䅁允䅁䅁䅯䅌䅁䅁杷允䅁䅁䅍䅁䑁䅁䅷䅁䙁䅁䅁䅁坁啔䈹权扁䅁䅁允䅁䅁䅅䅁䭁䅁䅕䅁䵁䅉䅅䅁䑁䅁䅁睁䵁䅁䅁兂䅁䅁䅃㕷全兑䅯兄䅁䅁䅅䅁䉁䅁䅁权剁䅁䅁䍄䉁䅁䅁睁䅁䅁䅍䅄䅁䅁䅕䅁䅁䵧奏䕕䭅䉁䅁䅁䉁䅁䅁允䅁䅁䅯充䅁䅁杷允䅁䅁䅍䅁䑁䅁䅷䅁䙁䅁䅁䅁楃歙䈹权歁䅁䅁允䅁䅁䅅䅁䙁䍁捬㡪ㅌ䍱䅬䍄䉁䅁䅁睁䅁䅁䅍䅄䅁䅁䅕䅁䅁乁戴啗䭅䍁䅑䅁䉁䅁䅁允䅁䅁䅕䡰㥁瑃䑥䕒䵁䅉䅅䅁䑁䅁䅁睁䵁䅁䅁兂䅁䅁䅃㕷全兑䅯䅆䅁䅁䅅䅁䉁䅁䅁权䙁䅁䅁䍄䉁䅁䅁睁䅁䅁䅍䅄䅁䅁䅕䅁䅁䉧敚づ䭅䉁䅙䅁䉁䅁䅁允䅁䅁䅯兂䅁䅁杷允䅁䅁䅍䅁䑁䅁䅷䅁䙁䅁䅁䥁䑄䙭䉂权捁䅁䅁允䅁䅁䅅䅁䭁䅁䅕䅁䵁䅉䅅䅁䑁䅁䅁睁䵁䅁䅁兂䅁䅁䅁浯偊兑䅯睃䅁䅁䅅䅁䉁䅁䅁兂硂児塲㍯乄睐杷允䅁䅁䅍䅁䑁䅁䅷䅁䙁䅁䅁䥁䑄䙭䉂权楁䅁䅁允䅁䅁䅅䅁䭁䅁䅕䅁䵁䅉䅅䅁䑁䅁䅁睁䵁䅁䅁兂䅁䅁䅄砶典兑䅯元䅁䅁䅅䅁䉁䅁䅁权㙁䅁䅁䍄䉁䅁䅁睁䅁䅁䅍䅄䅁䅁䅕䅁䅁䥧獙啕䭅䅁䅙䅁䉁䅁䅁允䅁䅁䅯兂䅁䅁杷允䅁䅁䅍䅁䑁䅁䅷䅁䙁䅁䅁䅁䥄䙶䉆权湁䅁䅁允䅁䅁䅅䅁䭁䅁䅕䅁䵁䅉䅅䅁䑁䅁䅁睁䵁䅁䅁兂䅁䅁䅃㕵党兑䅯杊䅁䅁䅅䅁䉁䅁䅁䅆䅁䅁䅁䅁䅁䅁杷允䅁䅁䅍䅁䑁䅁䅷䅁䙁䅁䅁䥁䑄䙭䉂权䵁䅁䅁允䅁䅁䅅䅁䭁䅁䅕䅁䵁䅉䅅䅁䑁䅁䅁睁䵁䅁䅁兂䅁䅁䅂䩫儱兑䅯䅂䅁䅁䅅䅁䉁䅁䅁权䙁䅁䅁䍄䉁䅁䅁睁䅁䅁䅍䅄䅁䅁䅕䅁䅁䑧婗䕕䭅䉁䅷䅁䉁䅁䅁允䅁䅁䅕硥畓⭒䭆啕䵁䅉䅅䅁䑁䅁䅁睁䵁䅁䅁兂䅁䅁䅂䩫儱兑䅯䅈䅁䅁䅅䅁䉁䅁䅁兂硂児塲㍯摄睐杷允䅁䅁䅍䅁䑁䅁䅷䅁䙁䅁䅁䥁䑄䙭䉂权汁䅁䅁允䅁䅁䅅䅁䭁䅁䅕䅁䵁䅉䅅䅁䑁䅁䅁睁䵁䅁䅁兂䅁䅁䅃汆㜵兑䅯杊䅁䅁䅅䅁䉁䅁䅁权䙁䅁䅁䍄䉁䅁䅁睁䅁䅁䅍䅄䅁䅁䅕䅁䅁䭁楊ご䭅䍁䅳䅁䉁䅁䅁允䅁䅁䅕灭婭婭婭呱䴸䅉䅅䅁䑁䅁䅁睁䵁䅁䅁兂䅁䅁䅃㕷全兑䅯睃䅁䅁䅅䅁䉁䅁䅁权䙁䅁䅁䍄䉁䅁䅁睁䅁䅁䅍䅄䅁䅁䅕䅁䅁䝑愲䕕䭅䉁䅯䅁䉁䅁䅁允䅁䅁䅯兂䅁䅁杷允䅁䅁䅍䅁䑁䅁䅷䅁䙁䅁䅁䥁䑄䙭䉂权䕁䅁䅁允䅁䅁䅅䅁䭁䅁䅕䅁䵁䅉䅅䅁䑁䅁䅁睁䵁䅁䅁兂䅁䅁䅃㕷全兑䅯杇䅁䅁䅅䅁䉁䅁䅁权䙁䅁䅁䍄䉁䅁䅁睁䅁䅁䅍䅄䅁䅁䅕䅁䅁䡑批䕕䭅䅁䅫䅁䉁䅁䅁允䅁䅁䅯睓䅁䅁杷允䅁䅁䅍䅁䑁䅁䅷䅁䙁䅁䅁䵁㕁ㅯ䉂权扁䅁䅁允䅁䅁䅅䅁䭁䅁䅕䅁䵁䅉䅅䅁䑁䅁䅁睁䵁䅁䅁兂䅁䅁睂㌹礵兑䅯䅋䅁䅁䅅䅁䉁䅁䅁权䙁䅁䅁䍄䉁䅁䅁睁䅁䅁䅍䅄䅁䅁䅕䅁䅁䡷湡䕕䭅䅁䅙䅁䉁䅁䅁允䅁䅁䅯兂䅁䅁杷允䅁䅁䅍䅁䑁䅁䅷䅁䙁䅁䅁䅁㍁ㅬ䉂权潁䅁䅁允䅁䅁䅅䅁䭁䅁䅕䅁䵁䅉䅅䅁䑁䅁䅁睁䵁䅁䅁兂䅁䅁䅂㝉兖兑䅯䅆䅁䅁䅅䅁䉁䅁䅁权䙁䅁䅁䍄䉁䅁䅁睁䅁䅁䅍䅄䅁䅁䅕䅁䅁䵧奏䕕䭅䍁䅳䅁䉁䅁䅁允䅁䅁䅯兂䅁䅁杷允䅁䅁䅍䅁䑁䅁䅷䅁䙁䅁䅁䥁䑄䙭䉂权婁䅁䅁允䅁䅁䅅䅁䭁䅁䅕䅁䵁䅉䅅䅁䑁䅁䅁睁䵁䅁䅁兂䅁䅁䅁浯偊兑䅯睂䅁䅁䅅䅁䉁䅁䅁权䙁䅁䅁䍄䉁䅁䅁睁䅁䅁䅍䅄䅁䅁䅕䅁䅁䑧婗䕕䭅䉁䅫䅁䉁䅁䅁允䅁䅁䅯兂䅁䅁杷允䅁䅁䅍䅁䑁䅁䅷䅁䙁䅁䅁䅁⭂䙮䉆权晁䅁䅁允䅁䅁䅅䅁䭁䅁䅕䅁䵁䅉䅅䅁䑁䅁䅁睁䵁䅁䅁兂䅁䅁䅁㕎兤兑䅯䅉䅁䅁䅅䅁䉁䅁䅁兂㝂䭆䠵場ぱ睐杷允䅁䅁䅍䅁䑁䅁䅷䅁䙁䅁䅁䵁祂噭䉂权捁䅁䅁允䅁䅁䅅䅁䭁䅁䅕䅁䵁䅉䅅䅁䑁䅁䅁睁䵁䅁䅁兂䅁䅁䅁䩥公兑䅯睂䅁䅁䅅䅁䉁䅁䅁权䙁䅁䅁䍄䉁䅁䅁睁䅁䅁䅍䅄䅁䅁䅕䅁䅁䱧坵䕕䭅䍁䅣䅁䉁䅁䅁允䅁䅁䅕体㙆䭆䠵戯䴸䅉䅅䅁䑁䅁䅁睁䵁䅁䅁兂䅁䅁䅁楮剰兑䅯睊䅁䅁䅅䅁䉁䅁䅁权䙁䅁䅁䍄䉁䅁䅁睁䅁䅁䅍䅄䅁䅁䅕䅁䅁䅧獖啕䭅䅁䅑䅁䉁䅁䅁允䅁䅁䅯兂䅁䅁杷允䅁䅁䅍䅁䑁䅁䅷䅁䙁䅁䅁䅁䥄䙶䉆权䩁䅁䅁允䅁䅁䅅䅁䭁䅁䅯䅁䵁䅉䅅䅁䑁䅁䅁睁䵁䅁䅁兂䅁䅁䅄煤兤兑䅯兄䅁䅁䅅䅁䉁䅁䅁权㡁䅁䅁䍄䉁䅁䅁睁䅁䅁䅍䅄䅁䅁䅕䅁䅁䭁楊ご䭅䉁䅳䅁䉁䅁䅁允䅁䅁䅕牕敧敨剴䐯䴸䅉䅅䅁䑁䅁䅁睁䵁䅁䅁兂䅁䅁䅄砶典兑䅯䅂䅁䅁䅅䅁䉁䅁䅁权䙁䅁䅁䍄䉁䅁䅁睁䅁䅁䅍䅄䅁䅁䅕䅁䅁䡧䅎ご䭅䉁䄸䅁䉁䅁䅁允䅁䅁䅯兂䅁䅁杷允䅁䅁䅍䅁䑁䅁䅷䅁䙁䅁䅁䵁㉂ㅰ䉂权扁䅁䅁允䅁䅁䅅䅁䭁䅁䅕䅁䵁䅉䅅䅁䑁䅁䅁睁䵁䅁䅁兂䅁䅁䅁䩢兴兑䅯杊䅁䅁䅅䅁䉁䅁䅁权䙁䅁䅁䍄䉁䅁䅁睁䅁䅁䅍䅄䅁䅁䅕䅁䅁䡁挶啕䭅䉁䅣䅁䉁䅁䅁允䅁䅁䅯充䅁䅁杷允䅁䅁䅍䅁䑁䅁䅷䅁䙁䅁䅁䅁敃汋䉆权晁䅁䅁允䅁䅁䅅䅁䭁䅁䅕䅁䵁䅉䅅䅁䑁䅁䅁睁䵁䅁䅁兂䅁䅁䅂婏兰兑䅯睄䅁䅁䅅䅁䉁䅁䅁兂㑃潈牘払敪睐杷允䅁䅁䅍䅁䑁䅁䅷䅁䙁䅁䅁䵁㉂ㅰ䉂权䥁䅁䅁允䅁䅁䅅䅁䭁䅁䅕䅁䵁䅉䅅䅁䑁䅁䅁睁䵁䅁䅁兂䅁䅁䅂㕣公兑䅯睃䅁䅁䅅䅁䉁䅁䅁权䙁䅁䅁䍄䉁䅁䅁睁䅁䅁䅍䅄䅁䅁䅕䅁䅁䉧敚づ䭅䍁䅧䅁䉁䅁䅁允䅁䅁䅯兂䅁䅁杷允䅁䅁䅍䅁䑁䅁䅷䅁䙁䅁䅁䵁㕁ㅯ䉂权橁䅁䅁允䅁䅁䅅䅁䭁䅁䅕䅁䵁䅉䅅䅁䑁䅁䅁睁䵁䅁䅁兂䅁䅁睂㌹礵兑䅯杉䅁䅁䅅䅁䉁䅁䅁权䙁䅁䅁䍄䉁䅁䅁睁䅁䅁䅍䅄䅁䅁䅕䅁䅁䡷湡䕕䭅䍁䅙䅁䉁䅁䅁允䅁䅁䅯兂䅁䅁杷允䅁䅁䅍䅁䑁䅁䅷䅁䙁䅁䅁䥁㝃汬䉂权歁䅁䅁允䅁䅁䅅䅁䙁䕁桪桥畓⽒⼰䍄䉁䅁䅁睁䅁䅁䅍䅄䅁䅁䅕䅁䅁䡷湡䕕䭅䅁䅷䅁䉁䅁䅁允䅁䅁䅯兂䅁䅁杷允䅁䅁䅍䅁䑁䅁䅷䅁䙁䅁䅁䵁㉂ㅰ䉂权橁䅁䅁允䅁䅁䅅䅁䭁䅁䅕䅁䵁䅉䅅䅁䑁䅁䅁睁䵁䅁䅁兂䅁䅁䅁浯偊兑䅯睉䅁䅁䅅䅁䉁䅁䅁权䙁䅁䅁䍄䉁䅁䅁睁䅁䅁䅍䅄䅁䅁䅕䅁䅁䍑ㅏ䕕䭅䅁䅳䅁䉁䅁䅁允䅁䉁䅑䅁䅁䅁䅁䅁䵁䅉䅅䅁䑁䅁䅁睁䵁䅁䅁兂䅁䅁䅄砶典兑䅯䅄䅁䅁䅅䅁䉁䅁䅁兂乄䵺䵺䥺䑸䅑杷允䅁䅁䅍䅁䑁䅁䅷䅁䙁䅁䅁䕁㕁汭䉂权䥁䅁䅁允䅁䅁䅅䅁䭁䅁䅕䅁䵁䅉䅅䅁䑁䅁䅁睁䵁䅁䅁兂䅁䅁䅂㝉兖兑䅯睇䅁䅁䅅䅁䉁䅁䅁权䙁䅁䅁䍄䉁䅁䅁睁䅁䅁䅍䅄䅁䅁䅕䅁䅁䝑愲䕕䭅䅁䅑䅁䉁䅁䅁允䅁䅁䅯兂䅁䅁杷允䅁䅁䅍䅁䑁䅁䅷䅁䙁䅁䅁䵁㉂ㅰ䉂权歁䅁䅁允䅁䅁䅅䅁䭁䅁䅕䅁䵁䅉䅅䅁䑁䅁䅁睁䵁䅁䅁兂䅁䅁䅃坂剸兑䅯睉䅁䅁䅅䅁䉁䅁䅁权䙁䅁䅁䍄䉁䅁䅁睁䅁䅁䅍䅄䅁䅁䅕䅁䅁䡷湡䕕䭅䉁䅯䅁䉁䅁䅁允䅁䅁䅯兂䅁䅁杷允䅁䅁䅍䅁䑁䅁䅷䅁䙁䅁䅁䵁㉂ㅰ䉂权坁䅁䅁允䅁䅁䅅䅁䭁䅁䅕䅁䵁䅉䅅䅁䑁䅁䅁睁䵁䅁䅁兂䅁䅁䅁栳婴兑䅯睃䅁䅁䅅䅁䉁䅁䅁兂䥂場啯歲塣䅑杷允䅁䅁䅍䅁䑁䅁䅷䅁䙁䅁䅁䵁牄䙈䉂权䝁䅁䅁允䅁䅁䅅䅁䙁䙁偹癷潕乘⼸䍄䉁䅁䅁睁䅁䅁䅍䅄䅁䅁䅕䅁䅁䝁批䕕䭅䅁䅣䅁䉁䅁䅁允䅁䅁䅯兂䅁䅁杷允䅁䅁䅍䅁䑁䅁䅷䅁䙁䅁䅁䕁橁噴䉂权偁䅁䅁允䅁䅁䅅䅁䙁䡁㥅瑃橥乣⼰䍄䉁䅁䅁睁䅁䅁䅍䅄䅁䅁䅕䅁䅁乑慗䕕䭅䉁䅑䅁䉁䅁䅁允䅁䅁䅯兂䅁䅁杷允䅁䅁䅍䅁䑁䅁䅷䅁䙁䅁䅁䵁㕁ㅯ䉂权十䅁䅁允䅁䅁䅅䅁䭁䑁䄸䅁䵁䅉䅅䅁䑁䅁䅁睁䵁䅁䅁兂䅁䅁䅄砶典兑䅯杅䅁䅁䅅䅁䉁䅁䅁权剁䅁䅁䍄䉁䅁䅁睁䅁䅁䅍䅄䅁䅁䅕䅁䅁乁㜶啕䭅䅁䄸䅁䉁䅁䅁允䅁䅁䅯兂䅁䅁杷允䅁䅁䅍䅁䑁䅁䅷䅁䙁䅁䅁䥁坁湘䉴权允䅁䅁允䅁䅁䅅䅁䭁䉁䅅䅁䵁䅉䅅䅁䑁䅁䅁睁䵁䅁䅁兂䅁䅁䅃㕵党兑䅯兊䅁䅁䅅䅁䉁䅁䅁权䙁䅁䅁䍄䉁䅁䅁睁䅁䅁䅍䅄䅁䅁䅕䅁䅁䱧坵䕕䭅䅁䅷䅁䉁䅁䅁允䅁䅁䅕椹捨㡪ㅌ䕒䵁䅉䅅䅁䑁䅁䅁睁䵁䅁䅁兂䅁䅁䅃汆㜵兑䅯䅆䅁䅁䅅䅁䉁䅁䅁权䙁䅁䅁䍄䉁䅁䅁睁䅁䅁䅍䅄䅁䅁䅕䅁䅁䉧敚づ䭅䉁䅷䅁䉁䅁䅁允䅁䅁䅯兂䅁䅁杷允䅁䅁䅍䅁䑁䅁䅷䅁䙁䅁䅁䵁祂噭䉂权敁䅁䅁允䅁䅁䅅䅁䭁䅁䅕䅁䵁䅉䅅䅁䑁䅁䅁睁䵁䅁䅁兂䅁䅁䅂偂晨兑䅯䅂䅁䅁䅅䅁䉁䅁䅁权䙁䅁䅁䍄䉁䅁䅁睁䅁䅁䅍䅄䅁䅁䅕䅁䅁䉧敚づ䭅䍁䅁䅁䉁䅁䅁允䅁䅁䅯兂䅁䅁杷允䅁䅁䅍䅁䑁䅁䅷䅁䙁䅁䅁䥁坁湘䉴权䵁䅁䅁允䅁䅁䅅䅁䭁䅁䅕䅁䵁䅉䅅䅁䑁䅁䅁睁䵁䅁䅁兂䅁䅁䅃汆㜵兑䅯睋䅁䅁䅅䅁䉁䅁䅁权䙁䅁䅁䍄䉁䅁䅁睁䅁䅁䅍䅄䅁䅁䅕䅁䅁䉧敚づ䭅䉁䅫䅁䉁䅁䅁允䅁䅁䅯兂䅁䅁杷允䅁䅁䅍䅁䑁䅁䅷䅁䙁䅁䅁䅁敃汋䉆权啁䅁䅁允䅁䅁䅅䅁䭁䅁䅕䅁䵁䅉䅅䅁䑁䅁䅁睁䵁䅁䅁权⽁䅁䅁权䅁䅁䅁允䅁䅁䅅䅁䭁䅁䅉䅁䵁䅉䅅䅁䑁䅁䅁睁䵁䅁䅁兂䅁䅁睂㌹礵兑䅯杅䅁䅁䅅䅁䉁䅁䅁权剁䅁䅁䍄䉁䅁䅁睁䅁䅁䅍䅄䅁䅁䅕䅁䅁䑁塥䕕䭅䉁䅉䅁䉁䅁䅁允䅁䅁䅯充䅁䅁杷允䅁䅁䅍䅁䑁䅁䅷䅁䙁䅁䅁䅁獂ㅭ䉂权偁䅁䅁允䅁䅁䅅䅁䭁䅁䅕䅁䵁䅉䅅䅁䑁䅁䅁睁䵁䅁䅁兂䅁䅁䅁楮剰兑䅯睇䅁䅁䅅䅁䉁䅁䅁权䙁䅁䅁䍄䉁䅁䅁睁䅁䅁䅍䅄䅁䅁䅕䅁䅁䥧獙啕䭅䍁䅣䅁䉁䅁䅁允䅁䅁䅯兂䅁䅁杷允䅁䅁䅍䅁䑁䅁䅷䅁䙁䅁䅁䅁敄ㅇ䉬权䡁䅁䅁允䅁䅁䅅䅁䭁䅁䅕䅁䵁䅉䅅䅁䑁䅁䅁睁䵁䅁䅁兂䅁䅁䅄砶典兑䅯睃䅁䅁䅅䅁䉁
A2: 䅁䅁兂㑃潈牘払敩睐杷允䅁䅁䅍䅁䑁䅁䅷䅁䙁䅁䅁䕁元噮䉂权乁䅁䅁允䅁䅁䅅䅁䭁䙁䅁䅁䵁䅉䅅䅁䑁䅁䅁睁䵁䅁䅁兂䅁䅁䅄砶典兑䅯䅊䅁䅁䅅䅁䉁䅁䅁兂㝂䭆䠵場啱睐杷允䅁䅁䅍䅁䑁䅁䅷䅁䙁䅁䅁䅁敃汋䉆权坁䅁䅁允䅁䅁䅅䅁䭁䅁䅕䅁䵁䅉䅅䅁䑁䅁䅁睁䵁䅁䅁兂䅁䅁䅁灦剸兑䅯杉䅁䅁䅅䅁䉁䅁䅁权䙁䅁䅁䍄䉁䅁䅁睁䅁䅁䅍䅄䅁䅁䅕䅁䅁䩁焴啕䭅䍁䅑䅁䉁䅁䅁允䅁䅁䅯兂䅁䅁杷允䅁䅁䅍䅁䑁䅁䅷䅁䙁䅁䅁䅁敃汋䉆权潁䅁䅁允䅁䅁䅅䅁䭁䅁䅕䅁䵁䅉䅅䅁䑁䅁䅁睁䵁䅁䅁兂䅁䅁䅄㥹橊兑䅯兇䅁䅁䅅䅁䉁䅁䅁权䙁䅁䅁䍄䉁䅁䅁睁䅁䅁䅍䅄䅁䅁䅕䅁䅁䑧婗䕕䭅䅁䄰䅁䉁䅁䅁允䅁䅁䅯充䅁䅁杷允䅁䅁䅍䅁䑁䅁䅷䅁䙁䅁䅁䅁敄ㅇ䉬权塁䅁䅁允䅁䅁䅅䅁䭁䉁䅅䅁䵁䅉䅅䅁䑁䅁䅁睁䵁䅁䅁兂䅁䅁䅃婎公兑䅯䅅䅁䅁䅅䅁䉁䅁䅁权剁䅁䅁䍄䉁䅁䅁睁䅁䅁䅍䅄䅁䅁䅕䅁䅁䭁䘷䕕䭅䅁䅫䅁䉁䅁䅁允䅁䅁䅯杒䅁䅁杷允䅁䅁䅍䅁䑁䅁䅷䅁䙁䅁䅁䥁ㅁ噭䉂权扁䅁䅁允䅁䅁䅅䅁䭁䅁䅕䅁䵁䅉䅅䅁䑁䅁䅁睁䵁䅁䅁兂䅁䅁睂㌹礵兑䅯杇䅁䅁䅅䅁䉁䅁䅁权䙁䅁䅁䍄䉁䅁䅁睁䅁䅁䅍䅄䅁䅁䅕䅁䅁䑧婗䕕䭅䅁䅣䅁䉁䅁䅁允䅁䅁䅯兂䅁䅁杷允䅁䅁䅍䅁䑁䅁䅷䅁䙁䅁䅁䡁㍄湦䉊权歁䅁䅁允䅁䅁䅅䅁䙁䭁睒児塲⽯⽷䍄䉁䅁䅁睁䅁䅁䅍䅄䅁䅁䅕䅁䅁䉁乚ご䭅䅁䅧䅁䉁䅁䅁允䅁䅁䅯兂䅁䅁杷允䅁䅁䅍䅁䑁䅁䅷䅁䙁䅁䅁䥁ㅁ噭䉂权楁䅁䅁允䅁䅁䅅䅁䙁䑁䬰㘱睎剐䅰䍄䉁䅁䅁睁䅁䅁䅍䅄䅁䅁䅕䅁䅁乑慗䕕䭅䅁䄴䅁䉁䅁䅁允䅁䅁䅯兂䅁䅁杷允䅁䅁䅍䅁䑁䅁䅷䅁䙁䅁䅁䅁䥄䙶䉆权流䅁䅁允䅁䅁䅅䅁䭁䅁䅕䅁䵁䅉䅅䅁䑁䅁䅁睁䵁䅁䅁兂䅁䅁䅃婎公兑䅯睊䅁䅁䅅䅁䉁䅁䅁兂畃⭒㙆䭆渷睐杷允䅁䅁䅍䅁䑁䅁䅷䅁䙁䅁䅁䥁㝃汬䉂权䝁䅁䅁允䅁䅁䅅䅁䙁䡁啳歲桦潥⽑䍄䉁䅁䅁睁䅁䅁䅍䅄䅁䅁䅕䅁䅁䅧獖啕䭅䉁䅫䅁䉁䅁䅁允䅁䅁䅯兂䅁䅁杷允䅁䅁䅍䅁䑁䅁䅷䅁䙁䅁䅁䕁㡂ㅭ䉂权䕁䅁䅁允䅁䅁䅅䅁䭁䅁䅕䅁䵁䅉䅅䅁䑁䅁䅁睁䵁䅁䅁兂䅁䅁睂㌹礵兑䅯杈䅁䅁䅅䅁䉁䅁䅁权䙁䅁䅁䍄䉁䅁䅁睁䅁䅁䅍䅄䅁䅁䅕䅁䅁䡷婋䕕䭅䉁䅫䅁䉁䅁䅁允䅁䅁䅯兂䅁䅁杷允䅁䅁䅍䅁䑁䅁䅷䅁䙁䅁䅁䅁獂ㅭ䉂权䩁䅁䅁允䅁䅁䅅䅁䭁䅁䅯䅁䵁䅉䅅䅁䑁䅁䅁睁䵁䅁䅁兂䅁䅁䅃っ偂兑䅯䅃䅁䅁䅅䅁䉁䅁䅁权䙁䅁䅁䍄䉁䅁䅁睁䅁䅁䅍䅄䅁䅁䅕䅁䅁䩷椵啕䭅䍁䅙䅁䉁䅁䅁允䅁䅁䅯兂䅁䅁杷允䅁䅁䅍䅁䑁䅁䅷䅁䙁䅁䅁䕁䕁䘫䈹权十䅁䅁允䅁䅁䅅䅁䭁䕁䅅䅁䵁䅉䅅䅁䑁䅁䅁睁䵁䅁䅁兂䅁䅁䅁歆倱兑䅯杊䅁䅁䅅䅁䉁䅁䅁权䙁䅁䅁䍄䉁䅁䅁睁䅁䅁䅍䅄䅁䅁䅕䅁䅁䵁慭䕕䭅䅁䅣䅁䉁䅁䅁允䅁䅁䅯兂䅁䅁杷允䅁䅁䅍䅁䑁䅁䅷䅁䙁䅁䅁䡁㍄湦䉊权乁䅁䅁允䅁䅁䅅䅁䭁䉁䅅䅁䵁䅉䅅䅁䑁䅁䅁睁䵁䅁䅁兂䅁䅁䅁䩢兴兑䅯杉䅁䅁䅅䅁䉁䅁䅁权䙁䅁䅁䍄䉁䅁䅁睁䅁䅁䅍䅄䅁䅁䅕䅁䅁乁㜶啕䭅䉁䅳䅁䉁䅁䅁允䅁䅁䅯兂䅁䅁杷允䅁䅁䅍䅁䑁䅁䅷䅁䙁䅁䅁䕁穂噭䉂权䥁䅁䅁允䅁䅁䅅䅁䭁䅁䅕䅁䵁䅉䅅䅁䑁䅁䅁睁䵁䅁䅁兂䅁䅁䅁䩢兴兑䅯睉䅁䅁䅅䅁䉁䅁䅁权䙁䅁䅁䍄䉁䅁䅁睁䅁䅁䅍䅄䅁䅁䅕䅁䅁䝁批䕕䭅䍁䅣䅁䉁䅁䅁允䅁䅁䅯兂䅁䅁杷允䅁䅁䅍䅁䑁䅁䅷䅁䙁䅁䅁䅁獂ㅭ䉂权潁䅁䅁允䅁䅁䅅䅁䭁䅁䅕䅁䵁䅉䅅䅁䑁䅁䅁睁䵁䅁䅁兂䅁䅁䅁㕎兤兑䅯杉䅁䅁䅅䅁䉁䅁䅁权䙁䅁䅁䍄䉁䅁䅁睁䅁䅁䅍䅄䅁䅁䅕䅁䅁乑慗䕕䭅䉁䅷䅁䉁䅁䅁允䅁䅁䅕䉵䘶ㄶ㑇䕃䵁䅉䅅䅁䑁䅁䅁睁䵁䅁䅁兂䅁䅁䅁獲兖兑䅯睄䅁䅁䅅䅁䉁䅁䅁权䙁䅁䅁䍄䉁䅁䅁睁䅁䅁䅍䅄䅁䅁䅕䅁䅁䝁批䕕䭅䅁䄴䅁䉁䅁䅁允䅁䅁䅯兂䅁䅁杷允䅁䅁䅍䅁䑁䅁䅷䅁䙁䅁䅁䕁穂噭䉂权乁䅁䅁允䅁䅁䅅䅁䭁䅁䅯䅁䵁䅉䅅䅁䑁䅁䅁睁䵁䅁䅁兂䅁䅁䅂婏兰兑䅯䅂䅁䅁䅅䅁䉁䅁䅁权䙁䅁䅁䍄䉁䅁䅁睁䅁䅁䅍䅄䅁䅁䅕䅁䅁䡷婋䕕䭅䉁䅉䅁䉁䅁䅁允䅁䅁䅯充䅁䅁杷允䅁䅁䅍䅁䑁䅁䅷䅁䙁䅁䅁䕁穂噭䉂权啁䅁䅁允䅁䅁䅅䅁啁䍁匸䅧䅁䅁䅁䍄䉁䅁䅁睁䅁䅁䅍䅄䅁䅁䅕䅁䅁䡑婏䕕䭅䉁䅳䅁䉁䅁䅁允䅁䅁䅯兂䅁䅁杷允䅁䅁䅍䅁䑁䅁䅷䅁䙁䅁䅁佁䙂流䉂权䅁䅁䅁允䅁䅁䅅䅁䭁䅁䅍䅁䵁䅉䅅䅁䑁䅁䅁睁䵁䅁䅁兂䅁䅁䅂娱兰兑䅯元䅁䅁䅅䅁䉁䅁䅁权䕂䅁䅁䍄䉁䅁䅁睁䅁䅁䅍䅄䅁䅁䅕䅁䅁䡑婏䕕䭅䍁䅁䅁䉁䅁䅁允䅁䅁䅯兂䅁䅁杷允䅁䅁䅍䅁䑁䅁䅷䅁䙁䅁䅁䵁㕁ㅯ䉂权潁䅁䅁允䅁䅁䅅䅁䭁䅁䅕䅁䵁䅉䅅䅁䑁䅁䅁睁䵁䅁䅁兂䅁䅁䅃坂剸兑䅯睋䅁䅁䅅䅁䉁䅁䅁权䙁䅁䅁䍄䉁䅁䅁睁䅁䅁䅍䅄䅁䅁䅕䅁䅁䡁婩䕕䭅䅁䄸䅁䉁䅁䅁允䅁䅁䅯兂䅁䅁杷允䅁䅁䅍䅁䑁䅁䅷䅁䙁䅁䅁䕁噄汭䉂权敁䅁䅁允䅁䅁䅅䅁䭁䅁䅕䅁䵁䅉䅅䅁䑁䅁䅁睁䵁䅁䅁兂䅁䅁䅂㕣公兑䅯杂䅁䅁䅅䅁䉁䅁䅁权䙁䅁䅁䍄䉁䅁䅁睁䅁䅁䅍䅄䅁䅁䅕䅁䅁佷捳䕕䭅䉁䅙䅁䉁䅁䅁允䅁䅁䅯兂䅁䅁杷允䅁䅁䅍䅁䑁䅁䅷䅁䙁䅁䅁䅁䩄汭䉂权䝁䅁䅁允䅁䅁䅅䅁䭁䅁䅕䅁䵁䅉䅅䅁䑁䅁䅁睁䵁䅁䅁兂䅁䅁䅃っ偂兑䅯睇䅁䅁䅅䅁䉁䅁䅁权䙁䅁䅁䍄䉁䅁䅁睁䅁䅁䅍䅄䅁䅁䅕䅁䅁䡑婏䕕䭅䅁䄸䅁䉁䅁䅁允䅁䅁䅯兂䅁䅁杷允䅁䅁䅍䅁䑁䅁䅷䅁䙁䅁䅁䕁穂噭䉂权䕁䅁䅁允䅁䅁䅅䅁䭁䅁䅕䅁䵁䅉䅅䅁䑁䅁䅁睁䵁䅁䅁兂䅁䅁䅃坂剸兑䅯杅䅁䅁䅅䅁䉁䅁䅁权剁䅁䅁䍄䉁䅁䅁睁䅁䅁䅍䅄䅁䅁䅕䅁䅁䡑婏䕕䭅䉁䄸䅁䉁䅁䅁允䅁䅁䅯兂䅁䅁杷允䅁䅁䅍䅁䑁䅁䅷䅁䙁䅁䅁䡁㍄湦䉊权捁䅁䅁允䅁䅁䅅䅁䙁䥁牘払敧摨⽳䍄䉁䅁䅁睁䅁䅁䅍䅄䅁䅁䅕䅁䅁䡑婏䕕䭅䉁䅯䅁䉁䅁䅁允䅁䅁䅯兂䅁䅁杷允䅁䅁䅍䅁䑁䅁䅷䅁䙁䅁䅁䕁元噮䉂权敁䅁䅁允䅁䅁䅅䅁䙁䡁啳歲桦灥⽑䍄䉁䅁䅁睁䅁䅁䅍䅄䅁䅁䅕䅁䅁䍑ㅏ䕕䭅䉁䅷䅁䉁䅁䅁允䅁䅁䅕䥘䌯匹䵪䕗䵁䅉䅅䅁䑁䅁䅁睁䵁䅁䅁兂䅁䅁䅂娱兰兑䅯睂䅁䅁䅅䅁䉁䅁䅁权䙁䅁䅁䍄䉁䅁䅁睁䅁䅁䅍䅄䅁䅁䅕䅁䅁䭁䘷䕕䭅䍁䅳䅁䉁䅁䅁允䅁䅁䅯兂䅁䅁杷允䅁䅁䅍䅁䑁䅁䅷䅁䙁䅁䅁䅁楃歙䈹权婁䅁䅁允䅁䅁䅅䅁䭁䅁䅕䅁䵁䅉䅅䅁䑁䅁䅁睁䵁䅁䅁兂䅁䅁䅂㝉兖兑䅯睋䅁䅁䅅䅁䉁䅁䅁权䙁䅁䅁䍄䉁䅁䅁睁䅁䅁䅍䅄䅁䅁䅕䅁䅁䵁㡩啕䭅䉁䄴䅁䉁䅁䅁允䅁䅁䅕灭婭婭婭い䵁䅉䅅䅁䑁䅁䅁睁䵁䅁䅁兂䅁䅁䅁䱹剸兑䅯䅃䅁䅁䅅䅁䉁䅁䅁权䙁䅁䅁䍄䉁䅁䅁睁䅁䅁䅍䅄䅁䅁䅕䅁䅁䵁㡩啕䭅䅁䅣䅁䉁䅁䅁允䅁䅁䅯兂䅁䅁杷允䅁䅁䅍䅁䑁䅁䅷䅁䙁䅁䅁䵁敃汙䉆权婁䅁䅁允䅁䅁䅅䅁䭁䅁䅕䅁䵁䅉䅅䅁䑁䅁䅁睁䵁䅁䅁兂䅁䅁䅁䱹剸兑䅯杉䅁䅁䅅䅁䉁䅁䅁权䙁䅁䅁䍄䉁䅁䅁睁䅁䅁䅍䅄䅁䅁䅕䅁䅁䱧坵䕕䭅䅁䅣䅁䉁䅁䅁允䅁䅁䅯兂䅁䅁杷允䅁䅁䅍䅁䑁䅁䅷䅁䙁䅁䅁䅁敄ㅇ䉬权捁䅁䅁允䅁䅁䅅䅁䙁佁剸䉵䘶ぱ䅎䍄䉁䅁䅁睁䅁䅁䅍䅄䅁䅁䅕䅁䅁䭁楊ご䭅䅁䄰䅁䉁䅁䅁允䅁䅁䅯充䅁䅁杷允䅁䅁䅍䅁䑁䅁䅷䅁䙁䅁䅁䥁䝃䙌䉆权汁䅁䅁允䅁䅁䅅䅁䭁䅁䅕䅁䵁䅉䅅䅁䑁䅁䅁睁䵁䅁䅁兂䅁䅁䅁䱹剸兑䅯睃䅁䅁䅅䅁䉁䅁䅁权䙁䅁䅁䍄䉁䅁䅁睁䅁䅁䅍䅄䅁䅁䅕䅁䅁䵁㡩啕䭅䅁䅑䅁䉁䅁䅁允䅁䅁䅯兂䅁䅁杷允䅁䅁䅍䅁䑁䅁䅷䅁䙁䅁䅁䅁䥄䙶䉆权晁䅁䅁允䅁䅁䅅䅁䭁䅁䅕䅁䵁䅉䅅䅁䑁䅁䅁睁䵁䅁䅁兂䅁䅁䅂偂晨兑䅯䅉䅁䅁䅅䅁䉁䅁䅁权䙁䅁䅁䍄䉁䅁䅁睁䅁䅁䅍䅄䅁䅁䅕䅁䅁䉁乚ご䭅䉁䅙䅁䉁䅁䅁允䅁䅁䅯兂䅁䅁杷允䅁䅁䅍䅁䑁䅁䅷䅁䙁䅁䅁䅁㑂噭䉂权敁䅁䅁允䅁䅁䅅䅁䭁䅁䅕䅁䵁䅉䅅䅁䑁䅁䅁睁䵁䅁䅁兂䅁䅁䅃楨剸兑䅯睃䅁䅁䅅䅁䉁䅁䅁权䙁䅁䅁䍄䉁䅁䅁睁䅁䅁䅍䅄䅁䅁䅕䅁䅁䵁慭䕕䭅䉁䅙䅁䉁䅁䅁允䅁䅁䅯兂䅁䅁杷允䅁䅁䅍䅁䑁䅁䅷䅁䙁䅁䅁䅁䥄䙶䉆权婁䅁䅁允䅁䅁䅅䅁䭁䅁䅕䅁䵁䅉䅅䅁䑁䅁䅁睁䵁䅁䅁兂䅁䅁䅁浯偊兑䅯䅆䅁䅁䅅䅁䉁䅁䅁权䙁䅁䅁䍄䉁䅁䅁睁䅁䅁䅍䅄䅁䅁䅕䅁䅁䱧坵䕕䭅䉁䅙䅁䉁䅁䅁允䅁䅁䅯兂䅁䅁杷允䅁䅁䅍䅁䑁䅁䅷䅁䙁䅁䅁䅁䩄汭䉂权䥁䅁䅁允䅁䅁䅅䅁䭁䅁䅕䅁䵁䅉䅅䅁䑁䅁䅁睁䵁䅁䅁兂䅁䅁䅃坂剸兑䅯䅃䅁䅁䅅䅁䉁䅁䅁权䙁䅁䅁䍄䉁䅁䅁睁䅁䅁䅍䅄䅁䅁䅕䅁䅁䝑愲䕕䭅䉁䄸䅁䉁䅁䅁允䅁䅁䅯兂䅁䅁杷允䅁䅁䅍䅁䑁䅁䅷䅁䙁䅁䅁䥁䙁䙢䉆权楁䅁䅁允䅁䅁䅅䅁䭁䅁䅕䅁䵁䅉䅅䅁䑁䅁䅁睁䵁䅁䅁兂䅁䅁䅂䩫儱兑䅯睄䅁䅁䅅䅁䉁䅁䅁权䙁䅁䅁䍄䉁䅁䅁睁䅁䅁䅍䅄䅁䅁䅕䅁䅁䉁乚ご䭅䉁䅯䅁䉁䅁䅁允䅁䅁䅯兂䅁䅁杷允䅁䅁䅍䅁䑁䅁䅷䅁䙁䅁䅁䥁䝃䙌䉆权乁䅁䅁允䅁䅁䅅䅁䭁䉁䅅䅁䵁䅉䅅䅁䑁䅁䅁睁䵁䅁䅁兂䅁䅁䅃㕵党兑䅯䅃䅁䅁䅅䅁䉁䅁䅁权䙁䅁䅁䍄䉁䅁䅁睁䅁䅁䅍䅄䅁䅁䅕䅁䅁䵷卶す䭅䉁䅷䅁䉁䅁䅁允䅁䅁䅯兂䅁䅁杷允䅁䅁䅍䅁䑁䅁䅷䅁䙁䅁䅁䥁䙁䙢䉆权歁䅁䅁允䅁䅁䅅䅁䭁䅁䅕䅁䵁䅉䅅䅁䑁䅁䅁睁䵁䅁䅁兂䅁䅁䅂娱兰兑䅯睈䅁䅁䅅䅁䉁䅁䅁权䙁䅁䅁䍄䉁䅁䅁睁䅁䅁䅍䅄䅁䅁䅕䅁䅁䭁楊ご䭅䅁䅷䅁䉁䅁䅁允䅁䅁䅕㘱睎児塯こ䵁䅉䅅䅁䑁䅁䅁睁䵁䅁䅁兂䅁䅁䅁栳婴兑䅯杉䅁䅁䅅䅁䉁䅁䅁权䙁䅁䅁䍄䉁䅁䅁睁䅁䅁䅍䅄䅁䅁䅕䅁䅁乑慗䕕䭅䍁䅙䅁䉁䅁䅁允䅁䉁䅑䅁䅁䅁䅁䅁䵁䅉䅅䅁䑁䅁䅁睁䵁䅁䅁兂䅁䅁䅃っ偂兑䅯睋䅁䅁䅅䅁䉁䅁䅁权䙁䅁䅁䍄䉁䅁䅁睁䅁䅁䅍䅄䅁䅁䅕䅁䅁䭁楊ご䭅䉁䄴䅁䉁䅁䅁允䅁䅁䅕呣䬰㘱睎啄䵁䅉䅅䅁䑁䅁䅁睁䵁䅁䅁兂䅁䅁䅁浯偊兑䅯䅃䅁䅁䅅䅁䉁䅁䅁兂㑃潈牘払敩睐杷允䅁䅁䅍䅁䑁䅁䅷䅁䙁䅁䅁䅁楃歙䈹权楁䅁䅁允䅁䅁䅅䅁啁䅁䅁䅁䅁䅁䅁䍄䉁䅁䅁睁䅁䅁䅍䅄䅁䅁䅕䅁䅁佷捳䕕䭅䍁䅧䅁䉁䅁䅁允䅁䅁䅯兂䅁䅁杷允䅁䅁䅍䅁䑁䅁䅷䅁䙁䅁䅁䅁畃噸䉂权允䅁䅁允䅁䅁䅅䅁䭁䕁䅙䅁䵁䅉䅅䅁䑁䅁䅁睁䵁䅁䅁兂䅁䅁䅂婏兰兑䅯睋䅁䅁䅅䅁䉁䅁䅁权䙁䅁䅁䍄䉁䅁䅁睁䅁䅁䅍䅄䅁䅁䅕䅁䅁䅑㑔じ䭅䍁䅧䅁䉁䅁䅁允䅁䅁䅯兂䅁䅁杷允䅁䅁䅍䅁䑁䅁䅷䅁䙁䅁䅁䅁楃歙䈹权杁䅁䅁允䅁䅁䅅䅁䙁䥁䌯匹捨㥪⽉䍄䉁䅁䅁睁䅁䅁䅍䅄䅁䅁䅕䅁䅁䩑摃䕕䭅䉁䅫䅁䉁䅁䅁允䅁䅁䅕䅁䅁䅁䅄啖䵁䅉䅅䅁䑁䅁䅁睁䵁䅁䅁兂䅁䅁䅁浯偊兑䅯睊䅁䅁䅅䅁䉁䅁䅁兂䅁䅁䅁䅁兄睐杷允䅁䅁䅍䅁䑁䅁䅷䅁䙁䅁䅁䅁楃歙䈹权偁䅁䅁允䅁䅁䅅䅁䙁䵁ㅐ䙋偹癷⽅䍄䉁䅁䅁睁䅁䅁䅍䅄䅁䅁䅕䅁䅁䭁楊ご䭅䉁䅯䅁䉁䅁䅁允䅁䅁䅯兂䅁䅁杷允䅁䅁䅍䅁䑁䅁䅷䅁䙁䅁䅁䥁㝃汬䉂权塁䅁䅁允䅁䅁䅅䅁䭁䉁䅅䅁䵁䅉䅅䅁䑁䅁䅁睁䵁䅁䅁兂䅁䅁䅃㕵党兑䅯杉䅁䅁䅅䅁䉁䅁䅁䅆䅁䅁䅁䅁䅁䅁杷允䅁䅁䅍䅁䑁䅁䅷䅁䙁䅁䅁䡁㍄湦䉊权䩁䅁䅁允䅁䅁䅅䅁䭁䑁䅧䅁䵁䅉䅅䅁䑁䅁䅁睁䵁䅁䅁兂䅁䅁䅃㕵党兑䅯睉䅁䅁䅅䅁䉁䅁䅁兂䅁䅁䅁䅁䥁䅑杷允䅁䅁䅍䅁䑁䅁䅷䅁䙁䅁䅁䥁㝃汬䉂权䱁䅁䅁允䅁䅁䅅䅁䙁䵁ㅐ䙋偹獷⽕䍄䉁䅁䅁睁䅁䅁䅍䅄䅁䅁䅕䅁䅁䑁塥䕕䭅䅁䄰䅁䉁䅁䅁允䅁䅁䅯充䅁䅁杷允䅁䅁䅍䅁䑁䅁䅷䅁䙁䅁䅁䅁㍁ㅬ䉂权敁䅁䅁允䅁䅁䅅䅁䙁䱁敧敨剴䭵⼴䍄䉁䅁䅁睁䅁䅁䅍䅄䅁䅁䅕䅁䅁䑁塥䕕䭅䉁䅳䅁䉁䅁䅁允䅁䅁䅯兂䅁䅁杷允䅁䅁䅍䅁䑁䅁䅷䅁䙁䅁䅁䕁噄汭䉂权扁䅁䅁允䅁䅁䅅䅁䭁䅁䅕䅁䵁䅉䅅䅁䑁䅁䅁睁䵁䅁䅁兂䅁䅁䅁㕎兤兑䅯䅃䅁䅁䅅䅁䉁䅁䅁䅆䅁䅁䅁䅁䅁䅁杷允䅁䅁䅍䅁䑁䅁䅷䅁䙁䅁䅁䅁㍁ㅬ䉂权䡁䅁䅁允䅁䅁䅅䅁䭁䅁䅕䅁䵁䅉䅅䅁䑁䅁䅁睁䵁䅁䅁兂䅁䅁䅁㕎兤兑䅯兊䅁䅁䅅䅁䉁䅁䅁权䙁䅁䅁䍄䉁䅁䅁睁䅁䅁䅍䅄䅁䅁䅕䅁䅁䝑愲䕕䭅䍁䅳䅁䉁䅁䅁允䅁䅁䅯兂䅁䅁杷允䅁䅁䅍䅁䑁䅁䅷䅁䙁䅁䅁䅁䩄汭䉂权橁䅁䅁允䅁䅁䅅䅁䭁䅁䅕䅁䵁䅉䅅䅁䑁䅁䅁睁䵁䅁䅁权⭁䅁䅁权䅁䅁䅁允䅁䅁䅅䅁䭁䅁䅉䅁䵁䅉䅅䅁䑁䅁䅁睁䵁䅁䅁兂䅁䅁䅁獲兖兑䅯睈䅁䅁䅅䅁䉁䅁䅁权䙁䅁䅁䍄䉁䅁䅁睁䅁䅁䅍䅄䅁䅁䅕䅁䅁佷捳䕕䭅䍁䅁䅁䉁䅁䅁允䅁䅁䅕椹捨㡪ㅌ䐹䴸䅉䅅䅁䑁䅁䅁睁䵁䅁䅁兂䅁䅁䅁歆倱兑䅯䅋䅁䅁䅅䅁䉁䅁䅁权䙁䅁䅁䍄䉁䅁䅁睁䅁䅁䅍䅄䅁䅁䅕䅁䅁䑁塥䕕䭅䅁䄴䅁䉁䅁䅁允䅁䅁䅯兂䅁䅁杷允䅁䅁䅍䅁䑁䅁䅷䅁䙁䅁䅁䅁敄ㅇ䉬权䩁䅁䅁允䅁䅁䅅䅁䭁䅁䅯䅁䵁䅉䅅䅁䑁䅁䅁睁䵁䅁䅁兂䅁䅁䅁栳婴兑䅯杊䅁䅁䅅䅁䉁䅁䅁权䙁䅁䅁䍄䉁䅁䅁睁䅁䅁䅍䅄䅁䅁䅕䅁䅁乁戴啗䭅䉁䅉䅁䉁䅁䅁允䅁䅁䅯充䅁䅁杷允䅁䅁䅍䅁䑁䅁䅷䅁䙁䅁䅁䅁敄ㅇ䉬权啁䅁䅁允䅁䅁䅅䅁䭁䅁䅕䅁䵁䅉䅅䅁䑁䅁䅁睁䵁䅁䅁兂䅁䅁䅁栳婴兑䅯睇䅁䅁䅅䅁䉁䅁䅁权䙁䅁䅁䍄䉁䅁䅁睁䅁䅁䅍䅄䅁䅁䅕䅁䅁䵁慭䕕䭅䉁䅁䅁䉁䅁䅁允䅁䅁䅯充䅁䅁杷允䅁䅁䅍䅁䑁䅁䅷䅁䙁䅁䅁䅁敄ㅇ䉬权杁䅁䅁允䅁䅁䅅䅁䙁䩁婱婭婭慭⽫䍄䉁䅁䅁睁䅁䅁䅍䅄䅁䅁䅕䅁䅁乁戴啗䭅䍁䅣䅁䉁䅁䅁允䅁䅁䅕䉵䘶ㄶ㑇橮䴸䅉䅅䅁䑁䅁䅁睁䵁䅁䅁兂䅁䅁䅁栳婴兑䅯䅄䅁䅁䅅䅁䉁䅁䅁兂㥁瑃橥䱣〰䅑杷允䅁䅁䅍䅁䑁䅁䅷䅁䙁䅁䅁䅁敄ㅇ䉬权橁䅁䅁允䅁䅁䅅䅁䭁䅁䅕䅁䵁䅉䅅䅁䑁䅁䅁睁䵁䅁䅁兂䅁䅁䅁栳婴兑䅯杆䅁䅁䅅䅁䉁䅁䅁权䙁䅁䅁䍄䉁䅁䅁睁䅁䅁䅍䅄䅁䅁䅕䅁䅁乁戴啗䭅䍁䅳䅁䉁䅁䅁允䅁䅁䅯兂䅁䅁杷允䅁䅁䅍䅁䑁䅁䅷䅁䙁䅁䅁䵁牄䙈䉂权䥁䅁䅁允䅁䅁䅅䅁䙁䕁桪桥畓硒䄱䍄䉁䅁䅁睁䅁䅁䅍䅄䅁䅁䅕䅁䅁佷捳䕕䭅䅁䅣䅁䉁䅁䅁允䅁䅁䅯兂䅁䅁杷允䅁䅁䅍䅁䑁䅁䅷䅁䙁䅁䅁䵁牄䙈䉂权流䅁䅁允䅁䅁䅅䅁啁䅁䅁䅁䅁䅁䅁䍄䉁䅁䅁睁䅁䅁䅍䅄䅁䅁䅕䅁䅁佷捳䕕䭅䍁䅍䅁䉁䅁䅁允䅁䅁䅯兂䅁䅁杷允䅁䅁䅍䅁䑁䅁䅷䅁䙁䅁䅁䅁䩄汭䉂权扁䅁䅁允䅁䅁䅅䅁䭁䅁䅕䅁䵁䅉䅅䅁䑁䅁䅁睁䵁䅁䅁兂䅁䅁䅄砶典兑䅯睈䅁䅁䅅䅁䉁䅁䅁权䙁䅁䅁䍄䉁䅁䅁睁䅁䅁䅍䅄䅁䅁䅕䅁䅁䩷椵啕䭅䅁䅣䅁䉁䅁䅁允䅁䅁䅯兂䅁䅁杷允䅁䅁䅍䅁䑁䅁䅷䅁䙁䅁䅁䵁敃汙䉆权湁䅁䅁允䅁䅁䅅䅁䙁䉁䘫ㄶ㑇杈䅎䍄䉁䅁䅁睁䅁䅁䅍䅄䅁䅁䅕䅁䅁䥧獙啕䭅䍁䅙䅁䉁䅁䅁允䅁䅁䅯兂䅁䅁杷允䅁䅁䅍䅁䑁䅁䅷䅁䙁䅁䅁䵁牄䙈䉂权牁䅁䅁允䅁䅁䅅䅁啁䅁䅁䅁䅁䅁䅁䍄䉁䅁䅁睁䅁䅁䅍䅄䅁䅁䅕䅁䅁佷捳䕕䭅䉁䅫䅁䉁䅁䅁允䅁䅁䅕䘷㑇潈牘歇䵁䅉䅅䅁䑁䅁䅁睁䵁䅁䅁兂䅁䅁䅃っ偂兑䅯杊䅁䅁䅅䅁䉁䅁䅁兂慃婭婭婭灭睐杷允䅁䅁䅍䅁䑁䅁䅷䅁䙁䅁䅁䕁䕁䘫䈹权䩁䅁䅁允䅁䅁䅅䅁䭁䕁䅧䅁䵁䅉䅅䅁䑁䅁䅁睁䵁䅁䅁兂䅁䅁䅁歆倱兑䅯睄䅁䅁䅅䅁䉁䅁䅁权䙁䅁䅁䍄䉁䅁䅁睁䅁䅁䅍䅄䅁䅁䅕䅁䅁乁㜶啕䭅䅁䄴䅁䉁䅁䅁允䅁䅁䅯兂䅁䅁杷允䅁䅁䅍䅁䑁䅁䅷䅁䙁䅁䅁䕁䕁䘫䈹权塁䅁䅁允䅁䅁䅅䅁䭁䕁䅫䅁䵁䅉䅅䅁䑁䅁䅁睁䵁䅁䅁兂䅁䅁䅂偂晨兑䅯䅅䅁䅁䅅䅁䉁䅁䅁权煁䅁䅁䍄䉁䅁䅁睁䅁䅁䅍䅄䅁䅁䅕䅁䅁䅑㑔じ䭅䉁䄴䅁䉁䅁䅁允䅁䅁䅯兂䅁䅁杷允䅁䅁䅍䅁䑁䅁䅷䅁䙁䅁䅁䕁䕁䘫䈹权䡁䅁䅁允䅁䅁䅅䅁䭁䅁䅕䅁䵁䅉䅅䅁䑁䅁䅁睁䵁䅁䅁兂䅁䅁䅂偂晨兑䅯杉䅁䅁䅅䅁䉁䅁䅁权䙁䅁䅁䍄䉁䅁䅁睁䅁䅁䅍䅄䅁䅁䅕䅁䅁䅑㑔じ䭅䍁䅕䅁䉁䅁䅁允䅁䅁䅯兂䅁䅁杷允䅁䅁䅍䅁䑁䅁䅷䅁䙁䅁䅁䕁䕁䘫䈹权䱁䅁䅁允䅁䅁䅅䅁䭁䅁䅕䅁䵁䅉䅅䅁䑁䅁䅁睁䵁䅁䅁兂䅁䅁䅂偂晨兑䅯䅊䅁䅁䅅䅁䉁䅁䅁权䙁䅁䅁䍄䉁䅁䅁睁䅁䅁䅍䅄䅁䅁䅕䅁䅁䅑㑔じ䭅䉁䅙䅁䉁䅁䅁允䅁䅁䅯兂䅁䅁杷允䅁䅁䅍䅁䑁䅁䅷䅁䙁䅁䅁䕁橁噴䉂权䩁䅁䅁允䅁䅁䅅䅁䭁䕁䅁䅁䵁䅉䅅䅁䑁䅁䅁睁䵁䅁䅁兂䅁䅁䅃っ偂兑䅯䅉䅁䅁䅅䅁䉁䅁䅁兂㑃潈牘払敩睐杷允䅁䅁䅍䅁䑁䅁䅷䅁䙁䅁䅁䕁橁噴䉂权䕁䅁䅁允䅁䅁䅅䅁䭁䅁䅕䅁䵁䅉䅅䅁䑁䅁䅁睁䵁䅁䅁兂䅁䅁䅂㝉兖兑䅯杇䅁䅁䅅䅁䉁䅁䅁权䙁䅁䅁䍄䉁䅁䅁睁䅁䅁䅍䅄䅁䅁䅕䅁䅁䥧獙啕䭅䉁䅫䅁䉁䅁䅁允䅁䅁䅯兂䅁䅁杷允䅁䅁䅍䅁䑁䅁䅷䅁䙁䅁䅁䵁祂噭䉂权杁䅁䅁允䅁䅁䅅䅁䭁䅁䅕䅁䵁䅉䅅䅁䑁䅁䅁睁䵁䅁䅁兂䅁䅁䅁䩥公兑䅯睈䅁䅁䅅䅁䉁䅁䅁权䙁䅁䅁䍄䉁䅁䅁睁䅁䅁䅍䅄䅁䅁䅕䅁䅁䥧獙啕䭅䅁䅫䅁䉁䅁䅁允䅁䅁䅯杓䅁䅁杷允䅁䅁䅍䅁䑁䅁䅷䅁䙁䅁䅁䅁坁啔䈹权牁䅁䅁允䅁䅁䅅䅁䭁䅁䅕䅁䵁䅉䅅䅁䑁䅁䅁睁䵁䅁䅁兂䅁䅁䅃楨剸兑䅯杅䅁䅁䅅䅁䉁䅁䅁权剁䅁䅁䍄䉁䅁䅁睁䅁䅁䅍䅄䅁䅁䅕䅁䅁䡁婩䕕䭅䍁䅁䅁䉁䅁䅁允䅁䅁䅯兂䅁䅁杷允䅁䅁䅍䅁䑁䅁䅷䅁䙁䅁䅁䥁䝃䙌䉆权敁䅁䅁允䅁䅁䅅䅁䭁䅁䅕䅁䵁䅉䅅䅁䑁䅁䅁睁䵁䅁䅁兂䅁䅁䅃楨剸兑䅯睇䅁䅁䅅䅁䉁䅁䅁权䙁䅁䅁䍄䉁䅁䅁睁䅁䅁䅍䅄䅁䅁䅕䅁䅁䥧獙啕䭅䅁䅣䅁䉁䅁䅁允䅁䅁䅯兂䅁䅁杷允䅁䅁䅍䅁䑁䅁䅷䅁䙁䅁䅁䥁䝃䙌䉆权潁䅁䅁允䅁䅁䅅䅁䭁䅁䅕䅁䵁䅉䅅䅁䑁䅁䅁睁䵁䅁䅁兂䅁䅁䅁歆倱兑䅯元䅁䅁䅅䅁䉁䅁䅁权㑁䅁䅁䍄䉁䅁䅁睁䅁䅁䅍䅄䅁䅁䅕䅁䅁乁㜶啕䭅䉁䅷䅁䉁䅁䅁允䅁䅁䅯兂䅁䅁杷允䅁䅁䅍䅁䑁䅁䅷䅁䙁䅁䅁䡁㍄湦䉊权允䅁䅁允䅁䅁䅅䅁䭁䉁䅅䅁䵁䅉䅅䅁䑁䅁䅁睁䵁䅁䅁兂䅁䅁䅁歆倱兑䅯兄䅁䅁䅅䅁䉁䅁䅁权剁䅁䅁䍄䉁䅁䅁睁䅁䅁䅍䅄䅁䅁䅕䅁䅁偣⭤正䭅䅁䅷䅁䉁䅁䅁允䅁䅁䅕敨剴䉵䘶稲䴸䅉䅅䅁䑁䅁䅁睁䵁䅁䅁兂䅁䅁䅁䩥公兑䅯杂䅁䅁䅅䅁䉁䅁䅁权䙁䅁䅁䍄䉁䅁䅁睁䅁䅁䅍䅄䅁䅁䅕䅁䅁䉁乚ご䭅䅁䅣䅁䉁䅁䅁允䅁䅁䅯兂䅁䅁杷允䅁䅁䅍䅁䑁䅁䅷䅁䙁䅁䅁䅁坁啔䈹权䵁䅁䅁允䅁䅁䅅䅁䙁䵁䴳䵺䵺佺⽷䍄䉁䅁䅁睁䅁䅁䅍䅄䅁䅁䅕䅁䅁䡷婋䕕䭅䉁䄸䅁䉁䅁䅁允䅁䅁䅯兂䅁䅁杷允䅁䅁䅍䅁䑁䅁䅷䅁䙁䅁䅁䅁⭂䙮䉆权歁䅁䅁允䅁䅁䅅䅁䭁䅁䅕䅁䵁䅉䅅䅁䑁䅁䅁睁䵁䅁䅁兂䅁䅁睂㌹礵兑䅯䅂䅁䅁䅅䅁䉁䅁䅁兂歃䑣䬰㈱硍䅑杷允䅁䅁䅍䅁䑁䅁䅷䅁䙁䅁䅁䅁坁啔䈹权䱁䅁䅁允䅁䅁䅅䅁䭁䅁䅕䅁䵁䅉䅅䅁䑁䅁䅁睁䵁䅁䅁兂䅁䅁䅂娱兰兑䅯兊䅁䅁䅅䅁䉁䅁䅁权䙁䅁䅁䍄䉁䅁䅁睁䅁䅁䅍䅄䅁䅁䅕䅁䅁䉁乚ご䭅䍁䅑䅁䉁䅁䅁允䅁䅁䅕䉵䘶ㄶ㑇橺䴸䅉䅅䅁䑁䅁䅁睁䵁䅁䅁兂䅁䅁䅂婏兰兑䅯䅋䅁䅁䅅䅁䉁䅁䅁权䙁䅁䅁䍄䉁䅁䅁睁䅁䅁䅍䅄䅁䅁䅕䅁䅁䉁乚ご䭅䉁䄸䅁䉁䅁䅁允䅁䅁䅯兂䅁䅁杷允䅁䅁䅍䅁䑁䅁䅷䅁䙁䅁䅁䅁⭂䙮䉆权乁䅁䅁允䅁䅁䅅䅁䭁䉁䅅䅁䵁䅉䅅䅁䑁䅁䅁睁䵁䅁䅁兂䅁䅁䅁灦剸兑䅯杈䅁䅁䅅䅁䉁䅁䅁权䙁䅁䅁䍄䉁䅁䅁睁䅁䅁䅍䅄䅁䅁䅕䅁䅁䵁慭䕕䭅䉁䅯䅁䉁䅁䅁允䅁䅁䅯兂䅁䅁杷允䅁䅁䅍䅁䑁䅁䅷䅁䙁䅁䅁䅁⭂䙮䉆权䥁䅁䅁允䅁䅁䅅䅁䭁䅁䅕䅁䵁䅉䅅䅁䑁䅁䅁睁䵁䅁䅁兂䅁䅁䅁灦剸兑䅯兇䅁䅁䅅䅁䉁䅁䅁权䙁䅁䅁䍄䉁䅁䅁睁䅁䅁䅍䅄䅁䅁䅕䅁䅁䡁挶啕䭅䅁䅣䅁䉁䅁䅁允䅁䅁䅯兂䅁䅁杷允䅁䅁䅍䅁䑁䅁䅷䅁䙁䅁䅁䅁⭂䙮䉆权杁䅁䅁允䅁䅁䅅䅁䭁䅁䅕䅁䵁䅉䅅䅁䑁䅁䅁睁䵁䅁䅁兂䅁䅁䅁灦剸兑䅯睊䅁䅁䅅䅁䉁䅁䅁权䙁䅁䅁䍄䉁䅁䅁睁䅁䅁䅍䅄䅁䅁䅕䅁䅁䑑慭䕕䭅䉁䅑䅁䉁䅁䅁允䅁䉁䅑倲䝆䅁䅁䅁䵁䅉䅅䅁䑁䅁䅁睁䵁䅁䅁兂䅁䅁䅁爳剴兑䅯杊䅁䅁䅅䅁䉁䅁䅁权䙁䅁䅁䍄䉁䅁䅁睁䅁䅁䅍䅄䅁䅁䅕䅁䅁䡷婋䕕䭅䍁䅙䅁䉁䅁䅁允䅁䅁䅯兂䅁䅁杷允䅁䅁䅍䅁䑁䅁䅷䅁䙁䅁䅁䅁⭂䙮䉆权䕁䅁䅁允䅁䅁䅅䅁䭁䅁䅕䅁䵁䅉䅅䅁䑁䅁䅁睁䵁䅁䅁兂䅁䅁䅂婢兰兑䅯䅅䅁䅁䅅䅁䉁䅁䅁权剁䅁䅁䍄䉁䅁䅁睁䅁䅁䅍䅄䅁䅁䅯充䅁䅁䅯䅁䅁䅁䅅䅁䉁䅁䅁权啂䅁䅁䍄䉁䅁䅁睁䅁䅁䅍䅄䅁䅁䅕䅁䅁䡁挶啕䭅䍁䅳䅁䉁䅁䅁允䅁䅁䅯兂䅁䅁杷允䅁䅁䅍䅁䑁䅁䅷䅁䙁䅁䅁䵁㕁ㅯ䉂权䩁䅁䅁允䅁䅁䅅䅁䭁䕁䅷䅁䵁䅉䅅䅁䑁䅁䅁睁䵁䅁䅁兂䅁䅁䅄慏兎兑䅯睆䅁䅁䅅䅁䉁䅁䅁权䍂䅁䅁䍄䉁䅁䅁睁䅁䅁䅍䅄䅁䅁䅕䅁䅁䑷橭䕕䭅䉁䅑䅁䉁䅁䅁允䅁䉁䅑硌䅋䅁䅁䅁䵁䅉䅅䅁䑁䅁䅁睁䵁䅁䅁兂䅁䅁䅄慏兎兑䅯睂䅁䅁䅅䅁䉁䅁䅁权䙁䅁䅁䍄䉁䅁䅁睁䅁䅁䅍䅄䅁䅁䅕䅁䅁䑷橭䕕䭅䍁䅁䅁䉁䅁䅁允䅁䅁䅯兂䅁䅁杷允䅁䅁䅍䅁䑁䅁䅷䅁䙁䅁䅁䵁㕁ㅯ䉂权䵁䅁䅁允䅁䅁䅅䅁䙁佁㙆䭆䠵卙䅤䍄䉁䅁䅁睁䅁䅁䅍䅄䅁䅁䅕䅁䅁䩷椵啕䭅䅁䅙䅁䉁䅁䅁允䅁䅁䅕歲桦桥畓稹䴸䅉䅅䅁䑁䅁䅁睁䵁䅁䅁兂䅁䅁䅄慏兎兑䅯睈䅁䅁䅅䅁䉁䅁䅁权䙁䅁䅁䍄䉁䅁䅁睁䅁䅁䅍䅄䅁䅁䅕䅁䅁䑷橭䕕䭅䍁䅳䅁䉁䅁䅁允䅁䅁䅯兂䅁䅁杷允䅁䅁䅍䅁䑁䅁䅷䅁䙁䅁䅁䅁畃噸䉂权乁䅁䅁允䅁䅁䅅䅁䭁䕁䅙䅁䵁䅉䅅䅁䑁䅁䅁睁䵁䅁䅁兂䅁䅁䅁獲兖兑䅯䅆䅁䅁䅅䅁䉁䅁䅁䅆啃㙏䅣䅁䅁䅁杷允䅁䅁䅍䅁䑁䅁䅷䅁䙁䅁䅁䅁畃噸䉂权捁䅁䅁允䅁䅁䅅䅁䭁䅁䅕䅁䵁䅉䅅䅁䑁䅁䅁睁䵁䅁䅁兂䅁䅁䅁獲兖兑䅯䅃䅁䅁䅅䅁䉁䅁䅁权䙁䅁䅁䍄䉁䅁䅁睁䅁䅁䅍䅄䅁䅁䅕䅁䅁䩑摃䕕䭅䍁䅧䅁䉁䅁䅁允䅁䅁䅯兂䅁䅁杷允䅁䅁䅍䅁䑁䅁䅷䅁䙁䅁䅁䕁噄汭䉂权䥁䅁䅁允䅁䅁䅅䅁䭁䅁䅕䅁䵁䅉䅅䅁䑁䅁䅁睁䵁䅁䅁兂䅁䅁䅁獲兖兑䅯䅉䅁䅁䅅䅁䉁䅁䅁权䙁䅁䅁䍄䉁䅁䅁睁䅁䅁䅍䅄䅁䅁䅕䅁䅁䡷婋䕕䭅䉁䅁䅁䉁䅁䅁允䅁䅁䅯充䅁䅁杷允䅁䅁䅍䅁䑁䅁䅷䅁䙁䅁䅁䅁畃噸䉂权汁䅁䅁允䅁䅁䅅䅁䭁䅁䅕䅁䵁䅉䅅䅁䑁䅁䅁睁䵁䅁䅁兂䅁䅁睂㌹礵兑䅯睄䅁䅁䅅䅁䉁䅁䅁权䙁䅁䅁䍄䉁䅁䅁睁䅁䅁䅍䅄䅁䅁䅕䅁䅁䡧䅎ご䭅䉁䅁䅁䉁䅁䅁允䅁䅁䅯充䅁䅁杷允䅁䅁䅍䅁䑁䅁䅷䅁䙁䅁䅁䅁畃噸䉂权歁䅁䅁允䅁䅁䅅䅁䭁䅁䅕䅁䵁䅉䅅䅁䑁䅁䅁睁䵁䅁䅁兂䅁䅁䅁獲兖兑䅯䅂䅁䅁䅅䅁䉁䅁䅁权䙁䅁䅁䍄䉁䅁䅁睁䅁䅁䅍䅄䅁䅁䅕䅁䅁䭁䘷䕕䭅䉁䅯䅁䉁䅁䅁允䅁䅁䅯兂䅁䅁杷允䅁䅁䅍䅁䑁䅁䅷䅁䙁䅁䅁䕁噄汭䉂权乁䅁䅁允䅁䅁䅅䅁䭁䉁䅅䅁䵁䅉䅅䅁䑁䅁䅁睁䵁䅁䅁兂䅁䅁䅂婢兰兑䅯元䅁䅁䅅䅁䉁䅁䅁权乂䅁䅁䍄䉁䅁䅁睁䅁䅁䅍䅄䅁䅁䅕䅁䅁乑慗䕕䭅䍁䅑䅁䉁䅁䅁允䅁䅁䅯兂䅁䅁杷允䅁䅁䅍䅁䑁䅁䅷䅁䙁䅁䅁䕁㡂ㅭ䉂权坁䅁䅁允䅁䅁䅅䅁䭁䅁䅕䅁䵁䅉䅅䅁䑁䅁䅁睁䵁䅁䅁兂䅁䅁䅂婏兰兑䅯䅈䅁䅁䅅䅁䉁䅁䅁兂䭁㘱睎奐湯䅑杷允䅁䅁䅍䅁䑁䅁䅷䅁䙁䅁䅁䕁噄汭䉂权楁䅁䅁允䅁䅁䅅䅁啁䅁䅁䅁䅁䅁䅁䍄䉁䅁䅁睁䅁䅁䅍䅄䅁䅁䅕䅁䅁乑慗䕕䭅䅁䅙䅁䉁䅁䅁允䅁䉁䅑䅁䅁䅁䅁䅁䵁䅉䅅䅁䑁䅁䅁睁䵁䅁䅁兂䅁䅁䅂娱兰兑䅯睃䅁䅁䅅䅁䉁䅁䅁兂㑃潈牘払畩睐杷允䅁䅁䅍䅁䑁䅁䅷䅁䙁䅁䅁䅁䩄汭䉂权䕁䅁䅁允䅁䅁䅅䅁䭁䅁䅕䅁䵁䅉䅅䅁䑁䅁䅁睁䵁䅁䅁兂䅁䅁䅂娱兰兑䅯杇䅁䅁䅅䅁䉁䅁䅁权䙁䅁䅁䍄䉁䅁䅁睁䅁䅁䅍䅄䅁䅁䅕䅁䅁乑慗䕕䭅䉁䅙䅁䉁䅁䅁允䅁䅁䅯兂䅁䅁杷允䅁䅁䅍䅁䑁䅁䅷䅁䙁䅁䅁䕁噄汭䉂权牁䅁䅁允䅁䅁䅅䅁䭁䅁䅕䅁䵁䅉䅅䅁䑁䅁䅁睁䵁䅁䅁兂䅁䅁䅄灣公兑䅯睆䅁䅁䅅䅁䉁䅁䅁权剁䅁䅁䍄䉁䅁䅁睁䅁䅁䅍䅄䅁䅁䅕䅁䅁䡷婋䕕䭅䉁䅑䅁䉁䅁䅁允䅁䅁䅯兂䅁䅁杷允䅁䅁䅍䅁䑁䅁䅷䅁䙁䅁䅁䵁祂噭䉂权扁䅁䅁允䅁䅁䅅䅁䭁䅁䅕䅁䵁䅉䅅䅁䑁䅁䅁睁䵁䅁䅁兂䅁䅁䅄灣公兑䅯䅃䅁䅁䅅䅁䉁䅁䅁权䙁䅁䅁䍄䉁䅁䅁睁䅁䅁䅍䅄䅁䅁䅕䅁䅁䡷婋䕕䭅䅁䅙䅁䉁䅁䅁允䅁䅁䅯兂䅁䅁杷允䅁䅁䅍䅁䑁䅁䅷䅁䙁䅁䅁䵁祂噭䉂权汁䅁䅁允䅁䅁䅅䅁䭁䅁䅕䅁䵁䅉䅅䅁䑁䅁䅁睁䵁䅁䅁兂䅁䅁䅄灣公兑䅯睊䅁䅁䅅䅁䉁䅁䅁权䙁䅁䅁䍄䉁䅁䅁睁䅁䅁䅍䅄䅁䅁䅕䅁䅁䡷婋䕕䭅䍁䅧䅁䉁䅁䅁允䅁䅁䅯兂䅁䅁杷允䅁䅁䅍䅁䑁䅁䅷䅁䙁䅁䅁䅁㑂噭䉂权塁䅁䅁允䅁䅁䅅䅁䭁䕁䅉䅁䵁䅉䅅䅁䑁䅁䅁睁䵁䅁䅁兂䅁䅁䅁䩥公兑䅯䅅䅁䅁䅅䅁䉁䅁䅁权䭁䅁䅁䍄䉁䅁䅁睁䅁䅁䅍䅄䅁䅁䅕䅁䅁䡁婩䕕䭅䅁䅷䅁䉁䅁䅁允䅁䅁䅯兂䅁䅁杷允䅁䅁䅍䅁䑁䅁䅷䅁䙁䅁䅁䅁㑂噭䉂权橁䅁䅁允䅁䅁䅅䅁䭁䅁䅕䅁䵁䅉䅅䅁䑁䅁䅁睁䵁䅁䅁兂䅁䅁䅁䩥公兑䅯杄䅁䅁䅅䅁䉁䅁䅁权䙁䅁䅁䍄䉁䅁䅁睁䅁䅁䅍䅄䅁䅁䅕䅁䅁偣⭤正䭅䍁䅕䅁䉁䅁䅁允䅁䅁䅯兂䅁䅁杷允䅁䅁䅍䅁䑁䅁䅷䅁䙁䅁䅁䕁㕁汭䉂权允䅁䅁允䅁䅁䅅䅁䭁䅁䅯䅁䵁䅉䅅䅁䑁䅁䅁睁䵁䅁䅁兂䅁䅁䅃儳剬兑䅯䅁䅁䅁䅅䅁䉁䅁䅁权䑁䅁䅁䍄䉁䅁䅁睁䅁䅁䅍䅄䅁䅁䅕䅁䅁䑑慭䕕䭅䉁䄴䅁䉁䅁䅁允䅁䅁䅕⽷潕䥘䌯い䵁䅉䅅䅁䑁䅁䅁睁䵁䅁䅁兂䅁䅁䅂婏兰兑䅯杉䅁䅁䅅䅁䉁䅁䅁权䙁䅁䅁䍄䉁䅁䅁睁䅁䅁䅍䅄䅁䅁䅕䅁䅁䑑慭䕕䭅䉁䅯䅁䉁䅁䅁允䅁䅁䅯兂䅁䅁杷允䅁䅁䅍䅁䑁䅁䅷䅁䙁䅁䅁䕁㕁汭䉂权坁䅁䅁允䅁䅁䅅䅁䭁䅁䅕䅁䵁䅉䅅䅁䑁䅁䅁睁䵁䅁䅁兂䅁䅁䅂婏兰兑䅯杄䅁䅁䅅䅁䉁䅁䅁兂乄䵺䵺䥺䱸䅑杷允䅁䅁䅍䅁䑁䅁䅷䅁䙁䅁䅁䕁瑂汭䉂权乁䅁䅁允䅁䅁䅅䅁䭁䉁䅅䅁䵁䅉䅅䅁䑁䅁䅁睁䵁䅁䅁兂䅁䅁䅂䩫儱兑䅯元䅁䅁䅅䅁䉁䅁䅁权佂䅁䅁䍄䉁䅁䅁睁䅁䅁䅍䅄䅁䅁䅕䅁䅁䝑愲䕕䭅䉁䅷䅁䉁䅁䅁允䅁䅁䅯兂䅁䅁杷允䅁䅁䅍䅁䑁䅁䅷䅁䙁䅁䅁䕁瑂汭䉂权敁䅁䅁允䅁䅁䅅䅁䭁䅁䅕䅁䵁䅉䅅䅁䑁䅁䅁睁䵁䅁䅁兂䅁䅁䅂䩫儱兑䅯睊䅁䅁䅅䅁䉁䅁䅁权䙁䅁䅁䍄䉁䅁䅁睁䅁䅁䅍䅄䅁䅁䅕䅁䅁䩷椵啕䭅䉁䅯䅁䉁䅁䅁允䅁䅁䅯兂䅁䅁杷允䅁䅁䅍䅁䑁䅁䅷䅁䙁䅁䅁䕁瑂汭䉂权杁䅁䅁允䅁䅁䅅䅁䭁䅁䅕䅁䵁䅉䅅䅁䑁䅁䅁睁䵁䅁䅁兂䅁䅁䅂婢兰兑䅯䅄䅁䅁䅅䅁䉁䅁䅁权䙁䅁䅁䍄䉁䅁䅁睁䅁䅁䅍䅄䅁䅁䅕䅁䅁䝑愲䕕䭅䅁䅳䅁䉁䅁䅁允䅁䅁䅯兂䅁䅁杷允䅁䅁䅍䅁䑁䅁䅷䅁䙁䅁䅁䕁㡂ㅭ䉂权敁䅁䅁允䅁䅁䅅䅁䙁䙁㑋潈牘捕⽧䍄䉁䅁䅁睁䅁䅁䅍䅄䅁䅁䅕䅁䅁偣⭤正䭅䅁䄴䅁䉁䅁䅁允䅁䅁䅯兂䅁䅁杷允䅁䅁䅍䅁䑁䅁䅷䅁䙁䅁䅁䡁㍄湦䉊权橁䅁䅁允䅁䅁䅅䅁䭁䅁䅕䅁䵁䅉䅅䅁䑁䅁䅁睁䵁䅁䅁兂䅁䅁睂㌹礵兑䅯杂䅁䅁䅅䅁䉁䅁䅁权䙁䅁䅁䍄䉁䅁䅁睁䅁䅁䅍䅄䅁䅁䅕䅁䅁偣⭤正䭅䅁䅳䅁䉁䅁䅁允䅁䅁䅯兂䅁䅁杷允䅁䅁䅍䅁䑁䅁䅷䅁䙁䅁䅁䕁㡂ㅭ䉂权十䅁䅁允䅁䅁䅅䅁䭁䉁䅅䅁䵁䅉䅅䅁䑁䅁䅁睁䵁䅁䅁兂䅁䅁睂㌹礵兑䅯杆䅁䅁䅅䅁䉁䅁䅁权䙁䅁䅁䍄䉁䅁䅁睁䅁䅁䅍䅄䅁䅁䅕䅁䅁偣⭤正䭅䉁䅫䅁䉁䅁䅁允䅁䅁䅯兂䅁䅁杷允䅁䅁䅍䅁䑁䅁䅷䅁䙁䅁䅁䅁䩄汭䉂权䩁䅁䅁允䅁䅁䅅䅁䭁䕁䄸䅁䵁䅉䅅䅁䑁䅁䅁睁䵁䅁䅁兂䅁䅁䅁婹兰兑䅯杅䅁䅁䅅䅁䉁䅁䅁权剁䅁䅁䍄䉁䅁䅁睁䅁䅁䅍䅄䅁䅁䅕䅁䅁䵁慭䕕䭅䉁䅑䅁䉁䅁䅁允䅁䅁䅯兂䅁䅁杷允䅁䅁䅍䅁䑁䅁䅷䅁䙁䅁䅁䅁䩄汭䉂权流䅁䅁允䅁䅁䅅䅁䭁䅁䅕䅁䵁䅉䅅䅁䑁䅁䅁睁䵁䅁䅁兂䅁䅁䅁婹兰兑䅯䅄䅁䅁䅅䅁䉁䅁䅁兂獄払敧敨灶睐杷允䅁䅁䅍䅁䑁䅁䅷䅁䭁䙁䅅䅁䭁䅁䅁䅁䉁䅁䅁允䅁䅁䅯杁䅁䅁杷允䅁䅁䅍䅁䑁䅁䅷䅁䙁䅁䅁䅁䩄汭䉂权汁䅁䅁允䅁䅁䅅䅁䭁䅁䅕䅁䵁䅉䅅䅁䑁䅁䅁睁䵁䅁䅁兂䅁䅁䅁婹兰兑䅯睈䅁䅁䅅䅁䉁䅁䅁权䙁䅁䅁䍄䉁䅁䅁睁䅁䅁䅍䅄䅁䅁䅕䅁䅁䵁慭䕕䭅䍁䅳䅁䉁䅁䅁允䅁䅁䅯兂䅁䅁杷允䅁䅁䅍䅁䑁䅁䅷䅁䙁䅁䅁䵁敃汙䉆权乁䅁䅁允䅁䅁䅅䅁䭁䉁䅅䅁䵁䅉䅅䅁䑁䅁䅁睁䵁䅁䅁兂䅁䅁䅄浮削兑䅯䅅䅁䅁䅅䅁䉁䅁䅁权剁䅁䅁䍄䉁䅁䅁睁䅁䅁䅍䅄䅁䅁䅕䅁䅁䩷椵啕䭅䉁䅑䅁䉁䅁䅁允䅁䅁䅯兂䅁䅁杷允䅁䅁䅍䅁䑁䅁䅷䅁䙁䅁䅁䵁敃汙䉆权扁䅁䅁允䅁䅁䅅䅁䭁䅁䅕䅁䵁䅉䅅䅁䑁䅁䅁睁䵁䅁䅁兂䅁䅁䅄浮削兑䅯䅃䅁䅁䅅䅁䉁䅁䅁权䙁䅁䅁䍄䉁䅁䅁睁䅁䅁䅍䅄䅁䅁䅕䅁䅁䩷椵啕䭅䅁䄸䅁䉁䅁䅁允䅁䅁䅯兂䅁䅁杷允䅁䅁䅍䅁䑁䅁䅷䅁䙁䅁䅁䵁敃汙䉆权潁䅁䅁允䅁䅁䅅䅁䭁䅁䅕䅁䵁䅉䅅䅁䑁䅁䅁睁䵁䅁䅁兂䅁䅁䅄浮削兑䅯杆䅁䅁䅅䅁䉁䅁䅁兂浂浚浚浚㉢睐杷允䅁䅁䅍䅁䑁䅁䅷䅁䙁䅁䅁䥁穂䕑䈹权捁䅁䅁允䅁䅁䅅䅁䙁䕁桪桥畓ず䅎䍄䉁䅁䅁睁䅁䅁䅍䅄䅁䅁䅕䅁䅁䡧䅎ご䭅䉁䄴䅁䉁䅁䅁允䅁䅁䅕䥘䌯匹捨啄䵁䅉䅅䅁䑁䅁䅁睁䵁䅁䅁兂䅁䅁䅃っ偂兑䅯睂䅁䅁䅅䅁䉁䅁䅁权䙁䅁䅁䍄䉁䅁䅁睁䅁䅁䅍䅄䅁䅁䅕䅁䅁䡧䅎ご䭅䍁䅉䅁䉁䅁䅁允䅁䅁䅯兂䅁䅁杷允䅁䅁䅍䅁䑁䅁䅷䅁䙁䅁䅁䥁穂䕑䈹权䵁䅁䅁允䅁䅁䅅䅁䙁䡁㥅瑃橥䑍䄹䍄䉁䅁䅁睁䅁䅁䅍䅄䅁䅁䅕䅁䅁䡧䅎ご䭅䍁䅍䅁䉁䅁䅁允䅁䅁䅯兂䅁䅁杷允䅁䅁䅍䅁䑁䅁䅷䅁䙁䅁䅁䥁穂䕑䈹权汁䅁䅁允䅁䅁䅅䅁䭁䅁䅕䅁䵁䅉䅅䅁䑁䅁䅁睁䵁䅁䅁兂䅁䅁䅃っ偂兑䅯杇䅁䅁䅅䅁䉁䅁䅁权䙁䅁䅁䍄䉁䅁䅁睁䅁䅁䅍䅄䅁䅁䅕䅁䅁䡧䅎ご䭅䉁䅙䅁䉁䅁䅁允䅁䅁䅯兂䅁䅁杷允䅁䅁䅍䅁䑁䅁䅷䅁䙁䅁䅁䥁穂䕑䈹权佁䅁䅁允䅁䅁䅅䅁䭁䅁䅕䅁䵁䅉䅅䅁䑁䅁䅁睁䵁䅁䅁兂䅁䅁䅄㥹橊兑䅯兄䅁䅁䅅䅁䉁䅁䅁权剁䅁䅁䍄䉁䅁䅁睁䅁䅁䅍䅄䅁䅁䅕䅁䅁䵷卶す䭅䉁䅉䅁䉁䅁䅁允䅁䅁䅯充䅁䅁杷允䅁䅁䅍䅁䑁䅁䅷䅁䙁䅁䅁䵁䱄洰䉎权敁䅁䅁允䅁䅁䅅䅁䭁䅁䅕䅁䵁䅉䅅䅁䑁䅁䅁睁䵁䅁䅁兂䅁䅁䅂䩦兴兑䅯䅃䅁䅁䅅䅁䉁䅁䅁兂䑄匹捨㡪䙌睐杷允䅁䅁䅍䅁䑁䅁䅷䅁䙁䅁䅁䵁䱄洰䉎权䡁䅁䅁允䅁䅁䅅䅁䭁䅁䅕䅁䵁䅉䅅䅁䑁䅁䅁睁䵁䅁䅁兂䅁䅁䅄㥹橊兑䅯杊䅁䅁䅅䅁䉁䅁䅁权䙁䅁䅁䍄䉁䅁䅁睁䅁䅁䅍䅄䅁䅁䅕䅁䅁䩑摃䕕䭅䍁䅳䅁䉁䅁䅁允䅁䅁䅯兂䅁䅁杷允䅁䅁䅍䅁䑁䅁䅷䅁䙁䅁䅁䵁䱄洰䉎权汁䅁䅁允䅁䅁䅅䅁䭁䅁䅕䅁䵁䅉䅅䅁䑁䅁䅁睁䵁䅁䅁兂䅁䅁䅄㥹橊兑䅯睄䅁䅁䅅䅁䉁䅁䅁权䙁䅁䅁䍄䉁䅁䅁睁䅁䅁䅍䅄䅁䅁䅕䅁䅁䡷欯䕘䭅䅁䅁䅁䉁䅁䅁允䅁䅁䅯杁䅁䅁杷允䅁䅁䅍䅁䑁䅁䅷䅁䙁䅁䅁䵁䱄洰䉎权歁䅁䅁允䅁䅁䅅䅁䭁䅁䅕䅁䵁䅉䅅䅁䑁䅁䅁睁䵁䅁䅁兂䅁䅁䅄㥹橊兑䅯䅋䅁䅁䅅䅁䉁䅁䅁权䙁䅁䅁䍄䉁䅁䅁睁䅁䅁䅍䅄䅁䅁䅕䅁䅁䵷卶す䭅䉁䅯䅁䉁䅁䅁允䅁䅁䅯兂䅁䅁杷允䅁䅁䅍䅁䑁䅁䅷䅁䙁䅁䅁䵁䱄洰䉎权牁䅁䅁允䅁䅁䅅䅁䭁䅁䅕䅁䵁䅉䅅䅁䑁䅁䅁睁䵁䅁䅁兂䅁䅁䅂䩦兴兑䅯睇䅁䅁䅅䅁䉁䅁䅁权䙁䅁䅁䍄䉁䅁䅁睁䅁䅁䅍䅄䅁䅁䅕䅁䅁䡑批䕕䭅䍁䅁䅁䉁䅁䅁允䅁䅁䅯兂䅁䅁杷允䅁䅁䅍䅁䑁䅁䅷䅁䙁䅁䅁䕁㡂ㅭ䉂权橁䅁䅁允䅁䅁䅅䅁䭁䅁䅕䅁䵁䅉䅅䅁䑁䅁䅁睁䵁䅁䅁兂䅁䅁䅂䩦兴兑䅯睊䅁䅁䅅䅁䉁䅁䅁权䙁䅁䅁䍄䉁䅁䅁睁䅁䅁䅍䅄䅁䅁䅕䅁䅁䡑批䕕䭅䅁䅳䅁䉁䅁䅁允䅁䅁䅯兂䅁䅁杷允䅁䅁䅍䅁䑁䅁䅷䅁䙁䅁䅁䕁元噮䉂权杁䅁䅁允䅁䅁䅅䅁䭁䅁䅕䅁䵁䅉䅅䅁䑁䅁䅁睁䵁䅁䅁兂䅁䅁䅂䩦兴兑䅯䅊䅁䅁䅅䅁䉁䅁䅁䅆䅁䅁䅁䅁䅁䅁杷允䅁䅁䅍䅁䑁䅁䅷䅁䙁䅁䅁䕁㡂ㅭ䉂权晁䅁䅁允䅁䅁䅅䅁䭁䅁䅕䅁䵁䅉䅅䅁䑁䅁䅁睁䵁䅁䅁兂䅁䅁䅂䩦兴兑䅯杇䅁䅁䅅䅁䉁䅁䅁权䙁䅁䅁䍄䉁䅁䅁睁䅁䅁䅍䅄䅁䅁䅕䅁䅁䡑批䕕䭅䍁䅳䅁䉁䅁䅁允䅁䅁䅕灭婭婭婭含䴸䅉䅅䅁䑁䅁䅁睁䵁䅁䅁兂䅁䅁䅂䩦兴兑䅯杄䅁䅁䅅䅁䉁䅁䅁兂乄䵺䵺䝺䍸䅑杷允䅁䅁䅍䅁䑁䅁䅷䅁䙁䅁䅁䅁敄ㅵ䉆权敁䅁䅁允䅁䅁䅅䅁䭁䅁䅕䅁䵁䅉䅅䅁䑁䅁䅁睁䵁䅁䅁兂䅁䅁䅁爳剴兑䅯䅉䅁䅁䅅䅁䉁䅁䅁权䙁䅁䅁䍄䉁䅁䅁睁䅁䅁䅍䅄䅁䅁䅕䅁䅁乁㜶啕䭅䍁䅍䅁䉁䅁䅁允䅁䅁䅯兂䅁䅁杷允䅁䅁䅍䅁䑁䅁䅷䅁䙁䅁䅁䅁敄ㅵ䉆权䕁䅁䅁允䅁䅁䅅䅁䭁䅁䅕䅁䵁䅉䅅䅁䑁䅁䅁睁䵁䅁䅁兂䅁䅁䅁爳剴兑䅯䅊䅁䅁䅅䅁䉁䅁䅁权䙁䅁䅁䍄䉁䅁䅁睁䅁䅁䅍䅄䅁䅁䅕䅁䅁乁㜶啕䭅䉁䄸䅁䉁䅁䅁允䅁䅁䅯兂䅁䅁杷允䅁䅁䅍䅁䑁䅁䅷䅁䙁䅁䅁䅁敄ㅵ䉆权潁䅁䅁允䅁䅁䅅䅁䭁䅁䅕䅁䵁䅉䅅䅁䑁䅁䅁睁䵁䅁䅁兂䅁䅁䅁爳剴兑䅯杆䅁䅁䅅䅁䉁䅁䅁权䙁䅁䅁䍄䉁䅁䅁睁䅁䅁䅍䅄䅁䅁䅕䅁䅁䩑摃䕕䭅䉁䅑䅁䉁䅁䅁允䅁䉁䅑洱䍒䅁䅁䅁䵁䅉䅅䅁䑁䅁䅁睁䵁䅁䅁兂䅁䅁䅂䩫儱兑䅯䅃䅁䅁䅅䅁䉁䅁䅁权䙁䅁䅁䍄䉁䅁䅁睁䅁䅁䅍䅄䅁䅁䅕䅁䅁䩑摃䕕䭅䅁䅣䅁䉁䅁䅁允䅁䅁䅯兂䅁䅁杷允䅁䅁䅍䅁䑁䅁䅷䅁䙁䅁䅁䕁元噮䉂权流䅁䅁允䅁䅁䅅䅁䭁䅁䅕䅁䵁䅉䅅䅁䑁䅁䅁睁䵁䅁䅁兂䅁䅁䅂䩫儱兑䅯䅊䅁䅁䅅䅁䉁䅁䅁兂䭁㘱睎児塲睐杷允䅁䅁䅍䅁䑁䅁䅷䅁䙁䅁䅁䕁元噮䉂权坁䅁䅁允䅁䅁䅅䅁䭁䅁䅕䅁䵁䅉䅅䅁䑁䅁䅁睁䵁䅁䅁权呁䅁䅁权䅁䅁䅁允䅁䅁䅅䅁䭁䅁䅉䅁䵁䅉䅅䅁䑁䅁䅁睁䵁䅁䅁权䙁䅁䅁权䅁䅁䅁允䅁䅁䅅䅁䭁䅁䅅䅁䵁䅉䅅䅁䑁䅁䅁睁䵁䅁䅁兂䅁䅁䅁ㅏ瀱兑䅯䅁䅁䅁䅅䅁䉁䅁䅁权䍁䅁䅁䍄䉁䅁䅁睁䅁䅁䅍䅄䅁䅁䅕䅁䅁䅑夯䕕䭅䅁䅁䅁䉁䅁䅁允䅁䅁䅯杁䅁䅁杷允䅁䅁䅍䅁䑁䅁䅷䅁䙁䅁䅁䅁潃噥䉆权䅁䅁䅁允䅁䅁䅅䅁䭁䅁䅉䅁䵁䅉䅅䅁䑁䅁䅁睁䵁䅁䅁兂䅁䅁䅄䑲剸兑䅯䅁䅁䅁䅅䅁䉁䅁䅁权䑁䅁䅁䍄䉁䅁䅁睁䅁䅁䅍䅄䅁䅁䅯兑䅁䅁䅯䅁䅁䅁䅅䅁䉁䅁䅁权䍁䅁䅁䍄䉁䅁䅁睁䅁䅁䅍䅄䅁䅁䅯杕䅁䅁䅯䅁䅁䅁䅅䅁䉁䅁䅁权䍁䅁䅁䍄䉁䅁䅁睁䅁䅁䅍䅄䅁䅁䅯睎䅁䅁䅯䅁䅁䅁䅅䅁䉁䅁䅁权䑁䅁䅁䍄䉁䅁䅁睁䅁䅁䅍䅄䅁䅁䅯睑䅁䅁䅯䅁䅁䅁䅅䅁䉁䅁䅁权䑁䅁䅁䍄䉁䅁䅁睁䅁䅁䅍䅄䅁䅁䅯睒䅁䅁䅯䅁䅁䅁䅅䅁䉁䅁䅁权䍁䅁䅁䍄䉁䅁䅁睁䅁䅁䅍䅄䅁䅁䅯睌䅁䅁䅯䅁䅁䅁䅅䅁䉁䅁䅁权䍁䅁䅁䍄䉁䅁䅁睁䅁䅁䅍䅄䅁䅁䅯兌䅁䅁䅯䅁䅁䅁䅅䅁䉁䅁䅁权䑁䅁䅁

Sheet Ore
A2: Ore
A3: Commodity: Cobalt
A4: Scenario: Market Intelligence 2024 Constant USD
A6: Period Ended | B6: Property | C6: Property ID | D6: Country/Region | E6: Waste Mined: Open Pit (kilotonnes) | F6: Waste Mined: Underground (kilotonnes) | G6: Waste Mined: Total (kilotonnes) | H6: Open Pit Strip Ratio (x) | I6: Ore Mined: Open Pit (kilotonnes) | J6: Ore Mined: Underground (kilotonnes) | K6: Ore Mined: Total (kilotonnes) | L6: Ore Treated (kilotonnes) | M6: Mine: Labor Cost ($/tonne) | N6: Mine: Fuel Cost ($/tonne) | O6: Mine: Electricity Cost ($/tonne) | P6: Mine: Other Cost ($/tonne) | Q6: Mine: Total Cost ($/tonne) | R6: Mill: Labor Cost ($/tonne) | S6: Mill: Reagents Cost ($/tonne) | T6: Mill: Electricity Cost ($/tonne) | U6: Mill: Other Cost ($/tonne) | V6: Mill: Total Cost ($/tonne) | W6: Total Minesite Cost ($/tonne) | X6: Transport and Offsite Cost ($/tonne) | Y6: Treatment & Refining Charges ($/tonne) | Z6: Cash Operating Cost ($/tonne) | AA6: Royalty Cost ($/tonne) | AB6: Total Cash Cost ($/tonne) | AC6: Reclamation, Closure Provision ($/tonne) | AD6: Depreciation ($/tonne) | AE6: Deferred Stripping Amortized ($/tonne) | AF6: Inventory Change ($/tonne) | AG6: Total Production Cost ($/tonne) | AH6: Corporate Overhead Charges ($/tonne) | AI6: Exploration and Other Sustaining Costs ($/tonne) | AJ6: Sustaining Capex ($/tonne) | AK6: All-in-Sustaining Cost ($/tonne) | AL6: Development and Expansion Capex ($/tonne) | AM6: Interest Charges ($/tonne) | AN6: Extraordinary Cash Charges ($/tonne) | AO6: Extraordinary Non-Cash Charges ($/tonne) | AP6: Other All-in-Cost ($/tonne) | AQ6: All-in-Cost ($/tonne) | AR6: Gross Revenue ($/tonne) | AS6: Cash Operating Margin ($/tonne) | AT6: Total Cash Margin ($/tonne)
A10: 46022 | B10: Alex | C10: 81253 | D10: China | E10: 0 | F10: 0 | G10: 0 | H10: 0 | I10: 0 | J10: 165 | K10: 165 | L10: 165 | M10: 3.209079 | N10: 0 | O10: 0.842017 | P10: 5.391343 | Q10: 9.442439 | R10: 3.473914 | S10: 1.783367 | T10: 2.810552 | U10: 2.498254 | V10: 10.566087 | W10: 20.008526 | X10: 5.9160325 | Y10: 12.753937 | Z10: 38.678495 | AA10: 7.4754259 | AB10: 46.153921 | AC10: 0 | AD10: 3.919365 | AE10: 0 | AF10: 0 | AG10: 50.073286 | AH10: 2.247665 | AI10: 0 | AJ10: 1.081689 | AK10: 49.483275 | AL10: 0 | AM10: 0 | AN10: 0 | AO10: 0 | AP10: 0 | AQ10: 49.483275 | AR10: 49.386032 | AS10: 10.707536 | AT10: 3.2321105
A11: 46022 | B11: Eagle | C11: 33795 | D11: USA | E11: 0 | F11: 0 | G11: 0 | H11: 0 | I11: 0 | J11: 684 | K11: 684 | L11: 684 | M11: 28.923464 | N11: 28.070563 | O11: 7.979398 | P11: 25.373466 | Q11: 90.346891 | R11: 13.207618 | S11: 6.743142 | T11: 11.63256 | U11: 18.534277 | V11: 50.117597 | W11: 140.46449 | X11: 6.0276686 | Y11: 60.021592 | Z11: 206.51375 | AA11: 14.418902 | AB11: 220.93265 | AC11: 0 | AD11: 88.792869 | AE11: 0 | AF11: 0 | AG11: 309.72552 | AH11: 13.630139 | AI11: 0 | AJ11: 36.549708 | AK11: 271.1125 | AL11: 0 | AM11: 0 | AN11: 0 | AO11: 0 | AP11: 0 | AQ11: 271.1125 | AR11: 364.20828 | AS11: 157.69453 | AT11: 143.27563
A12: 46022 | B12: Etoile | C12: 36399 | D12: Dem. Rep. Congo | E12: 4926.4612 | F12: 0 | G12: 4926.4612 | H12: 3.434784 | I12: 1434.2857 | J12: 0 | K12: 1434.2857 | L12: 1434.2857 | M12: 9.633823 | N12: 7.144348 | O12: 2.227646 | P12: 21.152475 | Q12: 40.158292 | R12: 7.629584 | S12: 15.646722 | T12: 25.903389 | U12: 12.650836 | V12: 61.830531 | W12: 101.98882 | X12: 1.1845952 | Y12: 0.18090543 | Z12: 103.35432 | AA12: 10.529851 | AB12: 113.88417 | AC12: 0 | AD12: 12.87845 | AE12: 0 | AF12: 0 | AG12: 126.76262 | AH12: 1.857572 | AI12: 0 | AJ12: 7.376143 | AK12: 123.11789 | AL12: 0 | AM12: 0 | AN12: 0 | AO12: 0 | AP12: 0 | AQ12: 123.11789 | AR12: 210.08057 | AS12: 106.72624 | AT12: 96.196393
A13: 46022 | B13: Goro | C13: 27742 | D13: New Caledonia | E13: 6123.457 | F13: 0 | G13: 6123.457 | H13: 2 | I13: 3061.7285 | J13: 0 | K13: 3061.7285 | L13: 2296.2964 | M13: 13.054637 | N13: 10.172679 | O13: 3.8392434 | P13: 48.419694 | Q13: 75.486254 | R13: 13.277756 | S13: 85.137464 | T13: 20.983163 | U13: 29.59927 | V13: 148.99765 | W13: 224.48391 | X13: 1.1710959 | Y13: 65.303129 | Z13: 290.95813 | AA13: 0 | AB13: 290.95813 | AC13: 0 | AD13: 61.480649 | AE13: 0 | AF13: 0 | AG13: 352.43878 | AH13: 6.9464172 | AI13: 0 | AJ13: 31.413471 | AK13: 329.31802 | AL13: 0 | AM13: 0 | AN13: 0 | AO13: 0 | AP13: 0 | AQ13: 329.31802 | AR13: 251.03564 | AS13: -39.922493 | AT13: -39.922493
A14: 46022 | B14: Impala Bafokeng | C14: 30267 | D14: South Africa | E14: 0 | F14: 0 | G14: 0 | H14: 0 | I14: 0 | J14: 4540 | K14: 4540 | L14: 4540 | M14: 62.126661 | N14: 0.707896 | O14: 17.476871 | P14: 25.787011 | Q14: 106.09844 | R14: 3.536245 | S14: 1.84808 | T14: 6.62894 | U14: 8.046346 | V14: 20.059611 | W14: 126.15805 | X14: 0.10630027 | Y14: 5.7621603 | Z14: 132.02651 | AA14: 1.9717263 | AB14: 133.99824 | AC14: 0 | AD14: 30.956179 | AE14: 0 | AF14: 0 | AG14: 164.95442 | AH14: 0.720823 | AI14: 0 | AJ14: 18.923708 | AK14: 153.64277 | AL14: 0 | AM14: 0 | AN14: 0 | AO14: 0 | AP14: 0 | AQ14: 153.64277 | AR14: 143.83996 | AS14: 11.813446 | AT14: 9.8417197
A15: 46022 | B15: Kamoto SX-EW | C15: 79271 | D15: Dem. Rep. Congo | E15: 84500 | F15: 0 | G15: 84500 | H15: 12.518519 | I15: 6750 | J15: 700 | K15: 7450 | L15: 8450 | M15: 9.621378 | N15: 10.666749 | O15: 2.520243 | P15: 19.112535 | Q15: 41.920905 | R15: 2.17347 | S15: 13.256164 | T15: 33.155879 | U15: 23.796147 | V15: 72.38166 | W15: 114.30257 | X15: 6.8874831 | Y15: 10.584483 | Z15: 131.77453 | AA15: 16.086008 | AB15: 147.86054 | AC15: 0.556839 | AD15: 64.498697 | AE15: 0 | AF15: 0 | AG15: 212.91608 | AH15: 1.139331 | AI15: 0 | AJ15: 38.800977 | AK15: 188.35769 | AL15: 0 | AM15: 0 | AN15: 0 | AO15: 0 | AP15: 0 | AQ15: 188.35769 | AR15: 234.07227 | AS15: 102.29773 | AT15: 86.211727
A16: 46022 | B16: Kevitsa | C16: 29179 | D16: Finland | E16: 21422.667 | F16: 0 | G16: 21422.667 | H16: 2.13515 | I16: 10033.333 | J16: 0 | K16: 10033.333 | L16: 10033.333 | M16: 0.788955 | N16: 0.418785 | O16: 0.043568 | P16: 1.089772 | Q16: 2.34108 | R16: 0.338125 | S16: 0.884967 | T16: 1.164028 | U16: 0.542343 | V16: 2.929463 | W16: 5.270543 | X16: 2.2312527 | Y16: 6.4463037 | Z16: 13.948099 | AA16: 0 | AB16: 13.948099 | AC16: 0 | AD16: 0.845863 | AE16: 0 | AF16: 0 | AG16: 14.793962 | AH16: 0.647841 | AI16: 0 | AJ16: 11.165892 | AK16: 25.761832 | AL16: 1.060528 | AM16: 0 | AN16: 0 | AO16: 0 | AP16: 0 | AQ16: 26.82236 | AR16: 45.543177 | AS16: 31.595078 | AT16: 31.595078
A17: 46022 | B17: Munali | C17: 27453 | D17: Zambia | E17: 0 | F17: 0 | G17: 0 | H17: 0 | I17: 0 | J17: 564.0244 | K17: 564.0244 | L17: 564.0244 | M17: 4.701922 | N17: 5.478196 | O17: 2.924667 | P17: 11.113153 | Q17: 24.217938 | R17: 0.882057 | S17: 1.747803 | T17: 4.533747 | U17: 6.253227 | V17: 13.416834 | W17: 37.634772 | X17: 12.794915 | Y17: 15.838118 | Z17: 66.267805 | AA17: 5.8518375 | AB17: 72.119642 | AC17: 0.531892 | AD17: 41.278582 | AE17: 0 | AF17: 0 | AG17: 113.93012 | AH17: 7.625678 | AI17: 0 | AJ17: 8.51027 | AK17: 88.787482 | AL17: 0 | AM17: 0 | AN17: 0 | AO17: 0 | AP17: 0 | AQ17: 88.787482 | AR17: 117.03721 | AS17: 50.769406 | AT17: 44.917568
A18: 46022 | B18: Musonoi | C18: 37355 | D18: Dem. Rep. Congo | E18: 0 | F18: 0 | G18: 0 | H18: 0 | I18: 0 | J18: 1230.1587 | K18: 1230.1587 | L18: 1230.1587 | M18: 30.835651 | N18: 4.08743 | O18: 7.514944 | P18: 29.977764 | Q18: 72.415789 | R18: 9.707288 | S18: 1.192103 | T18: 8.924746 | U18: 9.867326 | V18: 29.691463 | W18: 102.10725 | X18: 21.264476 | Y18: 36.982889 | Z18: 160.35462 | AA18: 36.469616 | AB18: 196.82423 | AC18: 0 | AD18: 37.825876 | AE18: 0 | AF18: 0 | AG18: 234.65011 | AH18: 6.259355 | AI18: 0 | AJ18: 6.503226 | AK18: 209.58681 | AL18: 0 | AM18: 0 | AN18: 0 | AO18: 0 | AP18: 0 | AQ18: 209.58681 | AR18: 356.90742 | AS18: 196.55281 | AT18: 160.08319
A19: 46022 | B19: Nchanga | C19: 28264 | D19: Zambia | E19: 3406.3121 | F19: 0 | G19: 3406.3121 | H19: 3 | I19: 1135.4374 | J19: 820.03809 | K19: 1955.4754 | L19: 1955.4754 | M19: 21.348671 | N19: 13.820075 | O19: 2.516709 | P19: 4.631249 | Q19: 42.316704 | R19: 10.659794 | S19: 1.582408 | T19: 8.529837 | U19: 3.657897 | V19: 24.429936 | W19: 66.74664 | X19: 0.12833989 | Y19: 2.9630472 | Z19: 69.838027 | AA19: 4.4445931 | AB19: 74.28262 | AC19: 0 | AD19: 2.518238 | AE19: 0 | AF19: 0 | AG19: 76.800858 | AH19: 0.696993 | AI19: 0 | AJ19: 2.054196 | AK19: 77.033809 | AL19: 0 | AM19: 0 | AN19: 0 | AO19: 0 | AP19: 0 | AQ19: 77.033809 | AR19: 44.445561 | AS19: -25.392466 | AT19: -29.837059
A20: 46022 | B20: Norilsk | C20: 75972 | D20: Russia | E20: 18000 | F20: 0 | G20: 18000 | H20: 3 | I20: 6000 | J20: 27740 | K20: 33740 | L20: 33740 | M20: 31.176264 | N20: 2.860535 | O20: 1.7982135 | P20: 28.691233 | Q20: 64.526245 | R20: 1.9620374 | S20: 1.8350298 | T20: 2.0133684 | U20: 2.8935857 | V20: 8.7040214 | W20: 73.230266 | X20: 4.655598 | Y20: 33.674814 | Z20: 111.56068 | AA20: 25.77647 | AB20: 137.33715 | AC20: 0 | AD20: 26.943664 | AE20: 0 | AF20: 0 | AG20: 164.28081 | AH20: 20.376122 | AI20: 0 | AJ20: 27.299921 | AK20: 185.01319 | AL20: 0 | AM20: 4.5858405 | AN20: 0 | AO20: 0 | AP20: 1.481921 | AQ20: 191.08095 | AR20: 384.51395 | AS20: 272.95327 | AT20: 247.1768
A21: 46022 | B21: Raglan | C21: 26073 | D21: Canada | E21: 0 | F21: 0 | G21: 0 | H21: 0 | I21: 0 | J21: 1350 | K21: 1350 | L21: 1350 | M21: 86.881849 | N21: 6.946916 | O21: 11.850735 | P21: 166.04817 | Q21: 271.72767 | R21: 10.242015 | S21: 9.448046 | T21: 6.485671 | U21: 27.329287 | V21: 53.505019 | W21: 325.23269 | X21: 30.076855 | Y21: 72.864783 | Z21: 428.17433 | AA21: 23.587164 | AB21: 451.76149 | AC21: 0 | AD21: 127.77133 | AE21: 0 | AF21: 0 | AG21: 579.53282 | AH21: 1.601561 | AI21: 0 | AJ21: 33.659338 | AK21: 487.02239 | AL21: 0 | AM21: 0 | AN21: 0 | AO21: 0 | AP21: 0 | AQ21: 487.02239 | AR21: 593.16028 | AS21: 164.98595 | AT21: 141.39879
... A51: 46022 | B51: Zimplats | C51: 29249 | D51: Zimbabwe | E51: 0 | F51: 0 | G51: 0 | H51: 0 | I51: 0 | J51: 7560 | K51: 7560 | L51: 7560 | M51: 10.507245 | N51: 0.487556 | O51: 0.588137 | P51: 34.178694 | Q51: 45.761632 | R51: 3.094332 | S51: 0.660549 | T51: 4.624988 | U51: 5.907668 | V51: 14.287537 | W51: 60.049169 | X51: 0 | Y51: 14.51627 | Z51: 74.565439 | AA51: 4.05328 | AB51: 78.618719 | AC51: 0 | AD51: 24.135255 | AE51: 0 | AF51: 0 | AG51: 102.75397 | AH51: 6.03632 | AI51: 0 | AJ51: 16.203383 | AK51: 100.85842 | AL51: 13.227513 | AM51: 0 | AN51: 0 | AO51: 0 | AP51: 0 | AQ51: 114.08594 | AR51: 123.22262 | AS51: 48.657176 | AT51: 44.603896

Sheet Production Costs Co Product
A2: Production Costs Co Product
A3: Commodity: Cobalt
A4: Scenario: Market Intelligence 2024 Constant USD
A6: Period Ended | B6: Property | C6: Property ID | D6: Country/Region | E6: Ore Treated (kilotonnes) | F6: Head Grade (%) | G6: Recovery Rate (%) | H6: Recovered Cobalt (kilotonnes) | I6: Payability (%) | J6: Paid Cobalt Produced (kilotonnes) | K6: Commodity Net Revenue (%) | L6: Mine: Labor Cost (¢/lb) | M6: Mine: Fuel Cost (¢/lb) | N6: Mine: Electricity Cost (¢/lb) | O6: Mine: Other Cost (¢/lb) | P6: Mine: Total Cost (¢/lb) | Q6: Mill: Labor Cost (¢/lb) | R6: Mill: Reagents Cost (¢/lb) | S6: Mill: Electricity Cost (¢/lb) | T6: Mill: Other Cost (¢/lb) | U6: Mill: Total Cost (¢/lb) | V6: Total Minesite Cost (¢/lb) | W6: Transport and Offsite Cost (¢/lb) | X6: Treatment & Refining Charges (¢/lb) | Y6: Cash Operating Cost (¢/lb) | Z6: Royalty Cost (¢/lb) | AA6: Total Cash Cost (¢/lb) | AB6: Reclamation, Closure Provision (¢/lb) | AC6: Depreciation (¢/lb) | AD6: Deferred Stripping Amortized (¢/lb) | AE6: Inventory Change (¢/lb) | AF6: Total Production Cost (¢/lb) | AG6: Corporate Overhead Charges (¢/lb) | AH6: Exploration and Other Sustaining Costs (¢/lb) | AI6: Sustaining Capex (¢/lb) | AJ6: All-in-Sustaining Cost (¢/lb) | AK6: Development and Expansion Capex (¢/lb) | AL6: Interest Charges (¢/lb) | AM6: Extraordinary Cash Charges (¢/lb) | AN6: Extraordinary Non-Cash Charges (¢/lb) | AO6: Other All-in-Cost (¢/lb) | AP6: All-in-Cost (¢/lb) | AQ6: Realized Price (¢/lb) | AR6: Gross Revenue ($M) | AS6: Cash Operating Margin (¢/lb) | AT6: Total Cash Margin (¢/lb)
A10: 46022 | B10: Alex | C10: 81253 | D10: China | E10: 165 | F10: 0.029 | G10: 60 | H10: 0.029 | I10: 95 | J10: 0.027274 | K10: 7.3604261 | L10: 64.816297 | M10: 0 | N10: 17.006881 | O10: 108.8932 | P10: 190.71638 | Q10: 70.165378 | R10: 36.020068 | S10: 56.766933 | T10: 50.459204 | U10: 213.41158 | V10: 404.12796 | W10: 164.4315 | X10: 422.32166 | Y10: 990.88112 | Z10: 150.98707 | AA10: 1141.8682 | AB10: 0 | AC10: 79.162503 | AD10: 0 | AE10: 0 | AF10: 1221.0307 | AG10: 45.397861 | AH10: 0 | AI10: 21.847725 | AJ10: 1209.1138 | AK10: 0 | AL10: 0 | AM10: 0 | AN10: 0 | AO10: 0 | AP10: 1209.1138 | AQ10: 1207.1497 | AR10: 8.148695 | AS10: 216.26855 | AT10: 65.281481
A11: 46022 | B11: Ambatovy | C11: 30428 | D11: Madagascar | E11: 3045.8785 | F11: 0.1 | G11: 75 | H11: 2.284 | I11: 100 | J11: 2.284409 | K11: 11.782002 | L11: 61.915608 | M11: 6.1821792 | N11: 65.809076 | O11: 493.15308 | P11: 627.05994 | Q11: 65.240186 | R11: 112.18812 | S11: 61.398636 | T11: 186.93927 | U11: 425.76621 | V11: 1052.8262 | W11: 59.706295 | X11: 112.82216 | Y11: 1225.3546 | Z11: 18.88851 | AA11: 1244.2431 | AB11: 0 | AC11: 598.89533 | AD11: 0 | AE11: 0 | AF11: 1843.1384 | AG11: 103.85405 | AH11: 21.05491 | AI11: 187.15479 | AJ11: 1556.3069 | AK11: 0 | AL11: 18.508209 | AM11: 0 | AN11: 0 | AO11: 0 | AP11: 1574.8151 | AQ11: 1205.9952 | AR11: 525.86245 | AS11: -19.35936 | AT11: -38.24787
A12: 46022 | B12: Chambishi | C12: 28268 | D12: Zambia | E12: 5600 | F12: 0.1677 | G12: 60 | H12: 5.635 | I12: 100 | J12: 5.634913 | K12: 15.629157 | L12: 122.44317 | M12: 7.9258551 | N12: 10.035921 | O12: 96.688206 | P12: 237.09316 | Q12: 14.739969 | R12: 8.1793042 | S12: 20.061182 | T12: 32.83827 | U12: 75.818726 | V12: 312.91188 | W12: 2.5873581 | X12: 249.99942 | Y12: 565.49866 | Z12: 78.680641 | AA12: 644.1793 | AB12: 0 | AC12: 127.96644 | AD12: 0 | AE12: 0 | AF12: 772.14575 | AG12: 13.94381 | AH12: 0 | AI12: 30.669974 | AJ12: 688.79309 | AK12: 0 | AL12: 0 | AM12: 0 | AN12: 0 | AO12: 0 | AP12: 688.79309 | AQ12: 1205.9972 | AR12: 833.86044 | AS12: 640.49855 | AT12: 561.81791
A13: 46022 | B13: Deerni | C13: 30531 | D13: China | E13: 719.05571 | F13: 0.09 | G13: 65 | H13: 0.421 | I13: 90 | J13: 0.378583 | K13: 7.7773369 | L13: 53.708169 | M13: 6.0133378 | N13: 0.62329421 | O13: 19.669996 | P13: 80.014797 | Q13: 21.481345 | R13: 3.5174808 | S13: 29.050057 | T13: 30.500577 | U13: 84.54946 | V13: 164.56426 | W13: 7.8946688 | X13: 610.02739 | Y13: 782.48632 | Z13: 30.358553 | AA13: 812.84487 | AB13: 0 | AC13: 14.589529 | AD13: 0 | AE13: 0 | AF13: 827.4344 | AG13: 19.662921 | AH13: 0 | AI13: 17.629797 | AJ13: 850.13759 | AK13: 0 | AL13: 0 | AM13: 0 | AN13: 0 | AO13: 0 | AP13: 850.13759 | AQ13: 1206.0542 | AR13: 73.156781 | AS13: 423.56784 | AT13: 393.20928
